Workbook

Sheet Actual
A1: Player | B1: Roster Position | C1: %Drafted | D1: FPTS
A2: Connor McDavid | B2: C | C2: 0.2693 | D2: 1.5
A3: Zach Hyman | B3: W | C3: 0.2166 | D3: 6
A4: Matt Duchene | B4: C | C4: 0.2063 | D4: 3
A5: Jake Walman | B5: D | C5: 0.1899 | D5: 15
A6: Cole Caufield | B6: W | C6: 0.182 | D6: 11.5
A7: Spencer Knight | B7: G | C7: 0.1791 | D7: 15.1
A8: Ryan O'Reilly | B8: C | C8: 0.1593 | D8: 19.5
A9: Ryan Nugent-Hopkins | B9: C | C9: 0.148 | D9: 0
A10: Alexander Nikishin | B10: D | C10: 0.1383 | D10: 2.8
A11: Filip Gustavsson | B11: G | C11: 0.1338 | D11: 16.5
A12: Nick Suzuki | B12: UTIL | C12: 0.1321 | D12: 19.3
A13: Seth Jarvis | B13: W | C13: 0.1304 | D13: 6
... A270: Ethan Del Mastro | B270: D | C270: 0.0006 | D270: 0

Sheet Projected
A1: name | B1: team | C1: position | D1: salary | E1: projected_fpts | F1: dk_avg_fpts | G1: edge | H1: value | I1: floor | J1: ceiling | K1: player_type | L1: actual | M1: ownership | N1: TOI
A2: Michael Callahan | B2: BOS | C2: D | D2: 2500 | E2: 3.7799891 | F2: 5.04 | G2: -1.2600109 | H2: 1.5119957 | I2: 1.5119957 | J2: 14.449973 | K2: skater | L2: =VLOOKUP($A2,Actual!$A:$D,4,FALSE) -> #N/A | M2: =VLOOKUP($A2,Actual!$A:$D,3,FALSE) -> #N/A | N2: =VLOOKUP(A2,NHT!B:F,5,FALSE) -> #N/A
A3: Riley Tufte | B3: BOS | C3: L | D3: 2500 | E3: 1.0743469 | F3: 3.95 | G3: -2.8756531 | H3: 0.42973875 | I3: 0.42973875 | J3: 7.6858672 | K3: skater | L3: =VLOOKUP($A3,Actual!$A:$D,4,FALSE) -> #N/A | M3: =VLOOKUP($A3,Actual!$A:$D,3,FALSE) -> #N/A | N3: =VLOOKUP(A3,NHT!B:F,5,FALSE) -> #N/A
A4: Joonas Korpisalo | B4: BOS | C4: G | D4: 7600 | E4: 12.062286 | F4: 10.33 | G4: 1.7322855 | H4: 1.5871428 | I4: 3.6186857 | J4: 34.124571 | K4: goalie | L4: =VLOOKUP($A4,Actual!$A:$D,4,FALSE) -> 16.5 | M4: =VLOOKUP($A4,Actual!$A:$D,3,FALSE) -> 0.0221 | N4: =VLOOKUP(A4,NHT!B:F,5,FALSE) -> #N/A
A5: Parker Wotherspoon | B5: BOS | C5: D | D5: 2800 | E5: 4.4076843 | F5: 6.08 | G5: -1.6723157 | H5: 1.5741729 | I5: 1.7630737 | J5: 16.019211 | K5: skater | L5: =VLOOKUP($A5,Actual!$A:$D,4,FALSE) -> 2.6 | M5: =VLOOKUP($A5,Actual!$A:$D,3,FALSE) -> 0.0074 | N5: =VLOOKUP(A5,NHT!B:F,5,FALSE) -> 19.216667
A6: Nikita Zadorov | B6: BOS | C6: D | D6: 2600 | E6: 6.1779678 | F6: 6.17 | G6: 0.0079678271 | H6: 2.3761415 | I6: 2.4711871 | J6: 20.44492 | K6: skater | L6: =VLOOKUP($A6,Actual!$A:$D,4,FALSE) -> 9.1 | M6: =VLOOKUP($A6,Actual!$A:$D,3,FALSE) -> 0.0085 | N6: =VLOOKUP(A6,NHT!B:F,5,FALSE) -> 20.616667
A7: Charlie McAvoy | B7: BOS | C7: D | D7: 4900 | E7: 8.8111188 | F7: 9.75 | G7: -0.93888124 | H7: 1.7981875 | I7: 3.5244475 | J7: 27.027797 | K7: skater | L7: =VLOOKUP($A7,Actual!$A:$D,4,FALSE) -> 21.4 | M7: =VLOOKUP($A7,Actual!$A:$D,3,FALSE) -> 0.0232 | N7: =VLOOKUP(A7,NHT!B:F,5,FALSE) -> 27.016667
A8: Andrew Peeke | B8: BOS | C8: D | D8: 2500 | E8: 5.3597053 | F8: 6.16 | G8: -0.80029471 | H8: 2.1438821 | I8: 2.1438821 | J8: 18.399263 | K8: skater | L8: =VLOOKUP($A8,Actual!$A:$D,4,FALSE) -> 2.6 | M8: =VLOOKUP($A8,Actual!$A:$D,3,FALSE) -> 0.004 | N8: =VLOOKUP(A8,NHT!B:F,5,FALSE) -> 20.45
A9: Elias Lindholm | B9: BOS | C9: C | D9: 4500 | E9: 7.8066328 | F9: 8.8 | G9: -0.99336722 | H9: 1.7348073 | I9: 3.1226531 | J9: 24.516582 | K9: skater | L9: =VLOOKUP($A9,Actual!$A:$D,4,FALSE) -> 19.3 | M9: =VLOOKUP($A9,Actual!$A:$D,3,FALSE) -> 0.0317 | N9: =VLOOKUP(A9,NHT!B:F,5,FALSE) -> 19.733333
A10: David Pastrnak | B10: BOS | C10: R | D10: 8800 | E10: 16.86332 | F10: 15.14 | G10: 1.7233203 | H10: 1.9162864 | I10: 6.7453281 | J10: 47.158301 | K10: skater | L10: =VLOOKUP($A10,Actual!$A:$D,4,FALSE) -> 33.5 | M10: =VLOOKUP($A10,Actual!$A:$D,3,FALSE) -> 0.0346 | N10: =VLOOKUP(A10,NHT!B:F,5,FALSE) -> 17.533333
A11: Morgan Geekie | B11: BOS | C11: C | D11: 5000 | E11: 9.5919488 | F11: 10.55 | G11: -0.95805119 | H11: 1.9183898 | I11: 3.8367795 | J11: 28.979872 | K11: skater | L11: =VLOOKUP($A11,Actual!$A:$D,4,FALSE) -> 11.5 | M11: =VLOOKUP($A11,Actual!$A:$D,3,FALSE) -> 0.0232 | N11: =VLOOKUP(A11,NHT!B:F,5,FALSE) -> 15.516667
A12: Pavel Zacha | B12: BOS | C12: C | D12: 3700 | E12: 7.1684526 | F12: 7.68 | G12: -0.51154743 | H12: 1.9374196 | I12: 2.867381 | J12: 22.921131 | K12: skater | L12: =VLOOKUP($A12,Actual!$A:$D,4,FALSE) -> 7.3 | M12: =VLOOKUP($A12,Actual!$A:$D,3,FALSE) -> 0.0215 | N12: =VLOOKUP(A12,NHT!B:F,5,FALSE) -> 17.15
A13: Mason Lohrei | B13: BOS | C13: D | D13: 2500 | E13: 6.7955118 | F13: 6.48 | G13: 0.31551179 | H13: 2.7182047 | I13: 2.7182047 | J13: 21.988779 | K13: skater | L13: =VLOOKUP($A13,Actual!$A:$D,4,FALSE) -> 4.1 | M13: =VLOOKUP($A13,Actual!$A:$D,3,FALSE) -> 0.0113 | N13: =VLOOKUP(A13,NHT!B:F,5,FALSE) -> 13.016667
... A299: Morgan Barron | B299: WPG | C299: C | D299: 2800 | E299: 4.361014 | F299: 5.88 | G299: -1.518986 | H299: 1.557505 | I299: 1.7444056 | J299: 15.902535 | K299: skater | L299: =VLOOKUP($A299,Actual!$A:$D,4,FALSE) -> 1.5 | M299: =VLOOKUP($A299,Actual!$A:$D,3,FALSE) -> 0.0017 | N299: =VLOOKUP(A299,NHT!B:F,5,FALSE) -> 8.75

Sheet NHT
B1: Player | C1: Team | D1: Position | E1: GP | F1: TOI | G1: Goals | H1: Total Assists | I1: First Assists | J1: Second Assists | K1: Total Points | L1: IPP | M1: Shots | N1: SH% | O1: ixG | P1: iCF | Q1: iFF | R1: iSCF | S1: iHDCF | T1: Rush Attempts | U1: Rebounds Created | V1: PIM | W1: Total Penalties | X1: Minor | Y1: Major | Z1: Misconduct | AA1: Penalties Drawn | AB1: Giveaways | AC1: Takeaways | AD1: Hits | AE1: Hits Taken | AF1: Shots Blocked | AG1: Faceoffs Won | AH1: Faceoffs Lost | AI1: Faceoffs %
A2: 245 | B2: Alex Steeves | C2: BOS | D2: C | E2: 1 | F2: 10.483333 | G2: 0 | H2: 0 | I2: 0 | J2: 0 | K2: 0 | L2: - | M2: 0 | N2: - | O2: 0.03 | P2: 1 | Q2: 1 | R2: 1 | S2: 0 | T2: 0 | U2: 0 | V2: 0 | W2: 0 | X2: 0 | Y2: 0 | Z2: 0 | AA2: 2 | AB2: 1 | AC2: 0 | AD2: 1 | AE2: 3 | AF2: 0 | AG2: 0 | AH2: 0 | AI2: -
A3: 143 | B3: Andrew Peeke | C3: BOS | D3: D | E3: 1 | F3: 20.45 | G3: 0 | H3: 0 | I3: 0 | J3: 0 | K3: 0 | L3: - | M3: 0 | N3: - | O3: 0 | P3: 1 | Q3: 0 | R3: 0 | S3: 0 | T3: 0 | U3: 0 | V3: 0 | W3: 0 | X3: 0 | Y3: 0 | Z3: 0 | AA3: 0 | AB3: 1 | AC3: 0 | AD3: 1 | AE3: 5 | AF3: 2 | AG3: 0 | AH3: 0 | AI3: -
A4: 155 | B4: Casey Mittelstadt | C4: BOS | D4: C | E4: 1 | F4: 14.666667 | G4: 0 | H4: 0 | I4: 0 | J4: 0 | K4: 0 | L4: 0 | M4: 0 | N4: - | O4: 0 | P4: 0 | Q4: 0 | R4: 0 | S4: 0 | T4: 0 | U4: 0 | V4: 0 | W4: 0 | X4: 0 | Y4: 0 | Z4: 0 | AA4: 0 | AB4: 1 | AC4: 1 | AD4: 0 | AE4: 2 | AF4: 0 | AG4: 1 | AH4: 2 | AI4: 33.33
A5: 138 | B5: Charlie McAvoy | C5: BOS | D5: D | E5: 1 | F5: 27.016667 | G5: 1 | H5: 0 | I5: 0 | J5: 0 | K5: 1 | L5: 50 | M5: 4 | N5: 25 | O5: 0.09 | P5: 5 | Q5: 4 | R5: 0 | S5: 0 | T5: 0 | U5: 1 | V5: 0 | W5: 0 | X5: 0 | Y5: 0 | Z5: 0 | AA5: 0 | AB5: 1 | AC5: 1 | AD5: 2 | AE5: 0 | AF5: 3 | AG5: 0 | AH5: 0 | AI5: -
A6: 95 | B6: David Pastrnak | C6: BOS | D6: R | E6: 1 | F6: 17.533333 | G6: 1 | H6: 2 | I6: 2 | J6: 0 | K6: 3 | L6: 100 | M6: 6 | N6: 16.67 | O6: 0.69 | P6: 12 | Q6: 9 | R6: 6 | S6: 1 | T6: 0 | U6: 1 | V6: 0 | W6: 0 | X6: 0 | Y6: 0 | Z6: 0 | AA6: 0 | AB6: 1 | AC6: 0 | AD6: 1 | AE6: 2 | AF6: 0 | AG6: 0 | AH6: 0 | AI6: -
A7: 81 | B7: Elias Lindholm | C7: BOS | D7: C | E7: 1 | F7: 19.733333 | G7: 1 | H7: 1 | I7: 0 | J7: 1 | K7: 2 | L7: 100 | M7: 3 | N7: 33.33 | O7: 0.83 | P7: 6 | Q7: 6 | R7: 5 | S7: 4 | T7: 0 | U7: 2 | V7: 0 | W7: 0 | X7: 0 | Y7: 0 | Z7: 0 | AA7: 0 | AB7: 0 | AC7: 2 | AD7: 0 | AE7: 0 | AF7: 1 | AG7: 10 | AH7: 13 | AI7: 43.48
A8: 264 | B8: Fraser Minten | C8: BOS | D8: C | E8: 1 | F8: 13.45 | G8: 0 | H8: 0 | I8: 0 | J8: 0 | K8: 0 | L8: - | M8: 1 | N8: 0 | O8: 0.06 | P8: 1 | Q8: 1 | R8: 1 | S8: 0 | T8: 0 | U8: 0 | V8: 0 | W8: 0 | X8: 0 | Y8: 0 | Z8: 0 | AA8: 0 | AB8: 1 | AC8: 1 | AD8: 0 | AE8: 0 | AF8: 0 | AG8: 5 | AH8: 6 | AI8: 45.45
A9: 53 | B9: Hampus Lindholm | C9: BOS | D9: D | E9: 1 | F9: 19.7 | G9: 0 | H9: 0 | I9: 0 | J9: 0 | K9: 0 | L9: 0 | M9: 0 | N9: - | O9: 0.03 | P9: 3 | Q9: 1 | R9: 3 | S9: 0 | T9: 0 | U9: 1 | V9: 0 | W9: 0 | X9: 0 | Y9: 0 | Z9: 0 | AA9: 0 | AB9: 1 | AC9: 1 | AD9: 0 | AE9: 2 | AF9: 2 | AG9: 0 | AH9: 0 | AI9: -
A10: 196 | B10: Jonathan Aspirot | C10: BOS | D10: D | E10: 1 | F10: 17.1 | G10: 0 | H10: 0 | I10: 0 | J10: 0 | K10: 0 | L10: 0 | M10: 2 | N10: 0 | O10: 0.03 | P10: 2 | Q10: 2 | R10: 0 | S10: 0 | T10: 0 | U10: 0 | V10: 2 | W10: 1 | X10: 1 | Y10: 0 | Z10: 0 | AA10: 0 | AB10: 2 | AC10: 0 | AD10: 1 | AE10: 1 | AF10: 2 | AG10: 0 | AH10: 0 | AI10: -
A11: 241 | B11: Marat Khusnutdinov | C11: BOS | D11: C | E11: 1 | F11: 18.033333 | G11: 0 | H11: 0 | I11: 0 | J11: 0 | K11: 0 | L11: - | M11: 0 | N11: - | O11: 0 | P11: 1 | Q11: 0 | R11: 0 | S11: 0 | T11: 0 | U11: 1 | V11: 2 | W11: 1 | X11: 1 | Y11: 0 | Z11: 0 | AA11: 0 | AB11: 0 | AC11: 1 | AD11: 1 | AE11: 2 | AF11: 1 | AG11: 0 | AH11: 0 | AI11: -
A12: 169 | B12: Mark Kastelic | C12: BOS | D12: C | E12: 1 | F12: 9.6333333 | G12: 0 | H12: 0 | I12: 0 | J12: 0 | K12: 0 | L12: 0 | M12: 0 | N12: - | O12: 0 | P12: 0 | Q12: 0 | R12: 0 | S12: 0 | T12: 0 | U12: 0 | V12: 5 | W12: 1 | X12: 0 | Y12: 1 | Z12: 0 | AA12: 1 | AB12: 0 | AC12: 0 | AD12: 3 | AE12: 0 | AF12: 0 | AG12: 2 | AH12: 2 | AI12: 50
A13: 244 | B13: Mason Lohrei | C13: BOS | D13: D | E13: 1 | F13: 13.016667 | G13: 0 | H13: 0 | I13: 0 | J13: 0 | K13: 0 | L13: 0 | M13: 1 | N13: 0 | O13: 0.06 | P13: 2 | Q13: 2 | R13: 0 | S13: 0 | T13: 0 | U13: 1 | V13: 0 | W13: 0 | X13: 0 | Y13: 0 | Z13: 0 | AA13: 0 | AB13: 1 | AC13: 0 | AD13: 0 | AE13: 2 | AF13: 2 | AG13: 0 | AH13: 0 | AI13: -
A14: 153 | B14: Morgan Geekie | C14: BOS | D14: C | E14: 1 | F14: 15.516667 | G14: 0 | H14: 2 | I14: 0 | J14: 2 | K14: 2 | L14: 100 | M14: 1 | N14: 0 | O14: 0.08 | P14: 3 | Q14: 2 | R14: 0 | S14: 0 | T14: 0 | U14: 0 | V14: 2 | W14: 1 | X14: 1 | Y14: 0 | Z14: 0 | AA14: 1 | AB14: 0 | AC14: 0 | AD14: 4 | AE14: 1 | AF14: 0 | AG14: 1 | AH14: 1 | AI14: 50
A15: 85 | B15: Nikita Zadorov | C15: BOS | D15: D | E15: 1 | F15: 20.616667 | G15: 0 | H15: 1 | I15: 1 | J15: 0 | K15: 1 | L15: 100 | M15: 1 | N15: 0 | O15: 0.05 | P15: 5 | Q15: 2 | R15: 1 | S15: 0 | T15: 0 | U15: 0 | V15: 2 | W15: 1 | X15: 1 | Y15: 0 | Z15: 0 | AA15: 0 | AB15: 2 | AC15: 0 | AD15: 1 | AE15: 2 | AF15: 2 | AG15: 0 | AH15: 0 | AI15: -
A16: 109 | B16: Pavel Zacha | C16: BOS | D16: C | E16: 1 | F16: 17.15 | G16: 0 | H16: 0 | I16: 0 | J16: 0 | K16: 0 | L16: 0 | M16: 4 | N16: 0 | O16: 0.66 | P16: 4 | Q16: 4 | R16: 3 | S16: 3 | T16: 0 | U16: 1 | V16: 2 | W16: 1 | X16: 1 | Y16: 0 | Z16: 0 | AA16: 0 | AB16: 0 | AC16: 1 | AD16: 0 | AE16: 1 | AF16: 1 | AG16: 3 | AH16: 10 | AI16: 23.08
A17: 42 | B17: Sean Kuraly | C17: BOS | D17: C | E17: 1 | F17: 12.466667 | G17: 0 | H17: 1 | I17: 1 | J17: 0 | K17: 1 | L17: 100 | M17: 0 | N17: - | O17: 0 | P17: 0 | Q17: 0 | R17: 0 | S17: 0 | T17: 0 | U17: 0 | V17: 0 | W17: 0 | X17: 0 | Y17: 0 | Z17: 0 | AA17: 0 | AB17: 0 | AC17: 0 | AD17: 1 | AE17: 1 | AF17: 3 | AG17: 4 | AH17: 2 | AI17: 66.67
A18: 150 | B18: Tanner Jeannot | C18: BOS | D18: L | E18: 1 | F18: 8.7 | G18: 1 | H18: 0 | I18: 0 | J18: 0 | K18: 1 | L18: 100 | M18: 1 | N18: 100 | O18: 0.14 | P18: 3 | Q18: 2 | R18: 0 | S18: 0 | T18: 0 | U18: 0 | V18: 0 | W18: 0 | X18: 0 | Y18: 0 | Z18: 0 | AA18: 0 | AB18: 1 | AC18: 0 | AD18: 2 | AE18: 0 | AF18: 0 | AG18: 0 | AH18: 0 | AI18: -
A19: 100 | B19: Viktor Arvidsson | C19: BOS | D19: L | E19: 1 | F19: 15.35 | G19: 0 | H19: 0 | I19: 0 | J19: 0 | K19: 0 | L19: - | M19: 4 | N19: 0 | O19: 0.47 | P19: 9 | Q19: 6 | R19: 6 | S19: 4 | T19: 1 | U19: 3 | V19: 0 | W19: 0 | X19: 0 | Y19: 0 | Z19: 0 | AA19: 0 | AB19: 0 | AC19: 1 | AD19: 1 | AE19: 4 | AF19: 1 | AG19: 0 | AH19: 0 | AI19: -
A20: 94 | B20: Alex Tuch | C20: BUF | D20: R | E20: 1 | F20: 19.766667 | G20: 0 | H20: 0 | I20: 0 | J20: 0 | K20: 0 | L20: 0 | M20: 4 | N20: 0 | O20: 0.18 | P20: 4 | Q20: 4 | R20: 2 | S20: 1 | T20: 0 | U20: 0 | V20: 0 | W20: 0 | X20: 0 | Y20: 0 | Z20: 0 | AA20: 1 | AB20: 0 | AC20: 1 | AD20: 3 | AE20: 0 | AF20: 3 | AG20: 0 | AH20: 1 | AI20: 0
A21: 141 | B21: Beck Malenstyn | C21: BUF | D21: L | E21: 1 | F21: 11.683333 | G21: 1 | H21: 0 | I21: 0 | J21: 0 | K21: 1 | L21: 100 | M21: 1 | N21: 100 | O21: 0.15 | P21: 1 | Q21: 1 | R21: 1 | S21: 1 | T21: 0 | U21: 0 | V21: 0 | W21: 0 | X21: 0 | Y21: 0 | Z21: 0 | AA21: 0 | AB21: 0 | AC21: 0 | AD21: 6 | AE21: 2 | AF21: 2 | AG21: 1 | AH21: 1 | AI21: 50
A22: 201 | B22: Bowen Byram | C22: BUF | D22: D | E22: 1 | F22: 27.35 | G22: 0 | H22: 0 | I22: 0 | J22: 0 | K22: 0 | L22: 0 | M22: 1 | N22: 0 | O22: 0.07 | P22: 3 | Q22: 2 | R22: 2 | S22: 0 | T22: 0 | U22: 0 | V22: 0 | W22: 0 | X22: 0 | Y22: 0 | Z22: 0 | AA22: 0 | AB22: 1 | AC22: 0 | AD22: 1 | AE22: 4 | AF22: 0 | AG22: 0 | AH22: 0 | AI22: -
A23: 227 | B23: Jack Quinn | C23: BUF | D23: R | E23: 1 | F23: 16.95 | G23: 0 | H23: 1 | I23: 1 | J23: 0 | K23: 1 | L23: 100 | M23: 1 | N23: 0 | O23: 0.18 | P23: 4 | Q23: 2 | R23: 2 | S23: 1 | T23: 0 | U23: 0 | V23: 0 | W23: 0 | X23: 0 | Y23: 0 | Z23: 0 | AA23: 0 | AB23: 0 | AC23: 0 | AD23: 0 | AE23: 2 | AF23: 0 | AG23: 0 | AH23: 0 | AI23: -
A24: 164 | B24: Jacob Bryson | C24: BUF | D24: D | E24: 1 | F24: 6.2833333 | G24: 0 | H24: 0 | I24: 0 | J24: 0 | K24: 0 | L24: 0 | M24: 0 | N24: - | O24: 0 | P24: 1 | Q24: 0 | R24: 0 | S24: 0 | T24: 0 | U24: 0 | V24: 0 | W24: 0 | X24: 0 | Y24: 0 | Z24: 0 | AA24: 0 | AB24: 0 | AC24: 0 | AD24: 0 | AE24: 3 | AF24: 2 | AG24: 0 | AH24: 0 | AI24: -
A25: 28 | B25: Jason Zucker | C25: BUF | D25: L | E25: 1 | F25: 17 | G25: 1 | H25: 0 | I25: 0 | J25: 0 | K25: 1 | L25: 100 | M25: 2 | N25: 50 | O25: 0.12 | P25: 2 | Q25: 2 | R25: 2 | S25: 0 | T25: 0 | U25: 0 | V25: 0 | W25: 0 | X25: 0 | Y25: 0 | Z25: 0 | AA25: 0 | AB25: 1 | AC25: 0 | AD25: 1 | AE25: 0 | AF25: 1 | AG25: 0 | AH25: 1 | AI25: 0
A26: 112 | B26: Jordan Greenway | C26: BUF | D26: L | E26: 1 | F26: 10.95 | G26: 0 | H26: 0 | I26: 0 | J26: 0 | K26: 0 | L26: 0 | M26: 0 | N26: - | O26: 0 | P26: 0 | Q26: 0 | R26: 0 | S26: 0 | T26: 0 | U26: 0 | V26: 0 | W26: 0 | X26: 0 | Y26: 0 | Z26: 0 | AA26: 0 | AB26: 1 | AC26: 1 | AD26: 0 | AE26: 2 | AF26: 0 | AG26: 0 | AH26: 0 | AI26: -
A27: 246 | B27: Josh Doan | C27: BUF | D27: R | E27: 1 | F27: 15.433333 | G27: 0 | H27: 0 | I27: 0 | J27: 0 | K27: 0 | L27: - | M27: 0 | N27: - | O27: 0 | P27: 1 | Q27: 0 | R27: 1 | S27: 1 | T27: 0 | U27: 0 | V27: 0 | W27: 0 | X27: 0 | Y27: 0 | Z27: 0 | AA27: 0 | AB27: 0 | AC27: 0 | AD27: 1 | AE27: 1 | AF27: 0 | AG27: 0 | AH27: 0 | AI27: -
A28: 285 | B28: Konsta Helenius | C28: BUF | D28: C | E28: 1 | F28: 9.6 | G28: 0 | H28: 1 | I28: 1 | J28: 0 | K28: 1 | L28: 100 | M28: 1 | N28: 0 | O28: 0.07 | P28: 2 | Q28: 2 | R28: 1 | S28: 0 | T28: 0 | U28: 0 | V28: 0 | W28: 0 | X28: 0 | Y28: 0 | Z28: 0 | AA28: 0 | AB28: 1 | AC28: 0 | AD28: 1 | AE28: 1 | AF28: 1 | AG28: 1 | AH28: 2 | AI28: 33.33
A29: 175 | B29: Mattias Samuelsson | C29: BUF | D29: D | E29: 1 | F29: 23.05 | G29: 0 | H29: 1 | I29: 1 | J29: 0 | K29: 1 | L29: 100 | M29: 0 | N29: - | O29: 0.03 | P29: 4 | Q29: 1 | R29: 1 | S29: 0 | T29: 0 | U29: 0 | V29: 2 | W29: 1 | X29: 1 | Y29: 0 | Z29: 0 | AA29: 1 | AB29: 1 | AC29: 1 | AD29: 5 | AE29: 1 | AF29: 2 | AG29: 0 | AH29: 0 | AI29: -
A30: 186 | B30: Michael Kesselring | C30: BUF | D30: D | E30: 1 | F30: 12.066667 | G30: 0 | H30: 0 | I30: 0 | J30: 0 | K30: 0 | L30: 0 | M30: 2 | N30: 0 | O30: 0.09 | P30: 2 | Q30: 2 | R30: 1 | S30: 0 | T30: 0 | U30: 0 | V30: 2 | W30: 1 | X30: 1 | Y30: 0 | Z30: 0 | AA30: 0 | AB30: 0 | AC30: 0 | AD30: 0 | AE30: 1 | AF30: 1 | AG30: 0 | AH30: 0 | AI30: -
A31: 266 | B31: Noah Ostlund | C31: BUF | D31: C | E31: 1 | F31: 13.033333 | G31: 0 | H31: 1 | I31: 0 | J31: 1 | K31: 1 | L31: 100 | M31: 0 | N31: - | O31: 0 | P31: 0 | Q31: 0 | R31: 0 | S31: 0 | T31: 0 | U31: 0 | V31: 2 | W31: 1 | X31: 1 | Y31: 0 | Z31: 0 | AA31: 0 | AB31: 1 | AC31: 1 | AD31: 0 | AE31: 0 | AF31: 0 | AG31: 0 | AH31: 3 | AI31: 0
A32: 248 | B32: Owen Power | C32: BUF | D32: D | E32: 1 | F32: 26.416667 | G32: 0 | H32: 0 | I32: 0 | J32: 0 | K32: 0 | L32: 0 | M32: 0 | N32: - | O32: 0 | P32: 2 | Q32: 0 | R32: 0 | S32: 0 | T32: 0 | U32: 0 | V32: 0 | W32: 0 | X32: 0 | Y32: 0 | Z32: 0 | AA32: 0 | AB32: 2 | AC32: 0 | AD32: 1 | AE32: 3 | AF32: 2 | AG32: 0 | AH32: 0 | AI32: -
A33: 199 | B33: Peyton Krebs | C33: BUF | D33: C | E33: 1 | F33: 10.633333 | G33: 1 | H33: 0 | I33: 0 | J33: 0 | K33: 1 | L33: 100 | M33: 1 | N33: 100 | O33: 0.17 | P33: 1 | Q33: 1 | R33: 0 | S33: 0 | T33: 0 | U33: 0 | V33: 0 | W33: 0 | X33: 0 | Y33: 0 | Z33: 0 | AA33: 0 | AB33: 0 | AC33: 0 | AD33: 4 | AE33: 1 | AF33: 0 | AG33: 4 | AH33: 3 | AI33: 57.14
A34: 181 | B34: Rasmus Dahlin | C34: BUF | D34: D | E34: 1 | F34: 22.883333 | G34: 0 | H34: 0 | I34: 0 | J34: 0 | K34: 0 | L34: - | M34: 1 | N34: 0 | O34: 0.12 | P34: 7 | Q34: 2 | R34: 3 | S34: 0 | T34: 0 | U34: 1 | V34: 4 | W34: 2 | X34: 2 | Y34: 0 | Z34: 0 | AA34: 2 | AB34: 1 | AC34: 0 | AD34: 1 | AE34: 3 | AF34: 2 | AG34: 0 | AH34: 0 | AI34: -
A35: 172 | B35: Ryan McLeod | C35: BUF | D35: C | E35: 1 | F35: 20.883333 | G35: 0 | H35: 1 | I35: 0 | J35: 1 | K35: 1 | L35: 100 | M35: 0 | N35: - | O35: 0.4 | P35: 4 | Q35: 2 | R35: 1 | S35: 0 | T35: 0 | U35: 0 | V35: 0 | W35: 0 | X35: 0 | Y35: 0 | Z35: 0 | AA35: 0 | AB35: 0 | AC35: 1 | AD35: 1 | AE35: 2 | AF35: 0 | AG35: 9 | AH35: 12 | AI35: 42.86
A36: 146 | B36: Tage Thompson | C36: BUF | D36: C | E36: 1 | F36: 17.233333 | G36: 0 | H36: 1 | I36: 1 | J36: 0 | K36: 1 | L36: 100 | M36: 1 | N36: 0 | O36: 0.09 | P36: 2 | Q36: 2 | R36: 0 | S36: 0 | T36: 0 | U36: 0 | V36: 0 | W36: 0 | X36: 0 | Y36: 0 | Z36: 0 | AA36: 0 | AB36: 0 | AC36: 0 | AD36: 0 | AE36: 0 | AF36: 2 | AG36: 5 | AH36: 13 | AI36: 27.78
A37: 276 | B37: Zach Benson | C37: BUF | D37: L | E37: 1 | F37: 10.783333 | G37: 1 | H37: 0 | I37: 0 | J37: 0 | K37: 1 | L37: 100 | M37: 2 | N37: 50 | O37: 0.68 | P37: 4 | Q37: 4 | R37: 3 | S37: 3 | T37: 0 | U37: 1 | V37: 0 | W37: 0 | X37: 0 | Y37: 0 | Z37: 0 | AA37: 0 | AB37: 0 | AC37: 0 | AD37: 1 | AE37: 2 | AF37: 0 | AG37: 0 | AH37: 0 | AI37: -
A38: 228 | B38: Alexander Nikishin | C38: CAR | D38: D | E38: 1 | F38: 15.783333 | G38: 0 | H38: 0 | I38: 0 | J38: 0 | K38: 0 | L38: 0 | M38: 1 | N38: 0 | O38: 0.14 | P38: 4 | Q38: 2 | R38: 3 | S38: 0 | T38: 0 | U38: 0 | V38: 5 | W38: 1 | X38: 0 | Y38: 1 | Z38: 0 | AA38: 2 | AB38: 0 | AC38: 0 | AD38: 2 | AE38: 0 | AF38: 1 | AG38: 0 | AH38: 0 | AI38: -
A39: 179 | B39: Andrei Svechnikov | C39: CAR | D39: R | E39: 1 | F39: 22.2 | G39: 0 | H39: 0 | I39: 0 | J39: 0 | K39: 0 | L39: - | M39: 1 | N39: 0 | O39: 0.18 | P39: 4 | Q39: 3 | R39: 3 | S39: 1 | T39: 0 | U39: 1 | V39: 0 | W39: 0 | X39: 0 | Y39: 0 | Z39: 0 | AA39: 1 | AB39: 2 | AC39: 0 | AD39: 2 | AE39: 0 | AF39: 1 | AG39: 0 | AH39: 0 | AI39: -
A40: 65 | B40: Jaccob Slavin | C40: CAR | D40: D | E40: 1 | F40: 23.533333 | G40: 0 | H40: 1 | I40: 0 | J40: 1 | K40: 1 | L40: 50 | M40: 1 | N40: 0 | O40: 0.02 | P40: 2 | Q40: 2 | R40: 0 | S40: 0 | T40: 0 | U40: 0 | V40: 0 | W40: 0 | X40: 0 | Y40: 0 | Z40: 0 | AA40: 0 | AB40: 2 | AC40: 1 | AD40: 0 | AE40: 3 | AF40: 1 | AG40: 0 | AH40: 0 | AI40: -
...
