Workbook

Sheet Actual
A1: Player | B1: Roster Position | C1: %Drafted | D1: FPTS
A2: Nathan MacKinnon | B2: C | C2: 0.2846 | D2: 11.5
A3: Victor Olofsson | B3: W | C3: 0.2487 | D3: 14.3
A4: Will Smith | B4: W | C4: 0.2414 | D4: 13
A5: Macklin Celebrini | B5: C | C5: 0.2361 | D5: 23
A6: Dougie Hamilton | B6: D | C6: 0.1772 | D6: 7.8
A7: Jared McCann | B7: W | C7: 0.1536 | D7: 13
A8: Matty Beniers | B8: C | C8: 0.1514 | D8: 7.8
A9: Martin Necas | B9: UTIL | C9: 0.1508 | D9: 26.5
A10: Philipp Grubauer | B10: G | C10: 0.1433 | D10: 8.4
A11: Nikita Kucherov | B11: W | C11: 0.1427 | D11: 11.5
A12: Logan Thompson | B12: G | C12: 0.1248 | D12: 20
A13: Brandon Hagel | B13: W | C13: 0.1222 | D13: 8
... A303: Ian Moore | B303: W | C303: 0.0003 | D303: 9.8

Sheet Projection
A1: name | B1: team | C1: position | D1: dk_pos | E1: salary | F1: projected_fpts | G1: floor | H1: ceiling | I1: dk_avg_fpts | J1: edge | K1: value | L1: goals_per_game | M1: assists_per_game | N1: shots_per_game | O1: pp_points_per_game | P1: projection_date | Q1: timestamp | R1: actual | S1: ownership | T1: TOI
A2: Freddy Gaudreau | B2: SEA | C2: C | D2: RW | E2: 2900 | F2: 5.8025683 | G2: 2.3210273 | H2: 19.506421 | I2: 5.15 | J2: 0.65256828 | K2: 2.0008856 | L2: 0.11111111 | M2: 0.25 | N2: 1.0555556 | O2: 0.055555556 | P2: 2026-01-23 | Q2: 20260123_190750 | R2: =IFERROR(VLOOKUP($A2,Actual!$A:$D,4,FALSE),IFERROR(VLOOKUP($A2,FC!$A:$AC,29,FALSE), "Not Found")) -> 1.5 | S2: =IFERROR(VLOOKUP($A2,Actual!$A:$D,3,FALSE),"0") -> 0.0006 | T2: =VLOOKUP(A2,NHT!B:F,5,FALSE) -> 13.416667
A3: Martin Fehervary | B3: WSH | C3: D | D3: D | E3: 3300 | F3: 6.8597419 | G3: 2.7438967 | H3: 22.149355 | I3: 7.14 | J3: -0.28025813 | K3: 2.0787097 | L3: 0.058823529 | M3: 0.2745098 | N3: 1.0588235 | O3: 0 | P3: 2026-01-23 | Q3: 20260123_190750 | R3: =IFERROR(VLOOKUP($A3,Actual!$A:$D,4,FALSE),IFERROR(VLOOKUP($A3,FC!$A:$AC,29,FALSE), "Not Found")) -> 14.3 | S3: =IFERROR(VLOOKUP($A3,Actual!$A:$D,3,FALSE),"0") -> 0.0048 | T3: =VLOOKUP(A3,NHT!B:F,5,FALSE) -> 18.983333
A4: Arvid Soderblom | B4: CHI | C4: G | D4: G | E4: 7000 | F4: 8.4987664 | G4: 2.5496299 | H4: 26.997533 | I4: 6.69 | J4: 1.8087664 | K4: 1.2141095 | P4: 2026-01-23 | Q4: 20260123_190750 | R4: =IFERROR(VLOOKUP($A4,Actual!$A:$D,4,FALSE),IFERROR(VLOOKUP($A4,FC!$A:$AC,29,FALSE), "Not Found")) -> 19.5 | S4: =IFERROR(VLOOKUP($A4,Actual!$A:$D,3,FALSE),"0") -> 0.021 | T4: =VLOOKUP(A4,NHT!B:F,5,FALSE) -> 65
A5: Andrei Vasilevskiy | B5: TBL | C5: G | D5: G | E5: 8400 | F5: 14.900869 | G5: 4.4702607 | H5: 39.801738 | I5: 13.4 | J5: 1.5008691 | K5: 1.773913 | P5: 2026-01-23 | Q5: 20260123_190750 | R5: =IFERROR(VLOOKUP($A5,Actual!$A:$D,4,FALSE),IFERROR(VLOOKUP($A5,FC!$A:$AC,29,FALSE), "Not Found")) -> 14.4 | S5: =IFERROR(VLOOKUP($A5,Actual!$A:$D,3,FALSE),"0") -> 0.0877 | T5: =VLOOKUP(A5,NHT!B:F,5,FALSE) -> 65
A6: Alex Nedeljkovic | B6: SJS | C6: G | D6: G | E6: 8000 | F6: 14.092368 | G6: 4.2277105 | H6: 38.184737 | I6: 10.26 | J6: 3.8323685 | K6: 1.7615461 | P6: 2026-01-23 | Q6: 20260123_190750 | R6: =IFERROR(VLOOKUP($A6,Actual!$A:$D,4,FALSE),IFERROR(VLOOKUP($A6,FC!$A:$AC,29,FALSE), "Not Found")) -> 22.1 | S6: =IFERROR(VLOOKUP($A6,Actual!$A:$D,3,FALSE),"0") -> 0.0502 | T6: =VLOOKUP(A6,NHT!B:F,5,FALSE) -> 60
A7: Lukas Dostal | B7: ANA | C7: G | D7: G | E7: 7600 | F7: 12.135659 | G7: 3.6406977 | H7: 34.271318 | I7: 10.22 | J7: 1.915659 | K7: 1.5967972 | P7: 2026-01-23 | Q7: 20260123_190750 | R7: =IFERROR(VLOOKUP($A7,Actual!$A:$D,4,FALSE),IFERROR(VLOOKUP($A7,FC!$A:$AC,29,FALSE), "Not Found")) -> 13 | S7: =IFERROR(VLOOKUP($A7,Actual!$A:$D,3,FALSE),"0") -> 0.0589 | T7: =VLOOKUP(A7,NHT!B:F,5,FALSE) -> 60
A8: Adin Hill | B8: VGK | C8: G | D8: G | E8: 7900 | F8: 6.7077291 | G8: 2.0123187 | H8: 23.415458 | I8: 5.49 | J8: 1.2177291 | K8: 0.84907963 | P8: 2026-01-23 | Q8: 20260123_190750 | R8: =IFERROR(VLOOKUP($A8,Actual!$A:$D,4,FALSE),IFERROR(VLOOKUP($A8,FC!$A:$AC,29,FALSE), "Not Found")) -> 8.1 | S8: =IFERROR(VLOOKUP($A8,Actual!$A:$D,3,FALSE),"0") -> 0.0084 | T8: =VLOOKUP(A8,NHT!B:F,5,FALSE) -> 60
A9: Jacob Markstrom | B9: NJD | C9: G | D9: G | E9: 8100 | F9: 10.52228 | G9: 3.1566841 | H9: 31.044561 | I9: 9.07 | J9: 1.4522803 | K9: 1.2990469 | P9: 2026-01-23 | Q9: 20260123_190750 | R9: =IFERROR(VLOOKUP($A9,Actual!$A:$D,4,FALSE),IFERROR(VLOOKUP($A9,FC!$A:$AC,29,FALSE), "Not Found")) -> 6.7 | S9: =IFERROR(VLOOKUP($A9,Actual!$A:$D,3,FALSE),"0") -> 0.0505 | T9: =VLOOKUP(A9,NHT!B:F,5,FALSE) -> 60
A10: Samuel Ersson | B10: PHI | C10: G | D10: G | E10: 7100 | F10: 6.4049538 | G10: 1.9214862 | H10: 22.809908 | I10: 4.95 | J10: 1.4549538 | K10: 0.90210618 | P10: 2026-01-23 | Q10: 20260123_190750 | R10: =IFERROR(VLOOKUP($A10,Actual!$A:$D,4,FALSE),IFERROR(VLOOKUP($A10,FC!$A:$AC,29,FALSE), "Not Found")) -> 17.9 | S10: =IFERROR(VLOOKUP($A10,Actual!$A:$D,3,FALSE),"0") -> 0.0179 | T10: =VLOOKUP(A10,NHT!B:F,5,FALSE) -> 59.9
A11: Logan Thompson | B11: WSH | C11: G | D11: G | E11: 7800 | F11: 14.06135 | G11: 4.2184049 | H11: 38.122699 | I11: 12.91 | J11: 1.1513497 | K11: 1.8027371 | P11: 2026-01-23 | Q11: 20260123_190750 | R11: =IFERROR(VLOOKUP($A11,Actual!$A:$D,4,FALSE),IFERROR(VLOOKUP($A11,FC!$A:$AC,29,FALSE), "Not Found")) -> 20 | S11: =IFERROR(VLOOKUP($A11,Actual!$A:$D,3,FALSE),"0") -> 0.1248 | T11: =VLOOKUP(A11,NHT!B:F,5,FALSE) -> 59.866667
A12: Jake Oettinger | B12: DAL | C12: G | D12: G | E12: 8200 | F12: 13.623843 | G12: 4.0871529 | H12: 37.247686 | I12: 11.92 | J12: 1.7038429 | K12: 1.6614443 | P12: 2026-01-23 | Q12: 20260123_190750 | R12: =IFERROR(VLOOKUP($A12,Actual!$A:$D,4,FALSE),IFERROR(VLOOKUP($A12,FC!$A:$AC,29,FALSE), "Not Found")) -> 13 | S12: =IFERROR(VLOOKUP($A12,Actual!$A:$D,3,FALSE),"0") -> 0.0622 | T12: =VLOOKUP(A12,NHT!B:F,5,FALSE) -> 59.8
A13: Jordan Binnington | B13: STL | C13: G | D13: G | E13: 7200 | F13: 7.5891931 | G13: 2.2767579 | H13: 25.178386 | I13: 6.4 | J13: 1.1891931 | K13: 1.0540546 | P13: 2026-01-23 | Q13: 20260123_190750 | R13: =IFERROR(VLOOKUP($A13,Actual!$A:$D,4,FALSE),IFERROR(VLOOKUP($A13,FC!$A:$AC,29,FALSE), "Not Found")) -> 0.7 | S13: =IFERROR(VLOOKUP($A13,Actual!$A:$D,3,FALSE),"0") -> 0.032 | T13: =VLOOKUP(A13,NHT!B:F,5,FALSE) -> 59
A14: Philipp Grubauer | B14: SEA | C14: G | D14: G | E14: 7800 | F14: 17.544782 | G14: 5.2634347 | H14: 45.089565 | I14: 13.82 | J14: 3.7247825 | K14: 2.2493311 | P14: 2026-01-23 | Q14: 20260123_190750 | R14: =IFERROR(VLOOKUP($A14,Actual!$A:$D,4,FALSE),IFERROR(VLOOKUP($A14,FC!$A:$AC,29,FALSE), "Not Found")) -> 8.4 | S14: =IFERROR(VLOOKUP($A14,Actual!$A:$D,3,FALSE),"0") -> 0.1433 | T14: =VLOOKUP(A14,NHT!B:F,5,FALSE) -> 58.683333
A15: Devin Cooley | B15: CGY | C15: G | D15: G | E15: 7600 | F15: 16.854585 | G15: 5.0563756 | H15: 43.709171 | I15: 12.58 | J15: 4.2745854 | K15: 2.2177086 | P15: 2026-01-23 | Q15: 20260123_190750 | R15: =IFERROR(VLOOKUP($A15,Actual!$A:$D,4,FALSE),IFERROR(VLOOKUP($A15,FC!$A:$AC,29,FALSE), "Not Found")) -> 20.5 | S15: =IFERROR(VLOOKUP($A15,Actual!$A:$D,3,FALSE),"0") -> 0.0771 | T15: =VLOOKUP(A15,NHT!B:F,5,FALSE) -> 58.333333
... A18: Kevin Lankinen | B18: VAN | C18: G | D18: G | E18: 7300 | F18: 11.207059 | G18: 3.3621178 | H18: 32.414119 | I18: 9.15 | J18: 2.0570593 | K18: 1.5352136 | P18: 2026-01-23 | Q18: 20260123_190750 | R18: =IFERROR(VLOOKUP($A18,Actual!$A:$D,4,FALSE),IFERROR(VLOOKUP($A18,FC!$A:$AC,29,FALSE), "Not Found")) -> -4.2 | S18: =IFERROR(VLOOKUP($A18,Actual!$A:$D,3,FALSE),"0") -> 0.0628 | T18: =VLOOKUP(A18,NHT!B:F,5,FALSE) -> 56.266667
A19: Vladislav Gavrikov | B19: NYR | C19: D | D19: D | E19: 4000 | F19: 9.0285801 | G19: 3.611432 | H19: 27.57145 | I19: 7.19 | J19: 1.8385801 | K19: 2.257145 | L19: 0.15686275 | M19: 0.17647059 | N19: 1.4705882 | O19: 0.039215686 | P19: 2026-01-23 | Q19: 20260123_190750 | R19: =IFERROR(VLOOKUP($A19,Actual!$A:$D,4,FALSE),IFERROR(VLOOKUP($A19,FC!$A:$AC,29,FALSE), "Not Found")) -> 4.5 | S19: =IFERROR(VLOOKUP($A19,Actual!$A:$D,3,FALSE),"0") -> 0.0917 | T19: =VLOOKUP(A19,NHT!B:F,5,FALSE) -> 28.033333
A20: Brandon Montour | B20: SEA | C20: D | D20: D | E20: 5400 | F20: 13.631743 | G20: 5.4526972 | H20: 39.079357 | I20: 10.08 | J20: 3.5517429 | K20: 2.5243968 | L20: 0.19354839 | M20: 0.41935484 | N20: 2.6129032 | O20: 0.19354839 | P20: 2026-01-23 | Q20: 20260123_190750 | R20: =IFERROR(VLOOKUP($A20,Actual!$A:$D,4,FALSE),IFERROR(VLOOKUP($A20,FC!$A:$AC,29,FALSE), "Not Found")) -> 5.6 | S20: =IFERROR(VLOOKUP($A20,Actual!$A:$D,3,FALSE),"0") -> 0.0555 | T20: =VLOOKUP(A20,NHT!B:F,5,FALSE) -> 27.9
A21: Filip Hronek | B21: VAN | C21: D | D21: D | E21: 3600 | F21: 9.7507779 | G21: 3.9003112 | H21: 29.376945 | I21: 7.54 | J21: 2.2107779 | K21: 2.7085494 | L21: 0.08 | M21: 0.5 | N21: 1.38 | O21: 0.18 | P21: 2026-01-23 | Q21: 20260123_190750 | R21: =IFERROR(VLOOKUP($A21,Actual!$A:$D,4,FALSE),IFERROR(VLOOKUP($A21,FC!$A:$AC,29,FALSE), "Not Found")) -> 4.1 | S21: =IFERROR(VLOOKUP($A21,Actual!$A:$D,3,FALSE),"0") -> 0.039 | T21: =VLOOKUP(A21,NHT!B:F,5,FALSE) -> 27.45
A22: Miro Heiskanen | B22: DAL | C22: D | D22: D | E22: 6400 | F22: 12.687271 | G22: 5.0749084 | H22: 36.718177 | I22: 11.16 | J22: 1.527271 | K22: 1.9823861 | L22: 0.14285714 | M22: 0.65306122 | N22: 2 | O22: 0.30612245 | P22: 2026-01-23 | Q22: 20260123_190750 | R22: =IFERROR(VLOOKUP($A22,Actual!$A:$D,4,FALSE),IFERROR(VLOOKUP($A22,FC!$A:$AC,29,FALSE), "Not Found")) -> 9.3 | S22: =IFERROR(VLOOKUP($A22,Actual!$A:$D,3,FALSE),"0") -> 0.0308 | T22: =VLOOKUP(A22,NHT!B:F,5,FALSE) -> 27
A23: Darren Raddysh | B23: TBL | C23: D | D23: D | E23: 6700 | F23: 16.470198 | G23: 6.5880791 | H23: 46.175495 | I23: 12.05 | J23: 4.4201978 | K23: 2.4582385 | L23: 0.28571429 | M23: 0.71428571 | N23: 2.4047619 | O23: 0.35714286 | P23: 2026-01-23 | Q23: 20260123_190750 | R23: =IFERROR(VLOOKUP($A23,Actual!$A:$D,4,FALSE),IFERROR(VLOOKUP($A23,FC!$A:$AC,29,FALSE), "Not Found")) -> 11.8 | S23: =IFERROR(VLOOKUP($A23,Actual!$A:$D,3,FALSE),"0") -> 0.0858 | T23: =VLOOKUP(A23,NHT!B:F,5,FALSE) -> 26.85
A24: Cale Makar | B24: COL | C24: D | D24: D | E24: 8200 | F24: 18.973209 | G24: 7.5892836 | H24: 52.433023 | I24: 14.18 | J24: 4.7932091 | K24: 2.313806 | L24: 0.29166667 | M24: 0.83333333 | N24: 2.7083333 | O24: 0.39583333 | P24: 2026-01-23 | Q24: 20260123_190750 | R24: =IFERROR(VLOOKUP($A24,Actual!$A:$D,4,FALSE),IFERROR(VLOOKUP($A24,FC!$A:$AC,29,FALSE), "Not Found")) -> 12.8 | S24: =IFERROR(VLOOKUP($A24,Actual!$A:$D,3,FALSE),"0") -> 0.1119 | T24: =VLOOKUP(A24,NHT!B:F,5,FALSE) -> 26.35
A25: Nathan MacKinnon | B25: COL | C25: C | D25: C | E25: 10200 | F25: 29.00469 | G25: 11.601876 | H25: 77.511726 | I25: 21.83 | J25: 7.1746904 | K25: 2.8435971 | L25: 0.79166667 | M25: 0.97916667 | N25: 4.6875 | O25: 0.45833333 | P25: 2026-01-23 | Q25: 20260123_190750 | R25: =IFERROR(VLOOKUP($A25,Actual!$A:$D,4,FALSE),IFERROR(VLOOKUP($A25,FC!$A:$AC,29,FALSE), "Not Found")) -> 11.5 | S25: =IFERROR(VLOOKUP($A25,Actual!$A:$D,3,FALSE),"0") -> 0.2846 | T25: =VLOOKUP(A25,NHT!B:F,5,FALSE) -> 26.25
A26: Thomas Harley | B26: DAL | C26: D | D26: D | E26: 4900 | F26: 9.0969333 | G26: 3.6387733 | H26: 27.742333 | I26: 9.34 | J26: -0.24306668 | K26: 1.856517 | L26: 0.051282051 | M26: 0.41025641 | N26: 1.5641026 | O26: 0.1025641 | P26: 2026-01-23 | Q26: 20260123_190750 | R26: =IFERROR(VLOOKUP($A26,Actual!$A:$D,4,FALSE),IFERROR(VLOOKUP($A26,FC!$A:$AC,29,FALSE), "Not Found")) -> 2.6 | S26: =IFERROR(VLOOKUP($A26,Actual!$A:$D,3,FALSE),"0") -> 0.0322 | T26: =VLOOKUP(A26,NHT!B:F,5,FALSE) -> 26.033333
A27: Kevin Bahl | B27: CGY | C27: D | D27: D | E27: 2700 | F27: 6.688025 | G27: 2.67521 | H27: 21.720063 | I27: 5.18 | J27: 1.508025 | K27: 2.4770463 | L27: 0.06122449 | M27: 0.18367347 | N27: 0.83673469 | O27: 0 | P27: 2026-01-23 | Q27: 20260123_190750 | R27: =IFERROR(VLOOKUP($A27,Actual!$A:$D,4,FALSE),IFERROR(VLOOKUP($A27,FC!$A:$AC,29,FALSE), "Not Found")) -> 3 | S27: =IFERROR(VLOOKUP($A27,Actual!$A:$D,3,FALSE),"0") -> 0.0168 | T27: =VLOOKUP(A27,NHT!B:F,5,FALSE) -> 25.766667
A28: Martin Necas | B28: COL | C28: C | D28: RW | E28: 7100 | F28: 17.378365 | G28: 6.9513458 | H28: 48.445911 | I28: 12.49 | J28: 4.8883645 | K28: 2.447657 | L28: 0.45833333 | M28: 0.79166667 | N28: 2.2916667 | O28: 0.22916667 | P28: 2026-01-23 | Q28: 20260123_190750 | R28: =IFERROR(VLOOKUP($A28,Actual!$A:$D,4,FALSE),IFERROR(VLOOKUP($A28,FC!$A:$AC,29,FALSE), "Not Found")) -> 26.5 | S28: =IFERROR(VLOOKUP($A28,Actual!$A:$D,3,FALSE),"0") -> 0.1508 | T28: =VLOOKUP(A28,NHT!B:F,5,FALSE) -> 25.266667
A29: J.J. Moser | B29: TBL | C29: D | D29: D | E29: 3100 | F29: 8.7919822 | G29: 3.5167929 | H29: 26.979956 | I29: 6.32 | J29: 2.4719822 | K29: 2.8361233 | L29: 0.10869565 | M29: 0.23913043 | N29: 1.3913043 | O29: 0 | P29: 2026-01-23 | Q29: 20260123_190750 | R29: =IFERROR(VLOOKUP($A29,Actual!$A:$D,4,FALSE),IFERROR(VLOOKUP($A29,FC!$A:$AC,29,FALSE), "Not Found")) -> 5.6 | S29: =IFERROR(VLOOKUP($A29,Actual!$A:$D,3,FALSE),"0") -> 0.0205 | T29: =VLOOKUP(A29,NHT!B:F,5,FALSE) -> 24.85
A30: Macklin Celebrini | B30: SJS | C30: C | D30: C | E30: 9000 | F30: 21.353396 | G30: 8.5413583 | H30: 58.38349 | I30: 16.92 | J30: 4.4333958 | K30: 2.3725995 | L30: 0.48979592 | M30: 0.97959184 | N30: 3.4489796 | O30: 0.42857143 | P30: 2026-01-23 | Q30: 20260123_190750 | R30: =IFERROR(VLOOKUP($A30,Actual!$A:$D,4,FALSE),IFERROR(VLOOKUP($A30,FC!$A:$AC,29,FALSE), "Not Found")) -> 23 | S30: =IFERROR(VLOOKUP($A30,Actual!$A:$D,3,FALSE),"0") -> 0.2361 | T30: =VLOOKUP(A30,NHT!B:F,5,FALSE) -> 24.6
... A287: Jack Finley | B287: TBL | C287: C | D287: C | E287: 2500 | F287: 3.7639038 | G287: 1.5055615 | H287: 14.409759 | I287: 2.33 | J287: 1.4339038 | K287: 1.5055615 | L287: 0.11764706 | M287: 0.058823529 | N287: 0.58823529 | O287: 0 | P287: 2026-01-23 | Q287: 20260123_190750 | R287: =IFERROR(VLOOKUP($A287,Actual!$A:$D,4,FALSE),IFERROR(VLOOKUP($A287,FC!$A:$AC,29,FALSE), "Not Found")) -> 0 | S287: =IFERROR(VLOOKUP($A287,Actual!$A:$D,3,FALSE),"0") -> 0 | T287: =VLOOKUP(A287,NHT!B:F,5,FALSE) -> 1.0166667

Sheet NHT
B1: Player | C1: Team | D1: Position | E1: GP | F1: TOI | G1: Goals | H1: Total Assists | I1: First Assists | J1: Second Assists | K1: Total Points | L1: IPP | M1: Shots | N1: SH% | O1: ixG | P1: iCF | Q1: iFF | R1: iSCF | S1: iHDCF | T1: Rush Attempts | U1: Rebounds Created | V1: PIM | W1: Total Penalties | X1: Minor | Y1: Major | Z1: Misconduct | AA1: Penalties Drawn | AB1: Giveaways | AC1: Takeaways | AD1: Hits | AE1: Hits Taken | AF1: Shots Blocked | AG1: Faceoffs Won | AH1: Faceoffs Lost | AI1: Faceoffs %
A2: 126 | B2: Adam Gaudette | C2: S.J | D2: R | E2: 1 | F2: 12.3 | G2: 0 | H2: 0 | I2: 0 | J2: 0 | K2: 0 | L2: - | M2: 2 | N2: 0 | O2: 0.26 | P2: 2 | Q2: 2 | R2: 1 | S2: 1 | T2: 0 | U2: 0 | V2: 0 | W2: 0 | X2: 0 | Y2: 0 | Z2: 0 | AA2: 0 | AB2: 1 | AC2: 0 | AD2: 0 | AE2: 1 | AF2: 1 | AG2: 1 | AH2: 1 | AI2: 50
A3: 257 | B3: Adam Klapka | C3: CGY | D3: R | E3: 1 | F3: 9.4333333 | G3: 0 | H3: 0 | I3: 0 | J3: 0 | K3: 0 | L3: - | M3: 2 | N3: 0 | O3: 0.61 | P3: 6 | Q3: 5 | R3: 4 | S3: 3 | T3: 0 | U3: 2 | V3: 12 | W3: 2 | X3: 1 | Y3: 0 | Z3: 1 | AA3: 0 | AB3: 0 | AC3: 0 | AD3: 3 | AE3: 1 | AF3: 1 | AG3: 0 | AH3: 0 | AI3: -
A4: 42 | B4: Adam Larsson | C4: SEA | D4: D | E4: 1 | F4: 17.566667 | G4: 0 | H4: 0 | I4: 0 | J4: 0 | K4: 0 | L4: - | M4: 0 | N4: - | O4: 0.02 | P4: 3 | Q4: 2 | R4: 0 | S4: 0 | T4: 0 | U4: 0 | V4: 0 | W4: 0 | X4: 0 | Y4: 0 | Z4: 0 | AA4: 1 | AB4: 1 | AC4: 0 | AD4: 0 | AE4: 0 | AF4: 1 | AG4: 0 | AH4: 0 | AI4: -
A5: 9 | B5: Adin Hill | C5: VGK | D5: G | E5: 1 | F5: 60
A6: 5 | B6: Alex Killorn | C6: ANA | D6: L | E6: 1 | F6: 15.283333 | G6: 0 | H6: 0 | I6: 0 | J6: 0 | K6: 0 | L6: 0 | M6: 1 | N6: 0 | O6: 0.11 | P6: 2 | Q6: 2 | R6: 1 | S6: 0 | T6: 0 | U6: 1 | V6: 2 | W6: 1 | X6: 1 | Y6: 0 | Z6: 0 | AA6: 1 | AB6: 0 | AC6: 0 | AD6: 0 | AE6: 1 | AF6: 1 | AG6: 0 | AH6: 0 | AI6: -
A7: 7 | B7: Alex Nedeljkovic | C7: S.J | D7: G | E7: 1 | F7: 60
A8: 2 | B8: Alex Ovechkin | C8: WSH | D8: L | E8: 1 | F8: 17.816667 | G8: 1 | H8: 0 | I8: 0 | J8: 0 | K8: 1 | L8: 100 | M8: 6 | N8: 16.67 | O8: 0.82 | P8: 10 | Q8: 9 | R8: 5 | S8: 2 | T8: 0 | U8: 0 | V8: 0 | W8: 0 | X8: 0 | Y8: 0 | Z8: 0 | AA8: 0 | AB8: 3 | AC8: 0 | AD8: 1 | AE8: 0 | AF8: 0 | AG8: 0 | AH8: 0 | AI8: -
A9: 196 | B9: Alex Vlasic | C9: CHI | D9: D | E9: 1 | F9: 23.7 | G9: 0 | H9: 0 | I9: 0 | J9: 0 | K9: 0 | L9: - | M9: 2 | N9: 0 | O9: 0.02 | P9: 5 | Q9: 2 | R9: 1 | S9: 0 | T9: 0 | U9: 0 | V9: 0 | W9: 0 | X9: 0 | Y9: 0 | Z9: 0 | AA9: 0 | AB9: 0 | AC9: 1 | AD9: 1 | AE9: 1 | AF9: 3 | AG9: 0 | AH9: 0 | AI9: -
A10: 219 | B10: Alexander Holtz | C10: VGK | D10: R | E10: 1 | F10: 9.75 | G10: 0 | H10: 1 | I10: 0 | J10: 1 | K10: 1 | L10: 100 | M10: 1 | N10: 0 | O10: 0.07 | P10: 2 | Q10: 2 | R10: 1 | S10: 0 | T10: 0 | U10: 0 | V10: 0 | W10: 0 | X10: 0 | Y10: 0 | Z10: 0 | AA10: 0 | AB10: 1 | AC10: 0 | AD10: 2 | AE10: 1 | AF10: 0 | AG10: 0 | AH10: 0 | AI10: -
A11: 83 | B11: Alexander Wennberg | C11: S.J | D11: C | E11: 1 | F11: 24.466667 | G11: 0 | H11: 0 | I11: 0 | J11: 0 | K11: 0 | L11: 0 | M11: 0 | N11: - | O11: 0.92 | P11: 4 | Q11: 4 | R11: 4 | S11: 3 | T11: 0 | U11: 0 | V11: 0 | W11: 0 | X11: 0 | Y11: 0 | Z11: 0 | AA11: 0 | AB11: 1 | AC11: 1 | AD11: 0 | AE11: 0 | AF11: 4 | AG11: 8 | AH11: 13 | AI11: 38.1
A12: 166 | B12: Alexey Toropchenko | C12: STL | D12: R | E12: 1 | F12: 11.916667 | G12: 0 | H12: 0 | I12: 0 | J12: 0 | K12: 0 | L12: - | M12: 0 | N12: - | O12: 0 | P12: 0 | Q12: 0 | R12: 0 | S12: 0 | T12: 0 | U12: 0 | V12: 0 | W12: 0 | X12: 0 | Y12: 0 | Z12: 0 | AA12: 0 | AB12: 0 | AC12: 1 | AD12: 1 | AE12: 1 | AF12: 1 | AG12: 0 | AH12: 0 | AI12: -
A13: 217 | B13: Alexis Lafrenière | C13: NYR | D13: L | E13: 1 | F13: 14.333333 | G13: 0 | H13: 0 | I13: 0 | J13: 0 | K13: 0 | L13: - | M13: 1 | N13: 0 | O13: 0.24 | P13: 3 | Q13: 3 | R13: 2 | S13: 1 | T13: 0 | U13: 0 | V13: 0 | W13: 0 | X13: 0 | Y13: 0 | Z13: 0 | AA13: 0 | AB13: 0 | AC13: 0 | AD13: 2 | AE13: 0 | AF13: 0 | AG13: 0 | AH13: 0 | AI13: -
A14: 205 | B14: Aliaksei Protas | C14: WSH | D14: C | E14: 1 | F14: 19.2 | G14: 1 | H14: 0 | I14: 0 | J14: 0 | K14: 1 | L14: 100 | M14: 3 | N14: 33.33 | O14: 0.59 | P14: 5 | Q14: 5 | R14: 4 | S14: 2 | T14: 0 | U14: 1 | V14: 0 | W14: 0 | X14: 0 | Y14: 0 | Z14: 0 | AA14: 0 | AB14: 1 | AC14: 1 | AD14: 1 | AE14: 2 | AF14: 2 | AG14: 0 | AH14: 0 | AI14: -
A15: 74 | B15: Andre Burakovsky | C15: CHI | D15: L | E15: 1 | F15: 21.433333 | G15: 0 | H15: 0 | I15: 0 | J15: 0 | K15: 0 | L15: - | M15: 3 | N15: 0 | O15: 0.68 | P15: 5 | Q15: 5 | R15: 5 | S15: 4 | T15: 0 | U15: 0 | V15: 0 | W15: 0 | X15: 0 | Y15: 0 | Z15: 0 | AA15: 0 | AB15: 0 | AC15: 1 | AD15: 2 | AE15: 0 | AF15: 1 | AG15: 0 | AH15: 0 | AI15: -
A16: 4 | B16: Andrei Vasilevskiy | C16: T.B | D16: G | E16: 1 | F16: 65
A17: 116 | B17: Anthony Beauvillier | C17: WSH | D17: L | E17: 1 | F17: 13.8 | G17: 0 | H17: 0 | I17: 0 | J17: 0 | K17: 0 | L17: 0 | M17: 2 | N17: 0 | O17: 0.26 | P17: 5 | Q17: 5 | R17: 4 | S17: 3 | T17: 0 | U17: 0 | V17: 0 | W17: 0 | X17: 0 | Y17: 0 | Z17: 0 | AA17: 0 | AB17: 0 | AC17: 0 | AD17: 1 | AE17: 0 | AF17: 0 | AG17: 1 | AH17: 0 | AI17: 100
A18: 122 | B18: Anthony Cirelli | C18: T.B | D18: C | E18: 1 | F18: 19.35 | G18: 0 | H18: 1 | I18: 0 | J18: 1 | K18: 1 | L18: 100 | M18: 2 | N18: 0 | O18: 0.43 | P18: 3 | Q18: 3 | R18: 3 | S18: 2 | T18: 0 | U18: 1 | V18: 0 | W18: 0 | X18: 0 | Y18: 0 | Z18: 0 | AA18: 0 | AB18: 2 | AC18: 1 | AD18: 0 | AE18: 1 | AF18: 1 | AG18: 7 | AH18: 7 | AI18: 50
A19: 5 | B19: Anthony Stolarz | C19: TOR | D19: G | E19: 1 | F19: 58.333333
A20: 67 | B20: Anton Blidh | C20: NYR | D20: L | E20: 1 | F20: 6.2333333 | G20: 0 | H20: 1 | I20: 0 | J20: 1 | K20: 1 | L20: 100 | M20: 3 | N20: 0 | O20: 0.35 | P20: 4 | Q20: 4 | R20: 3 | S20: 2 | T20: 0 | U20: 2 | V20: 0 | W20: 0 | X20: 0 | Y20: 0 | Z20: 0 | AA20: 0 | AB20: 0 | AC20: 0 | AD20: 0 | AE20: 0 | AF20: 0 | AG20: 0 | AH20: 0 | AI20: -
A21: 208 | B21: Arseny Gritsyuk | C21: N.J | D21: R | E21: 1 | F21: 13.233333 | G21: 0 | H21: 1 | I21: 1 | J21: 0 | K21: 1 | L21: 33.33 | M21: 0 | N21: - | O21: 0 | P21: 2 | Q21: 0 | R21: 0 | S21: 0 | T21: 0 | U21: 0 | V21: 0 | W21: 0 | X21: 0 | Y21: 0 | Z21: 0 | AA21: 1 | AB21: 0 | AC21: 0 | AD21: 0 | AE21: 0 | AF21: 0 | AG21: 0 | AH21: 0 | AI21: -
A22: 123 | B22: Artemi Panarin | C22: NYR | D22: L | E22: 1 | F22: 21.166667 | G22: 0 | H22: 0 | I22: 0 | J22: 0 | K22: 0 | L22: - | M22: 3 | N22: 0 | O22: 0.57 | P22: 11 | Q22: 8 | R22: 4 | S22: 1 | T22: 0 | U22: 0 | V22: 0 | W22: 0 | X22: 0 | Y22: 0 | Z22: 0 | AA22: 1 | AB22: 0 | AC22: 0 | AD22: 1 | AE22: 0 | AF22: 0 | AG22: 0 | AH22: 0 | AI22: -
A23: 77 | B23: Artturi Lehkonen | C23: COL | D23: L | E23: 1 | F23: 15.283333 | G23: 0 | H23: 0 | I23: 0 | J23: 0 | K23: 0 | L23: - | M23: 0 | N23: - | O23: 0.09 | P23: 3 | Q23: 1 | R23: 1 | S23: 1 | T23: 0 | U23: 0 | V23: 2 | W23: 1 | X23: 1 | Y23: 0 | Z23: 0 | AA23: 0 | AB23: 2 | AC23: 0 | AD23: 1 | AE23: 2 | AF23: 0 | AG23: 1 | AH23: 0 | AI23: 100
A24: 279 | B24: Artyom Levshunov | C24: CHI | D24: D | E24: 1 | F24: 21.983333 | G24: 0 | H24: 0 | I24: 0 | J24: 0 | K24: 0 | L24: - | M24: 0 | N24: - | O24: 0.02 | P24: 4 | Q24: 2 | R24: 1 | S24: 0 | T24: 0 | U24: 0 | V24: 2 | W24: 1 | X24: 1 | Y24: 0 | Z24: 0 | AA24: 0 | AB24: 4 | AC24: 0 | AD24: 2 | AE24: 1 | AF24: 0 | AG24: 0 | AH24: 0 | AI24: -
A25: 16 | B25: Arvid Soderblom | C25: CHI | D25: G | E25: 1 | F25: 65
A26: 132 | B26: Auston Matthews | C26: TOR | D26: C | E26: 1 | F26: 23.5 | G26: 0 | H26: 0 | I26: 0 | J26: 0 | K26: 0 | L26: 0 | M26: 3 | N26: 0 | O26: 0.35 | P26: 9 | Q26: 6 | R26: 4 | S26: 2 | T26: 0 | U26: 1 | V26: 0 | W26: 0 | X26: 0 | Y26: 0 | Z26: 0 | AA26: 0 | AB26: 0 | AC26: 0 | AD26: 2 | AE26: 2 | AF26: 0 | AG26: 9 | AH26: 5 | AI26: 64.29
A27: 50 | B27: Barclay Goodrow | C27: S.J | D27: C | E27: 1 | F27: 7.5166667 | G27: 0 | H27: 0 | I27: 0 | J27: 0 | K27: 0 | L27: - | M27: 0 | N27: - | O27: 0 | P27: 0 | Q27: 0 | R27: 0 | S27: 0 | T27: 0 | U27: 0 | V27: 0 | W27: 0 | X27: 0 | Y27: 0 | Z27: 0 | AA27: 0 | AB27: 0 | AC27: 0 | AD27: 0 | AE27: 0 | AF27: 2 | AG27: 0 | AH27: 0 | AI27: -
A28: 278 | B28: Beckett Sennecke | C28: ANA | D28: R | E28: 1 | F28: 13.9 | G28: 0 | H28: 0 | I28: 0 | J28: 0 | K28: 0 | L28: 0 | M28: 1 | N28: 0 | O28: 0.22 | P28: 2 | Q28: 2 | R28: 2 | S28: 2 | T28: 0 | U28: 0 | V28: 0 | W28: 0 | X28: 0 | Y28: 0 | Z28: 0 | AA28: 0 | AB28: 0 | AC28: 0 | AD28: 1 | AE28: 2 | AF28: 0 | AG28: 0 | AH28: 0 | AI28: -
A29: 66 | B29: Ben Hutton | C29: VGK | D29: D | E29: 1 | F29: 14.45 | G29: 0 | H29: 0 | I29: 0 | J29: 0 | K29: 0 | L29: 0 | M29: 0 | N29: - | O29: 0 | P29: 1 | Q29: 0 | R29: 0 | S29: 0 | T29: 0 | U29: 0 | V29: 0 | W29: 0 | X29: 0 | Y29: 0 | Z29: 0 | AA29: 0 | AB29: 2 | AC29: 1 | AD29: 0 | AE29: 1 | AF29: 0 | AG29: 0 | AH29: 0 | AI29: -
A30: 281 | B30: Berkly Catton | C30: SEA | D30: C | E30: 1 | F30: 13.616667 | G30: 0 | H30: 0 | I30: 0 | J30: 0 | K30: 0 | L30: - | M30: 1 | N30: 0 | O30: 0.13 | P30: 3 | Q30: 3 | R30: 2 | S30: 0 | T30: 0 | U30: 0 | V30: 0 | W30: 0 | X30: 0 | Y30: 0 | Z30: 0 | AA30: 1 | AB30: 1 | AC30: 0 | AD30: 0 | AE30: 2 | AF30: 0 | AG30: 0 | AH30: 0 | AI30: -
A31: 192 | B31: Bobby Brink | C31: PHI | D31: R | E31: 1 | F31: 13.216667 | G31: 1 | H31: 0 | I31: 0 | J31: 0 | K31: 1 | L31: 100 | M31: 2 | N31: 50 | O31: 0.25 | P31: 3 | Q31: 2 | R31: 2 | S31: 2 | T31: 0 | U31: 0 | V31: 0 | W31: 0 | X31: 0 | Y31: 0 | Z31: 0 | AA31: 0 | AB31: 1 | AC31: 0 | AD31: 0 | AE31: 0 | AF31: 0 | AG31: 0 | AH31: 0 | AI31: -
A32: 230 | B32: Bobby McMann | C32: TOR | D32: C | E32: 1 | F32: 17.316667 | G32: 1 | H32: 0 | I32: 0 | J32: 0 | K32: 1 | L32: 100 | M32: 4 | N32: 25 | O32: 0.36 | P32: 8 | Q32: 7 | R32: 5 | S32: 2 | T32: 0 | U32: 0 | V32: 0 | W32: 0 | X32: 0 | Y32: 0 | Z32: 0 | AA32: 0 | AB32: 0 | AC32: 0 | AD32: 0 | AE32: 0 | AF32: 0 | AG32: 0 | AH32: 0 | AI32: -
A33: 212 | B33: Braden Schneider | C33: NYR | D33: D | E33: 1 | F33: 22.766667 | G33: 0 | H33: 0 | I33: 0 | J33: 0 | K33: 0 | L33: - | M33: 0 | N33: - | O33: 0 | P33: 0 | Q33: 0 | R33: 0 | S33: 0 | T33: 0 | U33: 0 | V33: 0 | W33: 0 | X33: 0 | Y33: 0 | Z33: 0 | AA33: 0 | AB33: 3 | AC33: 0 | AD33: 0 | AE33: 1 | AF33: 2 | AG33: 0 | AH33: 0 | AI33: -
A34: 262 | B34: Braeden Bowman | C34: VGK | D34: R | E34: 1 | F34: 10.3 | G34: 1 | H34: 0 | I34: 0 | J34: 0 | K34: 1 | L34: 100 | M34: 2 | N34: 50 | O34: 0.11 | P34: 4 | Q34: 2 | R34: 3 | S34: 1 | T34: 0 | U34: 0 | V34: 0 | W34: 0 | X34: 0 | Y34: 0 | Z34: 0 | AA34: 0 | AB34: 0 | AC34: 1 | AD34: 0 | AE34: 1 | AF34: 0 | AG34: 0 | AH34: 0 | AI34: -
A35: 111 | B35: Brandon Carlo | C35: TOR | D35: D | E35: 1 | F35: 15.85 | G35: 0 | H35: 0 | I35: 0 | J35: 0 | K35: 0 | L35: 0 | M35: 0 | N35: - | O35: 0 | P35: 1 | Q35: 0 | R35: 1 | S35: 0 | T35: 0 | U35: 0 | V35: 0 | W35: 0 | X35: 0 | Y35: 0 | Z35: 0 | AA35: 0 | AB35: 0 | AC35: 0 | AD35: 2 | AE35: 2 | AF35: 0 | AG35: 0 | AH35: 0 | AI35: -
A36: 143 | B36: Brandon Duhaime | C36: WSH | D36: R | E36: 1 | F36: 9.2333333 | G36: 0 | H36: 0 | I36: 0 | J36: 0 | K36: 0 | L36: 0 | M36: 0 | N36: - | O36: 0 | P36: 0 | Q36: 0 | R36: 0 | S36: 0 | T36: 0 | U36: 0 | V36: 0 | W36: 0 | X36: 0 | Y36: 0 | Z36: 0 | AA36: 0 | AB36: 0 | AC36: 0 | AD36: 2 | AE36: 1 | AF36: 2 | AG36: 0 | AH36: 1 | AI36: 0
A37: 144 | B37: Brandon Hagel | C37: T.B | D37: L | E37: 1 | F37: 23.75 | G37: 0 | H37: 1 | I37: 1 | J37: 0 | K37: 1 | L37: 100 | M37: 2 | N37: 0 | O37: 0.45 | P37: 5 | Q37: 5 | R37: 4 | S37: 3 | T37: 0 | U37: 0 | V37: 0 | W37: 0 | X37: 0 | Y37: 0 | Z37: 0 | AA37: 0 | AB37: 0 | AC37: 1 | AD37: 1 | AE37: 1 | AF37: 0 | AG37: 0 | AH37: 0 | AI37: -
A38: 94 | B38: Brandon Montour | C38: SEA | D38: D | E38: 1 | F38: 27.9 | G38: 0 | H38: 0 | I38: 0 | J38: 0 | K38: 0 | L38: - | M38: 2 | N38: 0 | O38: 0.03 | P38: 3 | Q38: 2 | R38: 0 | S38: 0 | T38: 0 | U38: 1 | V38: 2 | W38: 1 | X38: 1 | Y38: 0 | Z38: 0 | AA38: 0 | AB38: 2 | AC38: 0 | AD38: 0 | AE38: 2 | AF38: 2 | AG38: 0 | AH38: 0 | AI38: -
A39: 186 | B39: Brayden Pachal | C39: CGY | D39: D | E39: 1 | F39: 11.7 | G39: 0 | H39: 0 | I39: 0 | J39: 0 | K39: 0 | L39: - | M39: 0 | N39: - | O39: 0 | P39: 4 | Q39: 0 | R39: 1 | S39: 0 | T39: 0 | U39: 0 | V39: 0 | W39: 0 | X39: 0 | Y39: 0 | Z39: 0 | AA39: 0 | AB39: 1 | AC39: 0 | AD39: 3 | AE39: 1 | AF39: 0 | AG39: 0 | AH39: 0 | AI39: -
A40: 15 | B40: Brayden Schenn | C40: STL | D40: C | E40: 1 | F40: 16.383333 | G40: 0 | H40: 0 | I40: 0 | J40: 0 | K40: 0 | L40: - | M40: 3 | N40: 0 | O40: 0.56 | P40: 4 | Q40: 3 | R40: 3 | S40: 3 | T40: 0 | U40: 0 | V40: 0 | W40: 0 | X40: 0 | Y40: 0 | Z40: 0 | AA40: 0 | AB40: 0 | AC40: 1 | AD40: 0 | AE40: 0 | AF40: 1 | AG40: 9 | AH40: 7 | AI40: 56.25
...

Sheet FC
A1: Player | B1: Inj | C1: Likes | D1: Pos | E1: Salary | F1: Team | G1: Opp | H1: Time | I1: Fav. | J1: Win % | K1: Spread | L1: Total | M1: TeamGoal | N1: OppGoal | O1: Start/Line | P1: PP Unit | Q1: avg TOI | R1: Avg | S1: STDV | T1: Ceiling | U1: FC Proj | V1: My Proj | W1: Exp. | X1: Used | Y1: Con. | Z1: Value | AA1: Own% | AB1: TOI | AC1: Score | AD1: Val
A2: Aatu Raty | C2: 0 | D2: C | E2: 2500 | F2: VAN | G2: vs NJ | H2: 21:59:59.9999999999968050 | I2: N | J2: 0.528 | K2: 89.5 | L2: 6 | M2: 2.77 | N2: 3 | Q2: 12:07:59.99999999999829150 | R2: 3.8 | S2: 5.17 | T2: 0 | U2: 0 | V2: 0 | W2: 100 | Y2: 32 | Z2: 0 | AA2: 0
A3: Adam Edstrom | C3: 0 | D3: C | E3: 2500 | F3: NYR | G3: @ SJ | H3: 21:59:59.9999999999968050 | I3: N | J3: 0.554 | K3: 80.5 | L3: 6.5 | M3: 3.25 | N3: 3.38 | Q3: 09:41:00.00000000000085425 | R3: 3.6 | S3: 3.99 | T3: 0 | U3: 0 | V3: 0 | W3: 100 | Y3: 45 | Z3: 0 | AA3: 0
A4: Adam Erne | C4: 0 | D4: W | E4: 2500 | F4: DAL | G4: vs STL | H4: 20:00:00.0000000000031950 | I4: Y | J4: 0.486 | K4: -94.5 | L4: 5.5 | M4: 3.07 | N4: 2.75 | Q4: 09:25:59.99999999999925675 | R4: 3.8 | S4: 4.24 | T4: 0 | U4: 0 | V4: 0 | W4: 100 | Y4: 44 | Z4: 0 | AA4: 0
A5: Adam Fox | C5: 0 | D5: D | E5: 6500 | F5: NYR | G5: @ SJ | H5: 21:59:59.9999999999968050 | I5: N | J5: 0.554 | K5: 80.5 | L5: 6.5 | M5: 3.25 | N5: 3.38 | Q5: 23:26:59.999999999997441975 | R5: 11 | S5: 6.33 | T5: 0 | U5: 0 | V5: 0 | W5: 100 | Y5: 71 | Z5: 0 | AA5: 0
A6: Adam Gaudette | C6: 0 | D6: W | E6: 2800 | F6: SJ | G6: vs NYR | H6: 21:59:59.9999999999968050 | I6: Y | J6: 0.446 | K6: -80.5 | L6: 6.5 | M6: 3.38 | N6: 3.25 | O6: 3 | Q6: 12:00:00.000 | R6: 6.1 | S6: 5.98 | T6: 19.78 | U6: 7.82 | V6: 7.82 | W6: 100 | Y6: 51 | Z6: 2.8 | AA6: 0 | AB6: 12:17:59.99999999999616600 | AC6: 4.3 | AD6: 1.5
A7: Adam Ginning | C7: 0 | D7: D | E7: 2500 | F7: PHI | G7: @ COL | H7: 21:00:00.000 | I7: N | J7: 0.377 | K7: 165 | L7: 6.5 | M7: 3.25 | N7: 4.18 | Q7: 15:23:00.000000000004689600 | R7: 2.6 | S7: 1.67 | T7: 0 | U7: 0 | V7: 0 | W7: 100 | Y7: 68 | Z7: 0 | AA7: 0
A8: Adam Klapka | C8: 0 | D8: W | E8: 2500 | F8: CGY | G8: vs WSH | H8: 21:00:00.000 | I8: N | J8: 0.541 | K8: 85 | L8: 6 | M8: 2.8 | N8: 3 | O8: 4 | Q8: 10:35:59.99999999999872200 | R8: 3.9 | S8: 4.22 | T8: 12.36 | U8: 3.92 | V8: 3.92 | W8: 100 | Y8: 46 | Z8: 1.6 | AA8: 0 | AB8: 09:25:59.99999999999925675 | AC8: 4.3 | AD8: 1.7
A9: Adam Larsson | C9: 0 | D9: D | E9: 3500 | F9: SEA | G9: vs ANA | H9: 21:59:59.9999999999968050 | I9: Y | J9: 0.471 | K9: -89 | L9: 6 | M9: 3.14 | N9: 3 | O9: 1 | Q9: 21:50:59.99999999999872200 | R9: 7.1 | S9: 4.97 | T9: 18.56 | U9: 8.62 | V9: 8.62 | W9: 100 | Y9: 65 | Z9: 2.5 | AA9: 0 | AB9: 17:33:59.99999999999595075 | AC9: 1.3 | AD9: 0.4
A10: Adin Hill | C10: 0 | D10: G | E10: 7900 | F10: VGK | G10: @ TOR | H10: 18:59:59.9999999999968050 | I10: Y | J10: 0.417 | K10: -71.5 | L10: 6.5 | M10: 3.25 | N10: 3.2 | O10: confirm | Q10: PT49H47M0.000S | R10: 5.4 | S10: 6.71 | T10: 21.59 | U10: 8.17 | V10: 8.17 | W10: 100 | Y10: 38 | Z10: 1 | AA10: 0 | AB10: PT60H0M0.000S | AC10: 8.1 | AD10: 1
A11: Akira Schmid | C11: 0 | D11: G | E11: 7900 | F11: VGK | G11: @ TOR | H11: 18:59:59.9999999999968050 | I11: Y | J11: 0.417 | K11: -71.5 | L11: 6.5 | M11: 3.25 | N11: 3.2 | O11: unlikely | Q11: PT57H53M0.000S | R11: 10.8 | S11: 8.34 | T11: 0 | U11: 0 | V11: 0 | W11: 100 | Y11: 61 | Z11: 0 | AA11: 0 | AB11: 1899-12-30 | AC11: 0
A12: Aleksanteri Kaskimaki | C12: 0 | D12: C | E12: 2500 | F12: STL | G12: @ DAL | H12: 20:00:00.0000000000031950 | I12: N | J12: 0.514 | K12: 94.5 | L12: 5.5 | M12: 2.75 | N12: 3.07 | Q12: 11:17:59.99999999999936100 | R12: 3.8 | S12: 3.48 | T12: 0 | U12: 0 | V12: 0 | W12: 100 | Y12: 54 | Z12: 0 | AA12: 0
A13: Alex Killorn | C13: 0 | D13: W | E13: 3300 | F13: ANA | G13: @ SEA | H13: 21:59:59.9999999999968050 | I13: N | J13: 0.529 | K13: 89 | L13: 6 | M13: 3 | N13: 3.14 | O13: 1 | P13: 2 | Q13: 15:51:59.99999999999850675 | R13: 5.2 | S13: 4.7 | T13: 15.25 | U13: 5.85 | V13: 5.85 | W13: 100 | Y13: 55 | Z13: 1.8 | AA13: 0 | AB13: 15:16:59.99999999999637450 | AC13: 2.8 | AD13: 0.8
A14: Alex Nedeljkovic | C14: 0 | D14: G | E14: 8000 | F14: SJ | G14: vs NYR | H14: 21:59:59.9999999999968050 | I14: Y | J14: 0.446 | K14: -80.5 | L14: 6.5 | M14: 3.38 | N14: 3.25 | O14: confirm | Q14: PT57H13M0.000S | R14: 10.5 | S14: 9.77 | T14: 31.01 | U14: 11.47 | V14: 11.47 | W14: 100 | Y14: 53 | Z14: 1.4 | AA14: 0 | AB14: PT60H0M0.000S | AC14: 22.1 | AD14: 2.8
A15: Alex Ovechkin | C15: 0 | D15: W | E15: 7500 | F15: WSH | G15: @ CGY | H15: 21:00:00.000 | I15: Y | J15: 0.459 | K15: -85 | L15: 6 | M15: 3 | N15: 2.8 | O15: 3 | P15: 2 | Q15: 18:00:00.000 | R15: 10 | S15: 7.42 | T15: 26.25 | U15: 11.41 | V15: 11.41 | W15: 100 | Y15: 63 | Z15: 1.5 | AA15: 0 | AB15: 17:49:00.000000000002344800 | AC15: 20.5 | AD15: 2.7
A16: Alex Petrovic | C16: 0 | D16: D | E16: 2500 | F16: DAL | G16: vs STL | H16: 20:00:00.0000000000031950 | I16: Y | J16: 0.486 | K16: -94.5 | L16: 5.5 | M16: 3.07 | N16: 2.75 | Q16: 15:48:59.99999999999914575 | R16: 5.2 | S16: 4.6 | T16: 0 | U16: 0 | V16: 0 | W16: 100 | Y16: 56 | Z16: 0 | AA16: 0
A17: Alex Pietrangelo | B17: ! | C17: 0 | D17: D | E17: 2700 | F17: VGK | G17: @ TOR | H17: 18:59:59.9999999999968050 | I17: Y | J17: 0.417 | K17: -71.5 | L17: 6.5 | M17: 3.25 | N17: 3.2 | T17: 0 | U17: 0 | V17: 0 | W17: 100 | Y17: 0 | Z17: 0 | AA17: 0
A18: Alex Vlasic | C18: 0 | D18: D | E18: 2900 | F18: CHI | G18: vs TB | H18: 18:59:59.9999999999968050 | I18: N | J18: 0.386 | K18: 159 | L18: 6 | M18: 2.24 | N18: 3 | O18: 1 | Q18: 20:55:00.00000000000106275 | R18: 5.3 | S18: 4.25 | T18: 12.93 | U18: 4.43 | V18: 4.43 | W18: 100 | Y18: 60 | Z18: 1.5 | AA18: 0 | AB18: 23:42:00.00000000000383400 | AC18: 9.9 | AD18: 3.4
A19: Alex Wennberg | C19: 0 | D19: C | E19: 4000 | F19: SJ | G19: vs NYR | H19: 21:59:59.9999999999968050 | I19: Y | J19: 0.446 | K19: -80.5 | L19: 6.5 | M19: 3.38 | N19: 3.25 | O19: 2 | P19: 1 | Q19: 20:36:59.99999999999531175 | R19: 8.1 | S19: 7.1 | T19: 25.18 | U19: 10.98 | V19: 10.98 | W19: 100 | Y19: 56 | Z19: 2.7 | AA19: 0 | AB19: PT24H28M0.000S | AC19: 8.2 | AD19: 2.1
A20: Alexander Holtz | C20: 0 | D20: W | E20: 2500 | F20: VGK | G20: @ TOR | H20: 18:59:59.9999999999968050 | I20: Y | J20: 0.417 | K20: -71.5 | L20: 6.5 | M20: 3.25 | N20: 3.2 | O20: 4 | Q20: 11:55:00.00000000000106275 | R20: 4.4 | S20: 5.27 | T20: 15.72 | U20: 5.18 | V20: 5.18 | W20: 100 | Y20: 40 | Z20: 2.1 | AA20: 0 | AB20: 09:45:00.000 | AC20: 6.5 | AD20: 2.6
A21: Alexei Kolosov | C21: 0 | D21: G | E21: 7100 | F21: PHI | G21: @ COL | H21: 21:00:00.000 | I21: N | J21: 0.377 | K21: 165 | L21: 6.5 | M21: 3.25 | N21: 4.18 | O21: unlikely | Q21: PT30H0M0.000S | R21: 0.8 | S21: 7.56 | T21: 0 | U21: 0 | V21: 0 | W21: 100 | Y21: 0 | Z21: 0 | AA21: 0 | AB21: 1899-12-30 | AC21: 0
A22: Alexey Toropchenko | C22: 0 | D22: W | E22: 2500 | F22: STL | G22: @ DAL | H22: 20:00:00.0000000000031950 | I22: N | J22: 0.514 | K22: 94.5 | L22: 5.5 | M22: 2.75 | N22: 3.07 | O22: 4 | Q22: 12:17:59.99999999999616600 | R22: 4.4 | S22: 4.06 | T22: 12.89 | U22: 4.77 | V22: 4.77 | W22: 100 | Y22: 54 | Z22: 1.9 | AA22: 0 | AB22: 11:55:00.00000000000106275 | AC22: 1.3 | AD22: 0.5
A23: Alexis Lafreniere | C23: 0 | D23: W | E23: 4000 | F23: NYR | G23: @ SJ | H23: 21:59:59.9999999999968050 | I23: N | J23: 0.554 | K23: 80.5 | L23: 6.5 | M23: 3.25 | N23: 3.38 | O23: 1 | P23: 2 | Q23: 17:11:00.00000000000085425 | R23: 7.3 | S23: 6.45 | T23: 21.47 | U23: 8.57 | V23: 8.57 | W23: 100 | Y23: 56 | Z23: 2.1 | AA23: 0 | AB23: 14:19:59.99999999999893725 | AC23: 1.5 | AD23: 0.4
A24: Aliaksei Protas | C24: 0 | D24: W | E24: 5100 | F24: WSH | G24: @ CGY | H24: 21:00:00.000 | I24: Y | J24: 0.459 | K24: -85 | L24: 6 | M24: 3 | N24: 2.8 | O24: 2 | Q24: 18:18:59.99999999999595075 | R24: 8.8 | S24: 7.26 | T24: 24.86 | U24: 10.34 | V24: 10.34 | W24: 100 | Y24: 59 | Z24: 2 | AA24: 0 | AB24: 19:12:00.00000000000383400 | AC24: 15.6 | AD24: 3.1
A25: Andre Burakovsky | C25: 0 | D25: W | E25: 3500 | F25: CHI | G25: vs TB | H25: 18:59:59.9999999999968050 | I25: N | J25: 0.386 | K25: 159 | L25: 6 | M25: 2.24 | N25: 3 | O25: 2 | P25: 1 | Q25: 17:29:59.9999999999968050 | R25: 7.1 | S25: 6.41 | T25: 18.36 | U25: 5.54 | V25: 5.54 | W25: 100 | Y25: 55 | Z25: 1.6 | AA25: 0 | AB25: 21:26:00.00000000000404925 | AC25: 5.8 | AD25: 1.7
A26: Andrei Vasilevskiy | C26: 0 | D26: G | E26: 8400 | F26: TB | G26: @ CHI | H26: 18:59:59.9999999999968050 | I26: Y | J26: 0.614 | K26: -159 | L26: 6 | M26: 3 | N26: 2.24 | O26: confirm | Q26: PT58H56M0.000S | R26: 12.5 | S26: 8.48 | T26: 28.91 | U26: 11.95 | V26: 11.95 | W26: 100 | Y26: 66 | Z26: 1.4 | AA26: 0 | AB26: PT65H0M0.000S | AC26: 14.4 | AD26: 1.7
A27: Angus Crookshank | C27: 0 | D27: W | E27: 2500 | F27: NJ | G27: @ VAN | H27: 21:59:59.9999999999968050 | I27: Y | J27: 0.472 | K27: -89.5 | L27: 6 | M27: 3 | N27: 2.77 | Q27: 08:35:00.00000000000053475 | R27: 3 | S27: 3.94 | T27: 0 | U27: 0 | V27: 0 | W27: 100 | Y27: 34 | Z27: 0 | AA27: 0
A28: Anthony Beauvillier | C28: 0 | D28: W | E28: 3600 | F28: WSH | G28: @ CGY | H28: 21:00:00.000 | I28: Y | J28: 0.459 | K28: -85 | L28: 6 | M28: 3 | N28: 2.8 | O28: 4 | Q28: 15:47:59.99999999999936100 | R28: 6 | S28: 4.54 | T28: 16.24 | U28: 7.16 | V28: 7.16 | W28: 100 | Y28: 62 | Z28: 2 | AA28: 0 | AB28: 13:47:59.99999999999616600 | AC28: 3 | AD28: 0.8
A29: Anthony Cirelli | C29: 0 | D29: C | E29: 5400 | F29: TB | G29: @ CHI | H29: 18:59:59.9999999999968050 | I29: Y | J29: 0.614 | K29: -159 | L29: 6 | M29: 3 | N29: 2.24 | O29: 1 | P29: 2 | Q29: 17:32:59.99999999999616600 | R29: 8.2 | S29: 6.45 | T29: 21.42 | U29: 8.52 | V29: 8.52 | W29: 100 | Y29: 61 | Z29: 1.6 | AA29: 0 | AB29: 19:21:00.00000000000191700 | AC29: 9.3 | AD29: 1.7
A30: Anthony Stolarz | C30: 0 | D30: G | E30: 7300 | F30: TOR | G30: vs VGK | H30: 18:59:59.9999999999968050 | I30: N | J30: 0.583 | K30: 71.5 | L30: 6.5 | M30: 3.2 | N30: 3.25 | O30: confirm | Q30: PT54H3M0.000S | R30: 9.2 | S30: 9.36 | T30: 30.56 | U30: 11.84 | V30: 11.84 | W30: 100 | Y30: 49 | Z30: 1.6 | AA30: 0 | AB30: PT58H20M0.000S | AC30: 0
A31: Anton Blidh | C31: 0 | D31: W | E31: 2500 | F31: NYR | G31: @ SJ | H31: 21:59:59.9999999999968050 | I31: N | J31: 0.554 | K31: 80.5 | L31: 6.5 | M31: 3.25 | N31: 3.38 | O31: 4 | Q31: 07:47:00.00000000000117375 | R31: 0.8 | S31: 0.75 | T31: 5.98 | U31: 4.48 | V31: 4.48 | W31: 100 | Y31: 0 | Z31: 1.8 | AA31: 0 | AB31: 06:14:00.00000000000181275 | AC31: 9.5 | AD31: 3.8
A32: Arseny Gritsyuk | C32: 0 | D32: W | E32: 3300 | F32: NJ | G32: @ VAN | H32: 21:59:59.9999999999968050 | I32: Y | J32: 0.472 | K32: -89.5 | L32: 6 | M32: 3 | N32: 2.77 | O32: 3 | Q32: 14:57:00.00000000000063900 | R32: 6.8 | S32: 6.14 | T32: 20.09 | U32: 7.81 | V32: 7.81 | W32: 100 | Y32: 55 | Z32: 2.4 | AA32: 0 | AB32: 13:14:00.00000000000341025 | AC32: 5 | AD32: 1.5
A33: Arshdeep Bains | C33: 0 | D33: W | E33: 2500 | F33: VAN | G33: vs NJ | H33: 21:59:59.9999999999968050 | I33: N | J33: 0.528 | K33: 89.5 | L33: 6 | M33: 2.77 | N33: 3 | Q33: 09:23:59.99999999999968050 | R33: 2.4 | S33: 3.25 | T33: 0 | U33: 0 | V33: 0 | W33: 100 | Y33: 32 | Z33: 0 | AA33: 0
A34: Artemi Panarin | C34: 0 | D34: W | E34: 8300 | F34: NYR | G34: @ SJ | H34: 21:59:59.9999999999968050 | I34: N | J34: 0.554 | K34: 80.5 | L34: 6.5 | M34: 3.25 | N34: 3.38 | O34: 1 | P34: 1 | Q34: 20:47:00.00000000000277125 | R34: 12.9 | S34: 9.68 | T34: 36.47 | U34: 17.11 | V34: 17.11 | W34: 100 | Y34: 62 | Z34: 2.1 | AA34: 0 | AB34: 21:09:59.99999999999786775 | AC34: 4.5 | AD34: 0.5
A35: Artturi Lehkonen | C35: 0 | D35: W | E35: 5700 | F35: COL | G35: vs PHI | H35: 21:00:00.000 | I35: Y | J35: 0.623 | K35: -165 | L35: 6.5 | M35: 4.18 | N35: 3.25 | O35: 2 | P35: 2 | Q35: 19:23:00.00000000000149325 | R35: 9.3 | S35: 6.26 | T35: 24.87 | U35: 12.35 | V35: 12.35 | W35: 100 | Y35: 66 | Z35: 2.2 | AA35: 0 | AB35: 15:16:59.99999999999637450 | AC35: 0
A36: Artyom Levshunov | C36: 0 | D36: D | E36: 3800 | F36: CHI | G36: vs TB | H36: 18:59:59.9999999999968050 | I36: N | J36: 0.386 | K36: 159 | L36: 6 | M36: 2.24 | N36: 3 | O36: 2 | P36: 1 | Q36: 19:00:59.99999999999658975 | R36: 5.7 | S36: 4.39 | T36: 13.66 | U36: 4.88 | V36: 4.88 | W36: 100 | Y36: 61 | Z36: 1.3 | AA36: 0 | AB36: 21:58:59.99999999999701350 | AC36: 0
A37: Arvid Soderblom | C37: 0 | D37: G | E37: 7000 | F37: CHI | G37: vs TB | H37: 18:59:59.9999999999968050 | I37: N | J37: 0.386 | K37: 159 | L37: 6 | M37: 2.24 | N37: 3 | O37: confirm | Q37: PT57H38M0.000S | R37: 6.5 | S37: 10.7 | T37: 28.75 | U37: 7.35 | V37: 7.35 | W37: 100 | Y37: 18 | Z37: 1.1 | AA37: 0 | AB37: PT65H0M0.000S | AC37: 19.5 | AD37: 2.8
A38: Auston Matthews | C38: 0 | D38: C | E38: 9700 | F38: TOR | G38: vs VGK | H38: 18:59:59.9999999999968050 | I38: N | J38: 0.583 | K38: 71.5 | L38: 6.5 | M38: 3.2 | N38: 3.25 | O38: 1 | P38: 1 | Q38: 20:47:00.00000000000277125 | R38: 15.9 | S38: 9.99 | T38: 38.96 | U38: 18.98 | V38: 18.98 | W38: 100 | Y38: 69 | Z38: 2 | AA38: 0 | AB38: 23:29:59.9999999999968050 | AC38: 4.5 | AD38: 0.5
A39: Barclay Goodrow | C39: 0 | D39: W | E39: 2500 | F39: SJ | G39: vs NYR | H39: 21:59:59.9999999999968050 | I39: Y | J39: 0.446 | K39: -80.5 | L39: 6.5 | M39: 3.38 | N39: 3.25 | O39: 4 | Q39: 11:37:00.00000000000010425 | R39: 3.8 | S39: 5.28 | T39: 16.37 | U39: 5.81 | V39: 5.81 | W39: 100 | Y39: 31 | Z39: 2.3 | AA39: 0 | AB39: 07:30:59.999999999999786775 | AC39: 2.6 | AD39: 1
A40: Beckett Sennecke | C40: 0 | D40: W | E40: 5200 | F40: ANA | G40: @ SEA | H40: 21:59:59.9999999999968050 | I40: N | J40: 0.529 | K40: 89 | L40: 6 | M40: 3 | N40: 3.14 | O40: 1 | P40: 1 | Q40: 17:02:00.00000000000277125 | R40: 8.9 | S40: 7.23 | T40: 25.3 | U40: 10.84 | V40: 10.84 | W40: 100 | Y40: 59 | Z40: 2.1 | AA40: 0 | AB40: 13:54:00.00000000000447975 | AC40: 1.5 | AD40: 0.3
...
