Workbook

Sheet Actual
A1: Player | B1: Roster Position | C1: %Drafted | D1: FPTS
A2: Connor McDavid | B2: C | C2: 0.4586 | D2: 18
A3: Ilya Sorokin | B3: G | C3: 0.3759 | D3: 24.7
A4: Viktor Arvidsson | B4: W | C4: 0.3114 | D4: 0
A5: Leon Draisaitl | B5: C | C5: 0.2763 | D5: 24.5
A6: Evan Bouchard | B6: D | C6: 0.2693 | D6: 9.1
A7: Pavel Zacha | B7: C | C7: 0.2637 | D7: 3
A8: Zach Hyman | B8: W | C8: 0.2553 | D8: 20.6
A9: Morgan Geekie | B9: W | C9: 0.2328 | D9: 15.8
A10: Charlie McAvoy | B10: D | C10: 0.202 | D10: 8
A11: Elias Lindholm | B11: C | C11: 0.1964 | D11: 25.6
A12: Mattias Ekholm | B12: D | C12: 0.1809 | D12: 40.1
A13: David Pastrnak | B13: W | C13: 0.1795 | D13: 22.3
... A159: Kevin Stenlund | B159: C | C159: 0.0014 | D159: 0

Sheet Projected
A1: name | B1: team | C1: position | D1: salary | E1: projected_fpts | F1: dk_avg_fpts | G1: edge | H1: value | I1: floor | J1: ceiling | K1: player_type | L1: actual | M1: ownership | N1: TOI
A2: Ryan Strome | B2: ANA | C2: C | D2: 2600 | E2: 5.1173032 | F2: 3.67 | G2: 1.4473032 | H2: 1.9681935 | I2: 1.2793258 | J2: 17.793258 | K2: skater | L2: =IFERROR(VLOOKUP($A2,Actual!$A:$D,4,FALSE),IFERROR(VLOOKUP($A2,fc!$A:$AC,29,FALSE),"Not Found")) -> 1.3 | M2: =IFERROR(VLOOKUP($A2,Actual!$A:$D,3,FALSE),"0") -> 0.0168 | N2: =IFERROR(VLOOKUP($A2,NHT!$B:$F,5,FALSE),IFERROR(VLOOKUP(A2,fc!A:AD,28,FALSE),"Not Found")) -> 4.7
A3: Jack Finley | B3: TBL | C3: C | D3: 2500 | E3: 3.4240006 | F3: 2.2 | G3: 1.2240006 | H3: 1.3696002 | I3: 0.85600014 | J3: 13.560001 | K3: skater | L3: =IFERROR(VLOOKUP($A3,Actual!$A:$D,4,FALSE),IFERROR(VLOOKUP($A3,fc!$A:$AC,29,FALSE),"Not Found")) -> 2.6 | M3: =IFERROR(VLOOKUP($A3,Actual!$A:$D,3,FALSE),"0") -> 0 | N3: =IFERROR(VLOOKUP($A3,NHT!$B:$F,5,FALSE),IFERROR(VLOOKUP(A3,fc!A:AD,28,FALSE),"Not Found")) -> 7.1833333
A4: Brandon Tanev | B4: UTA | C4: W | D4: 2500 | E4: 2.2118496 | F4: 2.35 | G4: -0.13815037 | H4: 0.88473985 | I4: 0.55296241 | J4: 10.529624 | K4: skater | L4: =IFERROR(VLOOKUP($A4,Actual!$A:$D,4,FALSE),IFERROR(VLOOKUP($A4,fc!$A:$AC,29,FALSE),"Not Found")) -> 0 | M4: =IFERROR(VLOOKUP($A4,Actual!$A:$D,3,FALSE),"0") -> 0 | N4: =IFERROR(VLOOKUP($A4,NHT!$B:$F,5,FALSE),IFERROR(VLOOKUP(A4,fc!A:AD,28,FALSE),"Not Found")) -> 7.65
A5: Trent Frederic | B5: EDM | C5: C | D5: 2500 | E5: 2.8479338 | F5: 2.2 | G5: 0.64793384 | H5: 1.1391735 | I5: 0.71198346 | J5: 12.119835 | K5: skater | L5: =IFERROR(VLOOKUP($A5,Actual!$A:$D,4,FALSE),IFERROR(VLOOKUP($A5,fc!$A:$AC,29,FALSE),"Not Found")) -> 4.5 | M5: =IFERROR(VLOOKUP($A5,Actual!$A:$D,3,FALSE),"0") -> 0.0014 | N5: =IFERROR(VLOOKUP($A5,NHT!$B:$F,5,FALSE),IFERROR(VLOOKUP(A5,fc!A:AD,28,FALSE),"Not Found")) -> 7.9833333
A6: Nick Paul | B6: TBL | C6: W | D6: 2900 | E6: 6.3275909 | F6: 4.96 | G6: 1.3675909 | H6: 2.1819279 | I6: 1.5818977 | J6: 20.818977 | K6: skater | L6: =IFERROR(VLOOKUP($A6,Actual!$A:$D,4,FALSE),IFERROR(VLOOKUP($A6,fc!$A:$AC,29,FALSE),"Not Found")) -> 2.8 | M6: =IFERROR(VLOOKUP($A6,Actual!$A:$D,3,FALSE),"0") -> 0.0182 | N6: =IFERROR(VLOOKUP($A6,NHT!$B:$F,5,FALSE),IFERROR(VLOOKUP(A6,fc!A:AD,28,FALSE),"Not Found")) -> 8.6833333
A7: Matt Rempe | B7: NYR | C7: C | D7: 2500 | E7: 2.602115 | F7: 1.64 | G7: 0.96211502 | H7: 1.040846 | I7: 0.65052875 | J7: 11.505288 | K7: skater | L7: =IFERROR(VLOOKUP($A7,Actual!$A:$D,4,FALSE),IFERROR(VLOOKUP($A7,fc!$A:$AC,29,FALSE),"Not Found")) -> 3 | M7: =IFERROR(VLOOKUP($A7,Actual!$A:$D,3,FALSE),"0") -> 0 | N7: =IFERROR(VLOOKUP($A7,NHT!$B:$F,5,FALSE),IFERROR(VLOOKUP(A7,fc!A:AD,28,FALSE),"Not Found")) -> 8.7166667
A8: Sam Carrick | B8: NYR | C8: C | D8: 2500 | E8: 4.2352707 | F8: 3.4 | G8: 0.8352707 | H8: 1.6941083 | I8: 1.0588177 | J8: 15.588177 | K8: skater | L8: =IFERROR(VLOOKUP($A8,Actual!$A:$D,4,FALSE),IFERROR(VLOOKUP($A8,fc!$A:$AC,29,FALSE),"Not Found")) -> 0 | M8: =IFERROR(VLOOKUP($A8,Actual!$A:$D,3,FALSE),"0") -> 0 | N8: =IFERROR(VLOOKUP($A8,NHT!$B:$F,5,FALSE),IFERROR(VLOOKUP(A8,fc!A:AD,28,FALSE),"Not Found")) -> 8.8666667
A9: Taylor Raddysh | B9: NYR | C9: W | D9: 2500 | E9: 4.79344 | F9: 3.87 | G9: 0.92343999 | H9: 1.917376 | I9: 1.19836 | J9: 16.9836 | K9: skater | L9: =IFERROR(VLOOKUP($A9,Actual!$A:$D,4,FALSE),IFERROR(VLOOKUP($A9,fc!$A:$AC,29,FALSE),"Not Found")) -> 0 | M9: =IFERROR(VLOOKUP($A9,Actual!$A:$D,3,FALSE),"0") -> 0 | N9: =IFERROR(VLOOKUP($A9,NHT!$B:$F,5,FALSE),IFERROR(VLOOKUP(A9,fc!A:AD,28,FALSE),"Not Found")) -> 9.5166667
A10: Ross Johnston | B10: ANA | C10: W | D10: 2500 | E10: 3.5647142 | F10: 2.52 | G10: 1.0447142 | H10: 1.4258857 | I10: 0.89117854 | J10: 13.911785 | K10: skater | L10: =IFERROR(VLOOKUP($A10,Actual!$A:$D,4,FALSE),IFERROR(VLOOKUP($A10,fc!$A:$AC,29,FALSE),"Not Found")) -> 1.3 | M10: =IFERROR(VLOOKUP($A10,Actual!$A:$D,3,FALSE),"0") -> 0 | N10: =IFERROR(VLOOKUP($A10,NHT!$B:$F,5,FALSE),IFERROR(VLOOKUP(A10,fc!A:AD,28,FALSE),"Not Found")) -> 9.65
A11: Tanner Jeannot | B11: BOS | C11: W | D11: 2500 | E11: 5.2745977 | F11: 5.28 | G11: -0.0054023085 | H11: 2.1098391 | I11: 1.3186494 | J11: 18.186494 | K11: skater | L11: =IFERROR(VLOOKUP($A11,Actual!$A:$D,4,FALSE),IFERROR(VLOOKUP($A11,fc!$A:$AC,29,FALSE),"Not Found")) -> 1.5 | M11: =IFERROR(VLOOKUP($A11,Actual!$A:$D,3,FALSE),"0") -> 0.0182 | N11: =IFERROR(VLOOKUP($A11,NHT!$B:$F,5,FALSE),IFERROR(VLOOKUP(A11,fc!A:AD,28,FALSE),"Not Found")) -> 9.8166667
A12: Brennan Othmann | B12: NYR | C12: W | D12: 2500 | E12: 3.6727104 | F12: 2.86 | G12: 0.81271043 | H12: 1.4690842 | I12: 0.91817761 | J12: 14.181776 | K12: skater | L12: =IFERROR(VLOOKUP($A12,Actual!$A:$D,4,FALSE),IFERROR(VLOOKUP($A12,fc!$A:$AC,29,FALSE),"Not Found")) -> 1.3 | M12: =IFERROR(VLOOKUP($A12,Actual!$A:$D,3,FALSE),"0") -> 0.0014 | N12: =IFERROR(VLOOKUP($A12,NHT!$B:$F,5,FALSE),IFERROR(VLOOKUP(A12,fc!A:AD,28,FALSE),"Not Found")) -> 9.95
A13: Maxim Tsyplakov | B13: NYI | C13: W | D13: 2500 | E13: 2.9309304 | F13: 1.74 | G13: 1.1909304 | H13: 1.1723722 | I13: 0.73273259 | J13: 12.327326 | K13: skater | L13: =IFERROR(VLOOKUP($A13,Actual!$A:$D,4,FALSE),IFERROR(VLOOKUP($A13,fc!$A:$AC,29,FALSE),"Not Found")) -> 6.5 | M13: =IFERROR(VLOOKUP($A13,Actual!$A:$D,3,FALSE),"0") -> 0.0014 | N13: =IFERROR(VLOOKUP($A13,NHT!$B:$F,5,FALSE),IFERROR(VLOOKUP(A13,fc!A:AD,28,FALSE),"Not Found")) -> 10.066667
... A143: Jonathan Quick | B143: NYR | C143: G | D143: 7600 | E143: 9.6388019 | F143: 7.32 | G143: 2.3188019 | H143: 1.2682634 | I143: 1.9277604 | J143: 29.277604 | K143: goalie | L143: =IFERROR(VLOOKUP($A143,Actual!$A:$D,4,FALSE),IFERROR(VLOOKUP($A143,fc!$A:$AC,29,FALSE),"Not Found")) -> 15.2 | M143: =IFERROR(VLOOKUP($A143,Actual!$A:$D,3,FALSE),"0") -> 0.0238 | N143: =IFERROR(VLOOKUP($A143,NHT!$B:$F,5,FALSE),IFERROR(VLOOKUP(A143,fc!A:AD,28,FALSE),"Not Found")) -> 63.816667

Sheet NHT
B1: Player | C1: Team | D1: Position | E1: GP | F1: TOI | G1: Goals | H1: Total Assists | I1: First Assists | J1: Second Assists | K1: Total Points | L1: IPP | M1: Shots | N1: SH% | O1: ixG | P1: iCF | Q1: iFF | R1: iSCF | S1: iHDCF | T1: Rush Attempts | U1: Rebounds Created | V1: PIM | W1: Total Penalties | X1: Minor | Y1: Major | Z1: Misconduct | AA1: Penalties Drawn | AB1: Giveaways | AC1: Takeaways | AD1: Hits | AE1: Hits Taken | AF1: Shots Blocked | AG1: Faceoffs Won | AH1: Faceoffs Lost | AI1: Faceoffs %
A2: 92 | B2: Adam Boqvist | C2: NYI | D2: D | E2: 1 | F2: 14.283333 | G2: 0 | H2: 0 | I2: 0 | J2: 0 | K2: 0 | L2: - | M2: 0 | N2: - | O2: 0 | P2: 0 | Q2: 0 | R2: 0 | S2: 0 | T2: 0 | U2: 0 | V2: 2 | W2: 1 | X2: 1 | Y2: 0 | Z2: 0 | AA2: 0 | AB2: 0 | AC2: 0 | AD2: 1 | AE2: 2 | AF2: 1 | AG2: 0 | AH2: 0 | AI2: -
A3: 26 | B3: Adam Pelech | C3: NYI | D3: D | E3: 1 | F3: 24.15 | G3: 0 | H3: 1 | I3: 0 | J3: 1 | K3: 1 | L3: 50 | M3: 0 | N3: - | O3: 0.01 | P3: 1 | Q3: 1 | R3: 0 | S3: 0 | T3: 0 | U3: 0 | V3: 0 | W3: 0 | X3: 0 | Y3: 0 | Z3: 0 | AA3: 0 | AB3: 1 | AC3: 1 | AD3: 0 | AE3: 1 | AF3: 1 | AG3: 0 | AH3: 0 | AI3: -
A4: 1 | B4: Alex Killorn | C4: ANA | D4: L | E4: 1 | F4: 19.3 | G4: 1 | H4: 0 | I4: 0 | J4: 0 | K4: 1 | L4: 50 | M4: 1 | N4: 100 | O4: 0.14 | P4: 2 | Q4: 1 | R4: 2 | S4: 1 | T4: 0 | U4: 1 | V4: 0 | W4: 0 | X4: 0 | Y4: 0 | Z4: 0 | AA4: 0 | AB4: 2 | AC4: 0 | AD4: 0 | AE4: 0 | AF4: 0 | AG4: 1 | AH4: 1 | AI4: 50
A5: 119 | B5: Alex Steeves | C5: BOS | D5: C | E5: 1 | F5: 11.416667 | G5: 0 | H5: 0 | I5: 0 | J5: 0 | K5: 0 | L5: - | M5: 1 | N5: 0 | O5: 0.11 | P5: 2 | Q5: 1 | R5: 1 | S5: 1 | T5: 0 | U5: 0 | V5: 0 | W5: 0 | X5: 0 | Y5: 0 | Z5: 0 | AA5: 0 | AB5: 0 | AC5: 0 | AD5: 2 | AE5: 2 | AF5: 1 | AG5: 0 | AH5: 0 | AI5: -
A6: 107 | B6: Alexis Lafrenière | C6: NYR | D6: L | E6: 1 | F6: 19.083333 | G6: 0 | H6: 1 | I6: 0 | J6: 1 | K6: 1 | L6: 100 | M6: 0 | N6: - | O6: 0.12 | P6: 1 | Q6: 1 | R6: 1 | S6: 1 | T6: 0 | U6: 0 | V6: 0 | W6: 0 | X6: 0 | Y6: 0 | Z6: 0 | AA6: 0 | AB6: 1 | AC6: 0 | AD6: 6 | AE6: 0 | AF6: 1 | AG6: 0 | AH6: 0 | AI6: -
A7: 6 | B7: Anders Lee | C7: NYI | D7: L | E7: 1 | F7: 13.9 | G7: 0 | H7: 1 | I7: 0 | J7: 1 | K7: 1 | L7: 50 | M7: 3 | N7: 0 | O7: 0.59 | P7: 4 | Q7: 3 | R7: 3 | S7: 3 | T7: 0 | U7: 1 | V7: 0 | W7: 0 | X7: 0 | Y7: 0 | Z7: 0 | AA7: 0 | AB7: 0 | AC7: 0 | AD7: 0 | AE7: 0 | AF7: 0 | AG7: 0 | AH7: 1 | AI7: 0
A8: 70 | B8: Andrew Peeke | C8: BOS | D8: D | E8: 1 | F8: 17.733333 | G8: 0 | H8: 0 | I8: 0 | J8: 0 | K8: 0 | L8: - | M8: 2 | N8: 0 | O8: 0.05 | P8: 4 | Q8: 3 | R8: 0 | S8: 0 | T8: 0 | U8: 0 | V8: 0 | W8: 0 | X8: 0 | Y8: 0 | Z8: 0 | AA8: 0 | AB8: 2 | AC8: 0 | AD8: 0 | AE8: 9 | AF8: 0 | AG8: 0 | AH8: 0 | AI8: -
A9: 59 | B9: Anthony Cirelli | C9: T.B | D9: C | E9: 1 | F9: 17.283333 | G9: 1 | H9: 0 | I9: 0 | J9: 0 | K9: 1 | L9: 50 | M9: 1 | N9: 100 | O9: 0.05 | P9: 1 | Q9: 1 | R9: 1 | S9: 0 | T9: 0 | U9: 0 | V9: 0 | W9: 0 | X9: 0 | Y9: 0 | Z9: 0 | AA9: 0 | AB9: 0 | AC9: 1 | AD9: 1 | AE9: 1 | AF9: 0 | AG9: 8 | AH9: 7 | AI9: 53.33
A10: 30 | B10: Anthony Duclair | C10: NYI | D10: L | E10: 1 | F10: 16.033333 | G10: 0 | H10: 2 | I10: 0 | J10: 2 | K10: 2 | L10: 100 | M10: 1 | N10: 0 | O10: 0.03 | P10: 3 | Q10: 1 | R10: 1 | S10: 0 | T10: 0 | U10: 1 | V10: 0 | W10: 0 | X10: 0 | Y10: 0 | Z10: 0 | AA10: 0 | AB10: 2 | AC10: 0 | AD10: 0 | AE10: 2 | AF10: 0 | AG10: 0 | AH10: 0 | AI10: -
A11: 60 | B11: Artemi Panarin | C11: NYR | D11: L | E11: 1 | F11: 24.25 | G11: 0 | H11: 1 | I11: 1 | J11: 0 | K11: 1 | L11: 100 | M11: 2 | N11: 0 | O11: 0.59 | P11: 7 | Q11: 6 | R11: 4 | S11: 1 | T11: 0 | U11: 0 | V11: 0 | W11: 0 | X11: 0 | Y11: 0 | Z11: 0 | AA11: 1 | AB11: 2 | AC11: 2 | AD11: 0 | AE11: 0 | AF11: 0 | AG11: 0 | AH11: 0 | AI11: -
A12: 90 | B12: Barrett Hayton | C12: UTA | D12: C | E12: 1 | F12: 15.466667 | G12: 0 | H12: 0 | I12: 0 | J12: 0 | K12: 0 | L12: - | M12: 5 | N12: 0 | O12: 1.11 | P12: 8 | Q12: 7 | R12: 5 | S12: 4 | T12: 0 | U12: 3 | V12: 0 | W12: 0 | X12: 0 | Y12: 0 | Z12: 0 | AA12: 1 | AB12: 1 | AC12: 0 | AD12: 0 | AE12: 4 | AF12: 0 | AG12: 7 | AH12: 3 | AI12: 70
A13: 140 | B13: Beckett Sennecke | C13: ANA | D13: R | E13: 1 | F13: 25.516667 | G13: 0 | H13: 2 | I13: 2 | J13: 0 | K13: 2 | L13: 66.67 | M13: 7 | N13: 0 | O13: 0.76 | P13: 11 | Q13: 10 | R13: 7 | S13: 5 | T13: 0 | U13: 0 | V13: 0 | W13: 0 | X13: 0 | Y13: 0 | Z13: 0 | AA13: 1 | AB13: 0 | AC13: 1 | AD13: 1 | AE13: 2 | AF13: 0 | AG13: 0 | AH13: 0 | AI13: -
A14: 37 | B14: Bo Horvat | C14: NYI | D14: C | E14: 1 | F14: 19.283333 | G14: 0 | H14: 0 | I14: 0 | J14: 0 | K14: 0 | L14: - | M14: 1 | N14: 0 | O14: 0.02 | P14: 3 | Q14: 1 | R14: 0 | S14: 0 | T14: 0 | U14: 0 | V14: 0 | W14: 0 | X14: 0 | Y14: 0 | Z14: 0 | AA14: 1 | AB14: 1 | AC14: 1 | AD14: 2 | AE14: 1 | AF14: 0 | AG14: 6 | AH14: 11 | AI14: 35.29
A15: 100 | B15: Bobby Brink | C15: PHI | D15: R | E15: 1 | F15: 15.016667 | G15: 0 | H15: 0 | I15: 0 | J15: 0 | K15: 0 | L15: - | M15: 0 | N15: - | O15: 0.04 | P15: 1 | Q15: 1 | R15: 0 | S15: 0 | T15: 0 | U15: 0 | V15: 0 | W15: 0 | X15: 0 | Y15: 0 | Z15: 0 | AA15: 0 | AB15: 0 | AC15: 0 | AD15: 2 | AE15: 0 | AF15: 0 | AG15: 0 | AH15: 0 | AI15: -
A16: 105 | B16: Braden Schneider | C16: NYR | D16: D | E16: 1 | F16: 21.133333 | G16: 0 | H16: 0 | I16: 0 | J16: 0 | K16: 0 | L16: - | M16: 1 | N16: 0 | O16: 0.03 | P16: 3 | Q16: 3 | R16: 0 | S16: 0 | T16: 0 | U16: 0 | V16: 0 | W16: 0 | X16: 0 | Y16: 0 | Z16: 0 | AA16: 0 | AB16: 0 | AC16: 0 | AD16: 0 | AE16: 3 | AF16: 5 | AG16: 0 | AH16: 0 | AI16: -
A17: 73 | B17: Brandon Hagel | C17: T.B | D17: L | E17: 1 | F17: 21.766667 | G17: 0 | H17: 0 | I17: 0 | J17: 0 | K17: 0 | L17: 0 | M17: 4 | N17: 0 | O17: 0.79 | P17: 12 | Q17: 7 | R17: 8 | S17: 5 | T17: 0 | U17: 4 | V17: 2 | W17: 1 | X17: 1 | Y17: 0 | Z17: 0 | AA17: 1 | AB17: 0 | AC17: 0 | AD17: 0 | AE17: 3 | AF17: 1 | AG17: 3 | AH17: 2 | AI17: 60
A18: 65 | B18: Brandon Tanev | C18: UTA | D18: L | E18: 1 | F18: 7.65 | G18: 0 | H18: 0 | I18: 0 | J18: 0 | K18: 0 | L18: - | M18: 0 | N18: - | O18: 0 | P18: 0 | Q18: 0 | R18: 0 | S18: 0 | T18: 0 | U18: 0 | V18: 0 | W18: 0 | X18: 0 | Y18: 0 | Z18: 0 | AA18: 0 | AB18: 2 | AC18: 1 | AD18: 3 | AE18: 1 | AF18: 0 | AG18: 0 | AH18: 0 | AI18: -
A19: 123 | B19: Brennan Othmann | C19: NYR | D19: L | E19: 1 | F19: 9.95 | G19: 0 | H19: 0 | I19: 0 | J19: 0 | K19: 0 | L19: 0 | M19: 0 | N19: - | O19: 0 | P19: 0 | Q19: 0 | R19: 0 | S19: 0 | T19: 0 | U19: 0 | V19: 0 | W19: 0 | X19: 0 | Y19: 0 | Z19: 0 | AA19: 0 | AB19: 0 | AC19: 0 | AD19: 6 | AE19: 1 | AF19: 1 | AG19: 0 | AH19: 0 | AI19: -
A20: 99 | B20: Cam York | C20: PHI | D20: D | E20: 1 | F20: 22.45 | G20: 0 | H20: 0 | I20: 0 | J20: 0 | K20: 0 | L20: - | M20: 4 | N20: 0 | O20: 0.3 | P20: 6 | Q20: 6 | R20: 3 | S20: 1 | T20: 0 | U20: 1 | V20: 2 | W20: 1 | X20: 1 | Y20: 0 | Z20: 0 | AA20: 0 | AB20: 1 | AC20: 0 | AD20: 0 | AE20: 1 | AF20: 3 | AG20: 0 | AH20: 0 | AI20: -
A21: 67 | B21: Carl Grundstrom | C21: PHI | D21: R | E21: 1 | F21: 10.533333 | G21: 0 | H21: 0 | I21: 0 | J21: 0 | K21: 0 | L21: - | M21: 1 | N21: 0 | O21: 0.02 | P21: 1 | Q21: 1 | R21: 0 | S21: 0 | T21: 0 | U21: 0 | V21: 0 | W21: 0 | X21: 0 | Y21: 0 | Z21: 0 | AA21: 0 | AB21: 1 | AC21: 0 | AD21: 3 | AE21: 1 | AF21: 0 | AG21: 0 | AH21: 0 | AI21: -
A22: 5 | B22: Casey Cizikas | C22: NYI | D22: C | E22: 1 | F22: 15.6 | G22: 0 | H22: 1 | I22: 1 | J22: 0 | K22: 1 | L22: 100 | M22: 2 | N22: 0 | O22: 0.04 | P22: 2 | Q22: 2 | R22: 0 | S22: 0 | T22: 0 | U22: 0 | V22: 0 | W22: 0 | X22: 0 | Y22: 0 | Z22: 0 | AA22: 0 | AB22: 1 | AC22: 0 | AD22: 0 | AE22: 1 | AF22: 1 | AG22: 10 | AH22: 5 | AI22: 66.67
A23: 79 | B23: Casey Mittelstadt | C23: BOS | D23: C | E23: 1 | F23: 13.75 | G23: 0 | H23: 0 | I23: 0 | J23: 0 | K23: 0 | L23: - | M23: 1 | N23: 0 | O23: 0.01 | P23: 1 | Q23: 1 | R23: 0 | S23: 0 | T23: 0 | U23: 0 | V23: 0 | W23: 0 | X23: 0 | Y23: 0 | Z23: 0 | AA23: 0 | AB23: 1 | AC23: 0 | AD23: 0 | AE23: 0 | AF23: 0 | AG23: 0 | AH23: 0 | AI23: -
A24: 66 | B24: Charlie McAvoy | C24: BOS | D24: D | E24: 1 | F24: 24.116667 | G24: 0 | H24: 1 | I24: 0 | J24: 1 | K24: 1 | L24: 100 | M24: 2 | N24: 0 | O24: 0.08 | P24: 2 | Q24: 2 | R24: 0 | S24: 0 | T24: 0 | U24: 0 | V24: 4 | W24: 2 | X24: 2 | Y24: 0 | Z24: 0 | AA24: 0 | AB24: 3 | AC24: 0 | AD24: 0 | AE24: 3 | AF24: 0 | AG24: 0 | AH24: 0 | AI24: -
A25: 3 | B25: Chris Kreider | C25: ANA | D25: L | E25: 1 | F25: 17.3 | G25: 0 | H25: 1 | I25: 1 | J25: 0 | K25: 1 | L25: 33.33 | M25: 4 | N25: 0 | O25: 0.53 | P25: 6 | Q25: 6 | R25: 5 | S25: 4 | T25: 0 | U25: 1 | V25: 0 | W25: 0 | X25: 0 | Y25: 0 | Z25: 0 | AA25: 0 | AB25: 2 | AC25: 1 | AD25: 0 | AE25: 0 | AF25: 0 | AG25: 0 | AH25: 0 | AI25: -
A26: 46 | B26: Christian Dvorak | C26: PHI | D26: C | E26: 1 | F26: 19 | G26: 0 | H26: 0 | I26: 0 | J26: 0 | K26: 0 | L26: - | M26: 1 | N26: 0 | O26: 0.3 | P26: 3 | Q26: 3 | R26: 3 | S26: 1 | T26: 0 | U26: 0 | V26: 0 | W26: 0 | X26: 0 | Y26: 0 | Z26: 0 | AA26: 0 | AB26: 1 | AC26: 0 | AD26: 1 | AE26: 1 | AF26: 1 | AG26: 3 | AH26: 7 | AI26: 30
A27: 68 | B27: Clayton Keller | C27: UTA | D27: R | E27: 1 | F27: 19.933333 | G27: 0 | H27: 0 | I27: 0 | J27: 0 | K27: 0 | L27: - | M27: 1 | N27: 0 | O27: 0.1 | P27: 3 | Q27: 1 | R27: 1 | S27: 1 | T27: 0 | U27: 1 | V27: 0 | W27: 0 | X27: 0 | Y27: 0 | Z27: 0 | AA27: 1 | AB27: 1 | AC27: 0 | AD27: 0 | AE27: 1 | AF27: 0 | AG27: 0 | AH27: 0 | AI27: -
A28: 51 | B28: Connor McDavid | C28: EDM | D28: C | E28: 1 | F28: 23.6 | G28: 1 | H28: 1 | I28: 0 | J28: 1 | K28: 2 | L28: 50 | M28: 3 | N28: 33.33 | O28: 1.23 | P28: 5 | Q28: 4 | R28: 3 | S28: 2 | T28: 0 | U28: 0 | V28: 0 | W28: 0 | X28: 0 | Y28: 0 | Z28: 0 | AA28: 1 | AB28: 4 | AC28: 1 | AD28: 0 | AE28: 0 | AF28: 0 | AG28: 8 | AH28: 9 | AI28: 47.06
A29: 38 | B29: Curtis Lazar | C29: EDM | D29: C | E29: 1 | F29: 11.4 | G29: 0 | H29: 0 | I29: 0 | J29: 0 | K29: 0 | L29: - | M29: 1 | N29: 0 | O29: 0.16 | P29: 2 | Q29: 1 | R29: 0 | S29: 0 | T29: 0 | U29: 0 | V29: 0 | W29: 0 | X29: 0 | Y29: 0 | Z29: 0 | AA29: 0 | AB29: 0 | AC29: 0 | AD29: 3 | AE29: 0 | AF29: 0 | AG29: 7 | AH29: 6 | AI29: 53.85
A30: 126 | B30: Cutter Gauthier | C30: ANA | D30: L | E30: 1 | F30: 17.916667 | G30: 0 | H30: 1 | I30: 0 | J30: 1 | K30: 1 | L30: 50 | M30: 5 | N30: 0 | O30: 0.52 | P30: 8 | Q30: 8 | R30: 5 | S30: 0 | T30: 1 | U30: 1 | V30: 0 | W30: 0 | X30: 0 | Y30: 0 | Z30: 0 | AA30: 1 | AB30: 0 | AC30: 1 | AD30: 1 | AE30: 0 | AF30: 0 | AG30: 0 | AH30: 2 | AI30: 0
A31: 138 | B31: Daniil But | C31: UTA | D31: L | E31: 1 | F31: 12.833333 | G31: 0 | H31: 0 | I31: 0 | J31: 0 | K31: 0 | L31: - | M31: 2 | N31: 0 | O31: 0.14 | P31: 3 | Q31: 3 | R31: 1 | S31: 0 | T31: 0 | U31: 1 | V31: 0 | W31: 0 | X31: 0 | Y31: 0 | Z31: 0 | AA31: 0 | AB31: 0 | AC31: 1 | AD31: 1 | AE31: 1 | AF31: 0 | AG31: 0 | AH31: 1 | AI31: 0
A32: 35 | B32: Darnell Nurse | C32: EDM | D32: D | E32: 1 | F32: 22.383333 | G32: 1 | H32: 0 | I32: 0 | J32: 0 | K32: 1 | L32: 100 | M32: 2 | N32: 50 | O32: 0.11 | P32: 6 | Q32: 3 | R32: 2 | S32: 0 | T32: 0 | U32: 0 | V32: 0 | W32: 0 | X32: 0 | Y32: 0 | Z32: 0 | AA32: 1 | AB32: 1 | AC32: 0 | AD32: 1 | AE32: 3 | AF32: 2 | AG32: 0 | AH32: 0 | AI32: -
A33: 49 | B33: Darren Raddysh | C33: T.B | D33: D | E33: 1 | F33: 25.283333 | G33: 1 | H33: 0 | I33: 0 | J33: 0 | K33: 1 | L33: 50 | M33: 3 | N33: 33.33 | O33: 0.17 | P33: 4 | Q33: 4 | R33: 1 | S33: 0 | T33: 0 | U33: 0 | V33: 0 | W33: 0 | X33: 0 | Y33: 0 | Z33: 0 | AA33: 1 | AB33: 1 | AC33: 0 | AD33: 2 | AE33: 1 | AF33: 1 | AG33: 0 | AH33: 0 | AI33: -
A34: 45 | B34: David Pastrnak | C34: BOS | D34: R | E34: 1 | F34: 22.5 | G34: 0 | H34: 3 | I34: 3 | J34: 0 | K34: 3 | L34: 100 | M34: 2 | N34: 0 | O34: 0.12 | P34: 6 | Q34: 3 | R34: 2 | S34: 0 | T34: 0 | U34: 1 | V34: 0 | W34: 0 | X34: 0 | Y34: 0 | Z34: 0 | AA34: 0 | AB34: 2 | AC34: 0 | AD34: 1 | AE34: 1 | AF34: 1 | AG34: 0 | AH34: 0 | AI34: -
A35: 125 | B35: Declan Carlile | C35: T.B | D35: D | E35: 1 | F35: 17.4 | G35: 0 | H35: 0 | I35: 0 | J35: 0 | K35: 0 | L35: - | M35: 0 | N35: - | O35: 0 | P35: 1 | Q35: 0 | R35: 1 | S35: 0 | T35: 0 | U35: 0 | V35: 4 | W35: 2 | X35: 2 | Y35: 0 | Z35: 0 | AA35: 1 | AB35: 1 | AC35: 0 | AD35: 1 | AE35: 1 | AF35: 0 | AG35: 0 | AH35: 0 | AI35: -
A36: 135 | B36: Denver Barkey | C36: PHI | D36: C | E36: 1 | F36: 14.683333 | G36: 0 | H36: 0 | I36: 0 | J36: 0 | K36: 0 | L36: - | M36: 1 | N36: 0 | O36: 0.12 | P36: 1 | Q36: 1 | R36: 1 | S36: 1 | T36: 0 | U36: 0 | V36: 0 | W36: 0 | X36: 0 | Y36: 0 | Z36: 0 | AA36: 0 | AB36: 0 | AC36: 0 | AD36: 0 | AE36: 0 | AF36: 0 | AG36: 1 | AH36: 0 | AI36: 100
A37: 134 | B37: Dominic James | C37: T.B | D37: C | E37: 1 | F37: 13.233333 | G37: 0 | H37: 0 | I37: 0 | J37: 0 | K37: 0 | L37: - | M37: 4 | N37: 0 | O37: 0.28 | P37: 5 | Q37: 5 | R37: 3 | S37: 1 | T37: 0 | U37: 0 | V37: 0 | W37: 0 | X37: 0 | Y37: 0 | Z37: 0 | AA37: 1 | AB37: 1 | AC37: 0 | AD37: 0 | AE37: 0 | AF37: 0 | AG37: 2 | AH37: 3 | AI37: 40
A38: 101 | B38: Drew Helleson | C38: ANA | D38: D | E38: 1 | F38: 14.933333 | G38: 0 | H38: 0 | I38: 0 | J38: 0 | K38: 0 | L38: - | M38: 0 | N38: - | O38: 0 | P38: 1 | Q38: 0 | R38: 1 | S38: 0 | T38: 0 | U38: 0 | V38: 0 | W38: 0 | X38: 0 | Y38: 0 | Z38: 0 | AA38: 0 | AB38: 2 | AC38: 0 | AD38: 3 | AE38: 0 | AF38: 0 | AG38: 0 | AH38: 0 | AI38: -
A39: 122 | B39: Dylan Guenther | C39: UTA | D39: R | E39: 1 | F39: 18.466667 | G39: 0 | H39: 0 | I39: 0 | J39: 0 | K39: 0 | L39: - | M39: 5 | N39: 0 | O39: 0.58 | P39: 11 | Q39: 9 | R39: 4 | S39: 2 | T39: 0 | U39: 2 | V39: 0 | W39: 0 | X39: 0 | Y39: 0 | Z39: 0 | AA39: 0 | AB39: 0 | AC39: 1 | AD39: 0 | AE39: 0 | AF39: 1 | AG39: 0 | AH39: 0 | AI39: -
A40: 34 | B40: Elias Lindholm | C40: BOS | D40: C | E40: 1 | F40: 20.716667 | G40: 2 | H40: 0 | I40: 0 | J40: 0 | K40: 2 | L40: 66.67 | M40: 4 | N40: 50 | O40: 0.82 | P40: 8 | Q40: 7 | R40: 6 | S40: 6 | T40: 0 | U40: 0 | V40: 0 | W40: 0 | X40: 0 | Y40: 0 | Z40: 0 | AA40: 0 | AB40: 1 | AC40: 0 | AD40: 0 | AE40: 0 | AF40: 2 | AG40: 7 | AH40: 9 | AI40: 43.75
...

Sheet fc
A1: Player | B1: Inj | C1: Likes | D1: Pos | E1: Salary | F1: Team | G1: Opp | H1: Time | I1: Fav. | J1: Win % | K1: Spread | L1: Total | M1: TeamGoal | N1: OppGoal | O1: Start/Line | P1: PP Unit | Q1: avg TOI | R1: Avg | S1: STDV | T1: Ceiling | U1: FC Proj | V1: My Proj | W1: Exp. | X1: Used | Y1: Con. | Z1: Value | AA1: Own% | AB1: TOI | AC1: Score | AD1: Val
A2: Connor McDavid | C2: 0 | D2: C | E2: 10500 | F2: EDM | G2: vs ANA | H2: 0.85416667 | I2: Y | J2: 0.609 | K2: -156 | L2: 7 | M2: 4.4 | N2: 3.5 | O2: 1 | P2: 1 | Q2: 0.95208333 | R2: 18.4 | S2: 12.63 | T2: 61.53 | U2: 36.27 | V2: 36.27 | W2: 100 | Y2: 66 | Z2: 3.5 | AA2: 0 | AB2: 0.98333333 | AC2: 18 | AD2: 1.7
A3: Leon Draisaitl | C3: 0 | D3: C | E3: 9300 | F3: EDM | G3: vs ANA | H3: 0.85416667 | I3: Y | J3: 0.609 | K3: -156 | L3: 7 | M3: 4.4 | N3: 3.5 | O3: 2 | P3: 1 | Q3: 0.91388889 | R3: 14.2 | S3: 9.13 | T3: 43.61 | U3: 25.35 | V3: 25.35 | W3: 100 | Y3: 68 | Z3: 2.7 | AA3: 0 | AB3: 0.83958333 | AC3: 24.5 | AD3: 2.6
A4: Evan Bouchard | C4: 0 | D4: D | E4: 7400 | F4: EDM | G4: vs ANA | H4: 0.85416667 | I4: Y | J4: 0.609 | K4: -156 | L4: 7 | M4: 4.4 | N4: 3.5 | O4: 1 | P4: 1 | Q4: 1.0236111 | R4: 13.1 | S4: 10 | T4: 44.11 | U4: 24.11 | V4: 24.11 | W4: 100 | Y4: 62 | Z4: 3.3 | AA4: 0 | AB4: 0.94930556 | AC4: 9.1 | AD4: 1.2
A5: Nikita Kucherov | C5: 0 | D5: W | E5: 9500 | F5: TB | G5: vs UTA | H5: 0.79166667 | I5: Y | J5: 0.494 | K5: -97.5 | L5: 6 | M5: 3.37 | N5: 3 | O5: 1 | P5: 2 | Q5: 0.84236111 | R5: 16.2 | S5: 9.36 | T5: 41.37 | U5: 22.65 | V5: 22.65 | W5: 100 | Y5: 71 | Z5: 2.4 | AA5: 0 | AB5: 0.76388889 | AC5: 27.4 | AD5: 2.9
A6: Zach Hyman | C6: 0 | D6: W | E6: 7600 | F6: EDM | G6: vs ANA | H6: 0.85416667 | I6: Y | J6: 0.609 | K6: -156 | L6: 7 | M6: 4.4 | N6: 3.5 | O6: 1 | P6: 1 | Q6: 0.84166667 | R6: 12.9 | S6: 9.81 | T6: 42.26 | U6: 22.64 | V6: 22.64 | W6: 100 | Y6: 62 | Z6: 3 | AA6: 0 | AB6: 0.80694444 | AC6: 20.6 | AD6: 2.7
A7: David Pastrnak | C7: 0 | D7: W | E7: 9000 | F7: BOS | G7: @ NYR | H7: 0.79166667 | I7: Y | J7: 0.455 | K7: -83.5 | L7: 6.5 | M7: 3.25 | N7: 3.2 | O7: 1 | P7: 1 | Q7: 0.82847222 | R7: 15.1 | S7: 10.68 | T7: 41.09 | U7: 19.73 | V7: 19.73 | W7: 100 | Y7: 65 | Z7: 2.2 | AA7: 0 | AB7: 0.9375 | AC7: 22.3 | AD7: 2.5
A8: Zach Werenski | C8: 0 | D8: D | E8: 8400 | F8: CBJ | G8: vs LA | H8: 0.79166667 | I8: Y | J8: 0.42 | K8: -72.5 | L8: 6 | M8: 3.06 | N8: 3 | O8: 1 | P8: 1 | Q8: 1.1104167 | R8: 16.1 | S8: 8.71 | T8: 37.56 | U8: 20.14 | V8: 20.14 | W8: 100 | Y8: 73 | Z8: 2.4 | AA8: 0
A9: Brandon Hagel | C9: 0 | D9: W | E9: 7500 | F9: TB | G9: vs UTA | H9: 0.79166667 | I9: Y | J9: 0.494 | K9: -97.5 | L9: 6 | M9: 3.37 | N9: 3 | O9: 1 | P9: 1 | Q9: 0.79166667 | R9: 13.3 | S9: 10.73 | T9: 39.63 | U9: 18.17 | V9: 18.17 | W9: 100 | Y9: 60 | Z9: 2.4 | AA9: 0 | AB9: 0.90694444 | AC9: 7.3 | AD9: 1
A10: Artemi Panarin | C10: 0 | D10: W | E10: 8000 | F10: NYR | G10: vs BOS | H10: 0.79166667 | I10: N | J10: 0.545 | K10: 83.5 | L10: 6.5 | M10: 3.2 | N10: 3.25 | O10: 1 | P10: 1 | Q10: 0.86666667 | R10: 12.7 | S10: 9.65 | T10: 36.12 | U10: 16.82 | V10: 16.82 | W10: 100 | Y10: 62 | Z10: 2.1 | AA10: 0 | AB10: 1.0104167 | AC10: 8 | AD10: 1
A11: Darren Raddysh | C11: 0 | D11: D | E11: 6300 | F11: TB | G11: vs UTA | H11: 0.79166667 | I11: Y | J11: 0.494 | K11: -97.5 | L11: 6 | M11: 3.37 | N11: 3 | O11: 1 | P11: 1 | Q11: 0.92569444 | R11: 12 | S11: 9.25 | T11: 36.25 | U11: 17.75 | V11: 17.75 | W11: 100 | Y11: 61 | Z11: 2.8 | AA11: 0 | AB11: 1.0534722 | AC11: 14.3 | AD11: 2.3
A12: Jake Walman | C12: 0 | D12: D | E12: 4700 | F12: EDM | G12: vs ANA | H12: 0.85416667 | I12: Y | J12: 0.609 | K12: -156 | L12: 7 | M12: 4.4 | N12: 3.5 | O12: 2 | P12: 2 | Q12: 0.81736111 | R12: 9.3 | S12: 7.43 | T12: 31.65 | U12: 16.79 | V12: 16.79 | W12: 100 | Y12: 60 | Z12: 3.6 | AA12: 0 | AB12: 0.93958333 | AC12: 3 | AD12: 0.6
A13: Mika Zibanejad | C13: 0 | D13: C | E13: 7100 | F13: NYR | G13: vs BOS | H13: 0.79166667 | I13: N | J13: 0.545 | K13: 83.5 | L13: 6.5 | M13: 3.2 | N13: 3.25 | O13: 2 | P13: 1 | Q13: 0.86458333 | R13: 12 | S13: 9.47 | T13: 34.71 | U13: 15.77 | V13: 15.77 | W13: 100 | Y13: 61 | Z13: 2.2 | AA13: 0 | AB13: 0.89375 | AC13: 9.5 | AD13: 1.3
A14: Bo Horvat | C14: 0 | D14: C | E14: 7800 | F14: NYI | G14: @ PHI | H14: 0.79166667 | I14: N | J14: 0.567 | K14: 76.5 | L14: 6 | M14: 3 | N14: 3.09 | O14: 1 | P14: 1 | Q14: 0.84791667 | R14: 12.5 | S14: 7.48 | T14: 28.92 | U14: 13.96 | V14: 13.96 | W14: 100 | Y14: 70 | Z14: 1.8 | AA14: 0 | AB14: 0.80347222 | AC14: 1.5 | AD14: 0.2
A15: Dylan Guenther | C15: 0 | D15: W | E15: 7700 | F15: UTA | G15: @ TB | H15: 0.79166667 | I15: N | J15: 0.506 | K15: 97.5 | L15: 6 | M15: 3 | N15: 3.37 | O15: 3 | P15: 1 | Q15: 0.72083333 | R15: 12.2 | S15: 9.1 | T15: 32.68 | U15: 14.48 | V15: 14.48 | W15: 100 | Y15: 63 | Z15: 1.9 | AA15: 0 | AB15: 0.76944444 | AC15: 11.8 | AD15: 1.5
A16: Jake Guentzel | C16: 0 | D16: W | E16: 7000 | F16: TB | G16: vs UTA | H16: 0.79166667 | I16: Y | J16: 0.494 | K16: -97.5 | L16: 6 | M16: 3.37 | N16: 3 | O16: 2 | P16: 1 | Q16: 0.85277778 | R16: 13.1 | S16: 8.84 | T16: 32.99 | U16: 15.31 | V16: 15.31 | W16: 100 | Y16: 66 | Z16: 2.2 | AA16: 0 | AB16: 0.77291667 | AC16: 6.5 | AD16: 0.9
A17: Ilya Sorokin | C17: 0 | D17: G | E17: 7400 | F17: NYI | G17: @ PHI | H17: 0.79166667 | I17: N | J17: 0.567 | K17: 76.5 | L17: 6 | M17: 3 | N17: 3.09 | O17: confirm | Q17: 2.4895833 | R17: 13.9 | S17: 12.37 | T17: 38.46 | U17: 13.72 | V17: 13.72 | W17: 100 | Y17: 56 | Z17: 1.9 | AA17: 0 | AB17: 2.4833333 | AC17: 24.7 | AD17: 3.3
A18: Cutter Gauthier | C18: 0 | D18: W | E18: 6700 | F18: ANA | G18: @ EDM | H18: 0.85416667 | I18: N | J18: 0.391 | K18: 156 | L18: 7 | M18: 3.5 | N18: 4.4 | O18: 2 | P18: 1 | Q18: 0.72291667 | R18: 13.3 | S18: 9.75 | T18: 33.98 | U18: 14.48 | V18: 14.48 | W18: 100 | Y18: 63 | Z18: 2.2 | AA18: 0 | AB18: 0.74652778 | AC18: 15.5 | AD18: 2.3
A19: Clayton Keller | C19: 0 | D19: W | E19: 6900 | F19: UTA | G19: @ TB | H19: 0.79166667 | I19: N | J19: 0.506 | K19: 97.5 | L19: 6 | M19: 3 | N19: 3.37 | O19: 1 | P19: 1 | Q19: 0.79861111 | R19: 11.3 | S19: 8.83 | T19: 31.06 | U19: 13.4 | V19: 13.4 | W19: 100 | Y19: 61 | Z19: 1.9 | AA19: 0 | AB19: 0.83055556 | AC19: 1.5 | AD19: 0.2
A20: Ryan Nugent-Hopkins | C20: 0 | D20: W | E20: 6000 | F20: EDM | G20: vs ANA | H20: 0.85416667 | I20: Y | J20: 0.609 | K20: -156 | L20: 7 | M20: 4.4 | N20: 3.5 | O20: 1 | P20: 1 | Q20: 0.79166667 | R20: 8.9 | S20: 6.9 | T20: 28.14 | U20: 14.34 | V20: 14.34 | W20: 100 | Y20: 61 | Z20: 2.4 | AA20: 0 | AB20: 0.80208333 | AC20: 6.5 | AD20: 1.1
A21: Andrei Vasilevskiy | C21: 0 | D21: G | E21: 8200 | F21: TB | G21: vs UTA | H21: 0.79166667 | I21: Y | J21: 0.494 | K21: -97.5 | L21: 6 | M21: 3.37 | N21: 3 | O21: confirm | Q21: 2.4631944 | R21: 12.6 | S21: 8.36 | T21: 29.7 | U21: 12.98 | V21: 12.98 | W21: 100 | Y21: 67 | Z21: 1.6 | AA21: 0 | AB21: 2.5 | AC21: 29.6 | AD21: 3.6
A22: Beckett Sennecke | C22: 0 | D22: W | E22: 5000 | F22: ANA | G22: @ EDM | H22: 0.85416667 | I22: N | J22: 0.391 | K22: 156 | L22: 7 | M22: 3.5 | N22: 4.4 | O22: 1 | P22: 1 | Q22: 0.70902778 | R22: 9.3 | S22: 8.13 | T22: 29.81 | U22: 13.55 | V22: 13.55 | W22: 100 | Y22: 56 | Z22: 2.7 | AA22: 0 | AB22: 1.0631944 | AC22: 23.5 | AD22: 4.7
A23: Jackson LaCombe | C23: 0 | D23: D | E23: 4900 | F23: ANA | G23: @ EDM | H23: 0.85416667 | I23: N | J23: 0.391 | K23: 156 | L23: 7 | M23: 3.5 | N23: 4.4 | O23: 1 | P23: 1 | Q23: 1.0215278 | R23: 10.4 | S23: 6.33 | T23: 26.48 | U23: 13.82 | V23: 13.82 | W23: 100 | Y23: 70 | Z23: 2.8 | AA23: 0 | AB23: 1.0944444 | AC23: 11.9 | AD23: 2.4
A24: Darnell Nurse | C24: 0 | D24: D | E24: 4400 | F24: EDM | G24: vs ANA | H24: 0.85416667 | I24: Y | J24: 0.609 | K24: -156 | L24: 7 | M24: 4.4 | N24: 3.5 | O24: 2 | Q24: 0.86597222 | R24: 9.5 | S24: 5.28 | T24: 23.96 | U24: 13.4 | V24: 13.4 | W24: 100 | Y24: 72 | Z24: 3 | AA24: 0 | AB24: 0.93263889 | AC24: 14.1 | AD24: 3.2
A25: Jack Roslovic | C25: 0 | D25: C | E25: 3900 | F25: EDM | G25: vs ANA | H25: 0.85416667 | I25: Y | J25: 0.609 | K25: -156 | L25: 7 | M25: 4.4 | N25: 3.5 | O25: 3 | P25: 2 | Q25: 0.67638889 | R25: 7.6 | S25: 6.64 | T25: 26.53 | U25: 13.25 | V25: 13.25 | W25: 100 | Y25: 56 | Z25: 3.4 | AA25: 0 | AB25: 0.46736111 | AC25: 4.5 | AD25: 1.2
A26: Tristan Jarry | C26: 0 | D26: G | E26: 8400 | F26: EDM | G26: vs ANA | H26: 0.85416667 | I26: Y | J26: 0.609 | K26: -156 | L26: 7 | M26: 4.4 | N26: 3.5 | O26: confirm | Q26: 2.2888889 | R26: 11.5 | S26: 10.9 | T26: 33.65 | U26: 11.85 | V26: 11.85 | W26: 100 | Y26: 53 | Z26: 1.4 | AA26: 0 | AB26: 2.5 | AC26: 20.2 | AD26: 2.4
A27: Darcy Kuemper | C27: 0 | D27: G | E27: 7900 | F27: LA | G27: @ CBJ | H27: 0.79166667 | I27: N | J27: 0.58 | K27: 72.5 | L27: 6 | M27: 3 | N27: 3.06 | O27: prob | Q27: 2.4055556 | R27: 10.5 | S27: 8.71 | T27: 28.63 | U27: 11.21 | V27: 11.21 | W27: 100 | Y27: 59 | Z27: 1.4 | AA27: 0
A28: Ville Husso | C28: 0 | D28: G | E28: 7000 | F28: ANA | G28: @ EDM | H28: 0.85416667 | I28: N | J28: 0.391 | K28: 156 | L28: 7 | M28: 3.5 | N28: 4.4 | O28: confirm | Q28: 2.2895833 | R28: 9.6 | S28: 9.1 | T28: 30.35 | U28: 12.15 | V28: 12.15 | W28: 100 | Y28: 53 | Z28: 1.7 | AA28: 0 | AB28: 2.4006944 | AC28: 0
A29: Kirill Marchenko | C29: 0 | D29: W | E29: 6600 | F29: CBJ | G29: vs LA | H29: 0.79166667 | I29: Y | J29: 0.42 | K29: -72.5 | L29: 6 | M29: 3.06 | N29: 3 | O29: 1 | P29: 1 | Q29: 0.78333333 | R29: 11.9 | S29: 7.99 | T29: 28.24 | U29: 12.26 | V29: 12.26 | W29: 100 | Y29: 66 | Z29: 1.9 | AA29: 0
A30: Charlie McAvoy | C30: 0 | D30: D | E30: 5000 | F30: BOS | G30: @ NYR | H30: 0.79166667 | I30: Y | J30: 0.455 | K30: -83.5 | L30: 6.5 | M30: 3.25 | N30: 3.2 | O30: 1 | P30: 1 | Q30: 0.99930556 | R30: 10.2 | S30: 5.54 | T30: 24.18 | U30: 13.1 | V30: 13.1 | W30: 100 | Y30: 73 | Z30: 2.6 | AA30: 0 | AB30: 1.0048611 | AC30: 8 | AD30: 1.6
A31: Joonas Korpisalo | C31: 0 | D31: G | E31: 7800 | F31: BOS | G31: @ NYR | H31: 0.79166667 | I31: Y | J31: 0.455 | K31: -83.5 | L31: 6.5 | M31: 3.25 | N31: 3.2 | O31: confirm | Q31: 2.24375 | R31: 11.6 | S31: 10.63 | T31: 32.35 | U31: 11.09 | V31: 11.09 | W31: 100 | Y31: 54 | Z31: 1.4 | AA31: 0 | AB31: 2.6451389 | AC31: 4.8 | AD31: 0.6
A32: Nick Schmaltz | C32: 0 | D32: C | E32: 6100 | F32: UTA | G32: @ TB | H32: 0.79166667 | I32: N | J32: 0.506 | K32: 97.5 | L32: 6 | M32: 3 | N32: 3.37 | O32: 1 | P32: 1 | Q32: 0.81875 | R32: 10.7 | S32: 9.9 | T32: 31.08 | U32: 11.28 | V32: 11.28 | W32: 100 | Y32: 54 | Z32: 1.8 | AA32: 0 | AB32: 0.92638889 | AC32: 0
A33: Vincent Trocheck | C33: 0 | D33: C | E33: 5800 | F33: NYR | G33: vs BOS | H33: 0.79166667 | I33: N | J33: 0.545 | K33: 83.5 | L33: 6.5 | M33: 3.2 | N33: 3.25 | O33: 1 | P33: 1 | Q33: 0.87152778 | R33: 9 | S33: 6.24 | T33: 23.85 | U33: 11.37 | V33: 11.37 | W33: 100 | Y33: 65 | Z33: 2 | AA33: 0 | AB33: 1.0458333 | AC33: 10.5 | AD33: 1.8
A34: Mikhail Sergachev | C34: 0 | D34: D | E34: 5700 | F34: UTA | G34: @ TB | H34: 0.79166667 | I34: N | J34: 0.506 | K34: 97.5 | L34: 6 | M34: 3 | N34: 3.37 | O34: 1 | P34: 1 | Q34: 1.0111111 | R34: 10.8 | S34: 6.67 | T34: 25.22 | U34: 11.88 | V34: 11.88 | W34: 100 | Y34: 69 | Z34: 2.1 | AA34: 0 | AB34: 1.0444444 | AC34: 4.3 | AD34: 0.8
A35: Travis Konecny | C35: 0 | D35: W | E35: 5600 | F35: PHI | G35: vs NYI | H35: 0.79166667 | I35: Y | J35: 0.433 | K35: -76.5 | L35: 6 | M35: 3.09 | N35: 3 | O35: 1 | P35: 1 | Q35: 0.78541667 | R35: 10.6 | S35: 7.13 | T35: 26.52 | U35: 12.26 | V35: 12.26 | W35: 100 | Y35: 66 | Z35: 2.2 | AA35: 0 | AB35: 0.62569444 | AC35: 1.5 | AD35: 0.3
A36: Morgan Geekie | C36: 0 | D36: W | E36: 5200 | F36: BOS | G36: @ NYR | H36: 0.79166667 | I36: Y | J36: 0.455 | K36: -83.5 | L36: 6.5 | M36: 3.25 | N36: 3.2 | O36: 1 | P36: 1 | Q36: 0.71736111 | R36: 10.4 | S36: 7.63 | T36: 27.62 | U36: 12.36 | V36: 12.36 | W36: 100 | Y36: 63 | Z36: 2.4 | AA36: 0 | AB36: 0.80069444 | AC36: 15.8 | AD36: 3
A37: Brandt Clarke | C37: 0 | D37: D | E37: 4800 | F37: LA | G37: @ CBJ | H37: 0.79166667 | I37: N | J37: 0.58 | K37: 72.5 | L37: 6 | M37: 3 | N37: 3.06 | O37: 2 | P37: 1 | Q37: 0.78958333 | R37: 9.5 | S37: 6.06 | T37: 23.91 | U37: 11.79 | V37: 11.79 | W37: 100 | Y37: 68 | Z37: 2.5 | AA37: 0
A38: Mikael Granlund | C38: 0 | D38: C | E38: 4500 | F38: ANA | G38: @ EDM | H38: 0.85416667 | I38: N | J38: 0.391 | K38: 156 | L38: 7 | M38: 3.5 | N38: 4.4 | O38: 1 | P38: 1 | Q38: 0.77569444 | R38: 8.8 | S38: 8.56 | T38: 29.14 | U38: 12.02 | V38: 12.02 | W38: 100 | Y38: 51 | Z38: 2.7 | AA38: 0 | AB38: 1.0118056 | AC38: 43.3 | AD38: 9.6
A39: Viktor Arvidsson | C39: 0 | D39: W | E39: 4400 | F39: BOS | G39: @ NYR | H39: 0.79166667 | I39: Y | J39: 0.455 | K39: -83.5 | L39: 6.5 | M39: 3.25 | N39: 3.2 | O39: 2 | P39: 2 | Q39: 0.60069444 | R39: 9.3 | S39: 6.3 | T39: 25.27 | U39: 12.67 | V39: 12.67 | W39: 100 | Y39: 66 | Z39: 2.9 | AA39: 0 | AB39: 0.53125 | AC39: 0
A40: J.T. Miller | C40: 0 | D40: W | E40: 5700 | F40: NYR | G40: vs BOS | H40: 0.79166667 | I40: N | J40: 0.545 | K40: 83.5 | L40: 6.5 | M40: 3.2 | N40: 3.25 | O40: 2 | P40: 1 | Q40: 0.85763889 | R40: 9.1 | S40: 7.26 | T40: 25.5 | U40: 10.98 | V40: 10.98 | W40: 100 | Y40: 60 | Z40: 1.9 | AA40: 0 | AB40: 0.88333333 | AC40: 11.3 | AD40: 2
...
