Workbook

Sheet Actual
A1: Player | B1: Roster Position | C1: %Drafted | D1: FPTS
A2: Adam Boqvist | B2: D | C2: 0.0051 | D2: 0
A3: Adam Fantilli | B3: C | C3: 0.1566 | D3: 11
A4: Adam Pelech | B4: D | C4: 0.0758 | D4: 9.3
A5: Alexis Lafreniere | B5: W | C5: 0.1027 | D5: 3
A6: Anders Lee | B6: UTIL | C6: 0.0808 | D6: 13.1
A7: Anthony Duclair | B7: W | C7: 0.2694 | D7: 2.8
A8: Artem Zub | B8: D | C8: 0.0303 | D8: 12.8
A9: Artemi Panarin | B9: W | C9: 0.0101 | D9: 0
A10: Artturi Lehkonen | B10: W | C10: 0.1296 | D10: 0
A11: Bo Horvat | B11: C | C11: 0.0943 | D11: 6.5
A12: Bobby Brink | B12: W | C12: 0.0623 | D12: 1.3
A13: Boone Jenner | B13: W | C13: 0.0741 | D13: 2.8
... A113: Zach Werenski | B113: D | C113: 0.1616 | D113: 14.3

Sheet Projection
A1: name | B1: team | C1: position | D1: salary | E1: projected_fpts | F1: dk_avg_fpts | G1: edge | H1: value | I1: floor | J1: ceiling | K1: player_type | L1: actual | M1: own | N1: TOI
A2: Travis Konecny | B2: PHI | C2: W | D2: 5500 | E2: 12.095887 | F2: 10.14 | G2: 1.9558866 | H2: 2.1992521 | I2: 3.0239717 | J2: 35.239717 | K2: skater | L2: =IFERROR(VLOOKUP($A2,Actual!$A:$D,4,FALSE),IFERROR(VLOOKUP($A2,FC!$A:$AC,29,FALSE),"Not Found")) -> 37.3 | M2: =IFERROR(VLOOKUP($A2,Actual!$A:$D,3,FALSE),"0") -> 0.1818 | N2: =VLOOKUP(A2,NHT!B:F,5,FALSE) -> 12.683333
A3: Mathew Barzal | B3: NYI | C3: C | D3: 6500 | E3: 11.142732 | F3: 9.59 | G3: 1.5527321 | H3: 1.7142665 | I3: 2.785683 | J3: 32.85683 | K3: skater | L3: =IFERROR(VLOOKUP($A3,Actual!$A:$D,4,FALSE),IFERROR(VLOOKUP($A3,FC!$A:$AC,29,FALSE),"Not Found")) -> 25.9 | M3: =IFERROR(VLOOKUP($A3,Actual!$A:$D,3,FALSE),"0") -> 0.1431 | N3: =VLOOKUP(A3,NHT!B:F,5,FALSE) -> 13.983333
A4: Simon Holmstrom | B4: NYI | C4: W | D4: 3300 | E4: 7.1096113 | F4: 6.22 | G4: 0.88961125 | H4: 2.1544277 | I4: 1.7774028 | J4: 22.774028 | K4: skater | L4: =IFERROR(VLOOKUP($A4,Actual!$A:$D,4,FALSE),IFERROR(VLOOKUP($A4,FC!$A:$AC,29,FALSE),"Not Found")) -> 24.5 | M4: =IFERROR(VLOOKUP($A4,Actual!$A:$D,3,FALSE),"0") -> 0.096 | N4: =VLOOKUP(A4,NHT!B:F,5,FALSE) -> 12.183333
A5: Jean-Gabriel Pageau | B5: NYI | C5: C | D5: 3500 | E5: 6.6459421 | F5: 6.36 | G5: 0.2859421 | H5: 1.8988406 | I5: 1.6614855 | J5: 21.614855 | K5: skater | L5: =IFERROR(VLOOKUP($A5,Actual!$A:$D,4,FALSE),IFERROR(VLOOKUP($A5,FC!$A:$AC,29,FALSE),"Not Found")) -> 19.3 | M5: =IFERROR(VLOOKUP($A5,Actual!$A:$D,3,FALSE),"0") -> 0.0539 | N5: =VLOOKUP(A5,NHT!B:F,5,FALSE) -> 12.05
A6: Tim Stuetzle | B6: OTT | C6: C | D6: 6800 | E6: 12.785263 | F6: 12.03 | G6: 0.75526261 | H6: 1.8801857 | I6: 3.1963157 | J6: 36.963157 | K6: skater | L6: =IFERROR(VLOOKUP($A6,Actual!$A:$D,4,FALSE),IFERROR(VLOOKUP($A6,FC!$A:$AC,29,FALSE),"Not Found")) -> 18 | M6: =IFERROR(VLOOKUP($A6,Actual!$A:$D,3,FALSE),"0") -> 0.0657 | N6: =VLOOKUP(A6,NHT!B:F,5,FALSE) -> 13.283333
A7: Mathieu Olivier | B7: CBJ | C7: W | D7: 2800 | E7: 5.259493 | F7: 5.02 | G7: 0.23949301 | H7: 1.8783904 | I7: 1.3148733 | J7: 18.148733 | K7: skater | L7: =IFERROR(VLOOKUP($A7,Actual!$A:$D,4,FALSE),IFERROR(VLOOKUP($A7,FC!$A:$AC,29,FALSE),"Not Found")) -> 17.8 | M7: =IFERROR(VLOOKUP($A7,Actual!$A:$D,3,FALSE),"0") -> 0.0168 | N7: =VLOOKUP(A7,NHT!B:F,5,FALSE) -> 11.883333
A8: Matthew Schaefer | B8: NYI | C8: D | D8: 6000 | E8: 12.337982 | F8: 10.06 | G8: 2.2779822 | H8: 2.0563304 | I8: 3.0844955 | J8: 35.844955 | K8: skater | L8: =IFERROR(VLOOKUP($A8,Actual!$A:$D,4,FALSE),IFERROR(VLOOKUP($A8,FC!$A:$AC,29,FALSE),"Not Found")) -> 16.4 | M8: =IFERROR(VLOOKUP($A8,Actual!$A:$D,3,FALSE),"0") -> 0.1094 | N8: =VLOOKUP(A8,NHT!B:F,5,FALSE) -> 20.333333
A9: Charlie Coyle | B9: CBJ | C9: C | D9: 4100 | E9: 8.3930991 | F9: 7.86 | G9: 0.53309908 | H9: 2.0470973 | I9: 2.0982748 | J9: 25.982748 | K9: skater | L9: =IFERROR(VLOOKUP($A9,Actual!$A:$D,4,FALSE),IFERROR(VLOOKUP($A9,FC!$A:$AC,29,FALSE),"Not Found")) -> 15 | M9: =IFERROR(VLOOKUP($A9,Actual!$A:$D,3,FALSE),"0") -> 0.1263 | N9: =VLOOKUP(A9,NHT!B:F,5,FALSE) -> 11.433333
A10: Emil Heineman | B10: NYI | C10: W | D10: 4200 | E10: 8.7952498 | F10: 7.88 | G10: 0.91524977 | H10: 2.0941071 | I10: 2.1988124 | J10: 26.988124 | K10: skater | L10: =IFERROR(VLOOKUP($A10,Actual!$A:$D,4,FALSE),IFERROR(VLOOKUP($A10,FC!$A:$AC,29,FALSE),"Not Found")) -> 14.5 | M10: =IFERROR(VLOOKUP($A10,Actual!$A:$D,3,FALSE),"0") -> 0.0892 | N10: =VLOOKUP(A10,NHT!B:F,5,FALSE) -> 13.15
A11: Claude Giroux | B11: OTT | C11: W | D11: 3500 | E11: 8.4397722 | F11: 7.13 | G11: 1.3097722 | H11: 2.4113635 | I11: 2.1099431 | J11: 26.099431 | K11: skater | L11: =IFERROR(VLOOKUP($A11,Actual!$A:$D,4,FALSE),IFERROR(VLOOKUP($A11,FC!$A:$AC,29,FALSE),"Not Found")) -> 14.5 | M11: =IFERROR(VLOOKUP($A11,Actual!$A:$D,3,FALSE),"0") -> 0.0522 | N11: =VLOOKUP(A11,NHT!B:F,5,FALSE) -> 13.666667
A12: Zach Werenski | B12: CBJ | C12: D | D12: 8500 | E12: 18.007785 | F12: 16.08 | G12: 1.9277854 | H12: 2.118563 | I12: 4.5019464 | J12: 50.019464 | K12: skater | L12: =IFERROR(VLOOKUP($A12,Actual!$A:$D,4,FALSE),IFERROR(VLOOKUP($A12,FC!$A:$AC,29,FALSE),"Not Found")) -> 14.3 | M12: =IFERROR(VLOOKUP($A12,Actual!$A:$D,3,FALSE),"0") -> 0.1616 | N12: =VLOOKUP(A12,NHT!B:F,5,FALSE) -> 16.033333
A13: Nick Cousins | B13: OTT | C13: C | D13: 2500 | E13: 3.9640097 | F13: 3.49 | G13: 0.47400972 | H13: 1.5856039 | I13: 0.99100243 | J13: 14.910024 | K13: skater | L13: =IFERROR(VLOOKUP($A13,Actual!$A:$D,4,FALSE),IFERROR(VLOOKUP($A13,FC!$A:$AC,29,FALSE),"Not Found")) -> 14.3 | M13: =IFERROR(VLOOKUP($A13,Actual!$A:$D,3,FALSE),"0") -> 0 | N13: =VLOOKUP(A13,NHT!B:F,5,FALSE) -> 16.716667
... A108: Taylor Makar | B108: COL | C108: W | D108: 2500 | E108: 2.455299 | F108: 1.48 | G108: 0.97529903 | H108: 0.98211961 | I108: 0.61382476 | J108: 11.138248 | K108: skater | L108: =IFERROR(VLOOKUP($A108,Actual!$A:$D,4,FALSE),IFERROR(VLOOKUP($A108,FC!$A:$AC,29,FALSE),"Not Found")) -> 0 | M108: =IFERROR(VLOOKUP($A108,Actual!$A:$D,3,FALSE),"0") -> 0.0017 | N108: =VLOOKUP(A108,NHT!B:F,5,FALSE) -> 5.5

Sheet NHT
B1: Player | C1: Team | D1: Position | E1: GP | F1: TOI | G1: Goals | H1: Total Assists | I1: First Assists | J1: Second Assists | K1: Total Points | L1: IPP | M1: Shots | N1: SH% | O1: ixG | P1: iCF | Q1: iFF | R1: iSCF | S1: iHDCF | T1: Rush Attempts | U1: Rebounds Created | V1: PIM | W1: Total Penalties | X1: Minor | Y1: Major | Z1: Misconduct | AA1: Penalties Drawn | AB1: Giveaways | AC1: Takeaways | AD1: Hits | AE1: Hits Taken | AF1: Shots Blocked | AG1: Faceoffs Won | AH1: Faceoffs Lost | AI1: Faceoffs %
A2: 104 | B2: Adam Fantilli | C2: CBJ | D2: C | E2: 1 | F2: 13.2 | G2: 0 | H2: 0 | I2: 0 | J2: 0 | K2: 0 | L2: - | M2: 2 | N2: 0 | O2: 0.48 | P2: 6 | Q2: 5 | R2: 3 | S2: 2 | T2: 0 | U2: 1 | V2: 0 | W2: 0 | X2: 0 | Y2: 0 | Z2: 0 | AA2: 0 | AB2: 0 | AC2: 0 | AD2: 2 | AE2: 1 | AF2: 0 | AG2: 10 | AH2: 4 | AI2: 71.43
A3: 22 | B3: Adam Pelech | C3: NYI | D3: D | E3: 1 | F3: 15.733333 | G3: 0 | H3: 1 | I3: 1 | J3: 0 | K3: 1 | L3: 50 | M3: 2 | N3: 0 | O3: 0.02 | P3: 2 | Q3: 2 | R3: 0 | S3: 0 | T3: 0 | U3: 0 | V3: 0 | W3: 0 | X3: 0 | Y3: 0 | Z3: 0 | AA3: 0 | AB3: 1 | AC3: 1 | AD3: 0 | AE3: 1 | AF3: 1 | AG3: 0 | AH3: 0 | AI3: -
A4: 84 | B4: Alexis Lafreniere | C4: NYR | D4: L | E4: 1 | F4: 11.5 | G4: 0 | H4: 0 | I4: 0 | J4: 0 | K4: 0 | L4: - | M4: 0 | N4: - | O4: 0.04 | P4: 1 | Q4: 1 | R4: 0 | S4: 0 | T4: 0 | U4: 0 | V4: 2 | W4: 1 | X4: 1 | Y4: 0 | Z4: 0 | AA4: 1 | AB4: 0 | AC4: 1 | AD4: 0 | AE4: 0 | AF4: 0 | AG4: 0 | AH4: 0 | AI4: -
A5: 5 | B5: Anders Lee | C5: NYI | D5: L | E5: 1 | F5: 12.633333 | G5: 0 | H5: 0 | I5: 0 | J5: 0 | K5: 0 | L5: 0 | M5: 3 | N5: 0 | O5: 0.21 | P5: 4 | Q5: 3 | R5: 3 | S5: 1 | T5: 0 | U5: 2 | V5: 0 | W5: 0 | X5: 0 | Y5: 0 | Z5: 0 | AA5: 0 | AB5: 1 | AC5: 0 | AD5: 1 | AE5: 2 | AF5: 2 | AG5: 1 | AH5: 0 | AI5: 100
A6: 26 | B6: Anthony Duclair | C6: NYI | D6: L | E6: 1 | F6: 13.95 | G6: 0 | H6: 0 | I6: 0 | J6: 0 | K6: 0 | L6: - | M6: 0 | N6: - | O6: 0 | P6: 1 | Q6: 0 | R6: 0 | S6: 0 | T6: 0 | U6: 0 | V6: 0 | W6: 0 | X6: 0 | Y6: 0 | Z6: 0 | AA6: 0 | AB6: 1 | AC6: 1 | AD6: 0 | AE6: 1 | AF6: 1 | AG6: 0 | AH6: 0 | AI6: -
A7: 88 | B7: Artem Zub | C7: OTT | D7: D | E7: 1 | F7: 19.583333 | G7: 0 | H7: 1 | I7: 1 | J7: 0 | K7: 1 | L7: 100 | M7: 1 | N7: 0 | O7: 0.02 | P7: 3 | Q7: 2 | R7: 1 | S7: 0 | T7: 0 | U7: 1 | V7: 0 | W7: 0 | X7: 0 | Y7: 0 | Z7: 0 | AA7: 0 | AB7: 0 | AC7: 1 | AD7: 2 | AE7: 2 | AF7: 0 | AG7: 0 | AH7: 0 | AI7: -
A8: 28 | B8: Artturi Lehkonen | C8: COL | D8: L | E8: 1 | F8: 15.45 | G8: 0 | H8: 0 | I8: 0 | J8: 0 | K8: 0 | L8: 0 | M8: 0 | N8: - | O8: 0 | P8: 1 | Q8: 0 | R8: 1 | S8: 0 | T8: 0 | U8: 0 | V8: 2 | W8: 1 | X8: 1 | Y8: 0 | Z8: 0 | AA8: 0 | AB8: 1 | AC8: 0 | AD8: 2 | AE8: 4 | AF8: 0 | AG8: 0 | AH8: 1 | AI8: 0
A9: 33 | B9: Bo Horvat | C9: NYI | D9: C | E9: 1 | F9: 13.183333 | G9: 0 | H9: 0 | I9: 0 | J9: 0 | K9: 0 | L9: 0 | M9: 1 | N9: 0 | O9: 0.21 | P9: 3 | Q9: 3 | R9: 2 | S9: 2 | T9: 0 | U9: 0 | V9: 2 | W9: 1 | X9: 1 | Y9: 0 | Z9: 0 | AA9: 0 | AB9: 1 | AC9: 0 | AD9: 0 | AE9: 1 | AF9: 0 | AG9: 7 | AH9: 4 | AI9: 63.64
A10: 74 | B10: Bobby Brink | C10: PHI | D10: R | E10: 1 | F10: 10.966667 | G10: 0 | H10: 0 | I10: 0 | J10: 0 | K10: 0 | L10: - | M10: 0 | N10: - | O10: 0 | P10: 1 | Q10: 0 | R10: 0 | S10: 0 | T10: 0 | U10: 0 | V10: 0 | W10: 0 | X10: 0 | Y10: 0 | Z10: 0 | AA10: 0 | AB10: 2 | AC10: 0 | AD10: 2 | AE10: 0 | AF10: 0 | AG10: 0 | AH10: 0 | AI10: -
A11: 18 | B11: Boone Jenner | C11: CBJ | D11: C | E11: 1 | F11: 13.1 | G11: 0 | H11: 0 | I11: 0 | J11: 0 | K11: 0 | L11: 0 | M11: 1 | N11: 0 | O11: 0.07 | P11: 1 | Q11: 1 | R11: 0 | S11: 0 | T11: 0 | U11: 1 | V11: 0 | W11: 0 | X11: 0 | Y11: 0 | Z11: 0 | AA11: 0 | AB11: 1 | AC11: 0 | AD11: 1 | AE11: 1 | AF11: 1 | AG11: 0 | AH11: 0 | AI11: -
A12: 80 | B12: Braden Schneider | C12: NYR | D12: D | E12: 1 | F12: 19.916667 | G12: 0 | H12: 0 | I12: 0 | J12: 0 | K12: 0 | L12: - | M12: 3 | N12: 0 | O12: 0.16 | P12: 5 | Q12: 4 | R12: 3 | S12: 0 | T12: 1 | U12: 0 | V12: 0 | W12: 0 | X12: 0 | Y12: 0 | Z12: 0 | AA12: 0 | AB12: 1 | AC12: 0 | AD12: 2 | AE12: 3 | AF12: 0 | AG12: 0 | AH12: 0 | AI12: -
A13: 64 | B13: Brady Tkachuk | C13: OTT | D13: L | E13: 1 | F13: 11.45 | G13: 0 | H13: 0 | I13: 0 | J13: 0 | K13: 0 | L13: - | M13: 1 | N13: 0 | O13: 0.25 | P13: 4 | Q13: 3 | R13: 1 | S13: 1 | T13: 0 | U13: 0 | V13: 0 | W13: 0 | X13: 0 | Y13: 0 | Z13: 0 | AA13: 0 | AB13: 1 | AC13: 2 | AD13: 1 | AE13: 1 | AF13: 0 | AG13: 2 | AH13: 0 | AI13: 100
A14: 95 | B14: Brennan Othmann | C14: NYR | D14: L | E14: 1 | F14: 12.983333 | G14: 0 | H14: 0 | I14: 0 | J14: 0 | K14: 0 | L14: 0 | M14: 0 | N14: - | O14: 0 | P14: 1 | Q14: 0 | R14: 1 | S14: 0 | T14: 0 | U14: 0 | V14: 0 | W14: 0 | X14: 0 | Y14: 0 | Z14: 0 | AA14: 0 | AB14: 0 | AC14: 0 | AD14: 4 | AE14: 2 | AF14: 0 | AG14: 0 | AH14: 1 | AI14: 0
A15: 1 | B15: Brent Burns | C15: COL | D15: D | E15: 1 | F15: 18.45 | G15: 0 | H15: 0 | I15: 0 | J15: 0 | K15: 0 | L15: 0 | M15: 1 | N15: 0 | O15: 0.02 | P15: 2 | Q15: 2 | R15: 0 | S15: 0 | T15: 0 | U15: 1 | V15: 0 | W15: 0 | X15: 0 | Y15: 0 | Z15: 0 | AA15: 0 | AB15: 2 | AC15: 0 | AD15: 0 | AE15: 1 | AF15: 0 | AG15: 0 | AH15: 0 | AI15: -
A16: 8 | B16: Brock Nelson | C16: COL | D16: C | E16: 1 | F16: 18.283333 | G16: 0 | H16: 1 | I16: 1 | J16: 0 | K16: 1 | L16: inf | M16: 0 | N16: - | O16: 0 | P16: 0 | Q16: 0 | R16: 0 | S16: 0 | T16: 0 | U16: 0 | V16: 0 | W16: 0 | X16: 0 | Y16: 0 | Z16: 0 | AA16: 0 | AB16: 1 | AC16: 0 | AD16: 0 | AE16: 1 | AF16: 1 | AG16: 6 | AH16: 5 | AI16: 54.55
A17: 59 | B17: Cale Makar | C17: COL | D17: D | E17: 1 | F17: 22.366667 | G17: 0 | H17: 0 | I17: 0 | J17: 0 | K17: 0 | L17: - | M17: 4 | N17: 0 | O17: 0.19 | P17: 8 | Q17: 6 | R17: 2 | S17: 0 | T17: 0 | U17: 1 | V17: 0 | W17: 0 | X17: 0 | Y17: 0 | Z17: 0 | AA17: 0 | AB17: 1 | AC17: 1 | AD17: 0 | AE17: 0 | AF17: 1 | AG17: 0 | AH17: 0 | AI17: -
A18: 73 | B18: Cam York | C18: PHI | D18: D | E18: 1 | F18: 17.716667 | G18: 0 | H18: 1 | I18: 1 | J18: 0 | K18: 1 | L18: 100 | M18: 2 | N18: 0 | O18: 0.09 | P18: 2 | Q18: 2 | R18: 1 | S18: 1 | T18: 0 | U18: 0 | V18: 0 | W18: 0 | X18: 0 | Y18: 0 | Z18: 0 | AA18: 0 | AB18: 0 | AC18: 0 | AD18: 0 | AE18: 2 | AF18: 1 | AG18: 0 | AH18: 0 | AI18: -
A19: 51 | B19: Carl Grundstrom | C19: PHI | D19: R | E19: 1 | F19: 8.8666667 | G19: 0 | H19: 0 | I19: 0 | J19: 0 | K19: 0 | L19: - | M19: 0 | N19: - | O19: 0 | P19: 0 | Q19: 0 | R19: 0 | S19: 0 | T19: 0 | U19: 0 | V19: 0 | W19: 0 | X19: 0 | Y19: 0 | Z19: 0 | AA19: 0 | AB19: 0 | AC19: 0 | AD19: 3 | AE19: 0 | AF19: 1 | AG19: 0 | AH19: 0 | AI19: -
A20: 24 | B20: Carson Soucy | C20: NYI | D20: D | E20: 1 | F20: 14.7 | G20: 0 | H20: 0 | I20: 0 | J20: 0 | K20: 0 | L20: - | M20: 2 | N20: 0 | O20: 0.05 | P20: 3 | Q20: 3 | R20: 0 | S20: 0 | T20: 0 | U20: 0 | V20: 0 | W20: 0 | X20: 0 | Y20: 0 | Z20: 0 | AA20: 0 | AB20: 2 | AC20: 0 | AD20: 1 | AE20: 5 | AF20: 1 | AG20: 0 | AH20: 0 | AI20: -
A21: 4 | B21: Casey Cizikas | C21: NYI | D21: C | E21: 1 | F21: 10.933333 | G21: 0 | H21: 0 | I21: 0 | J21: 0 | K21: 0 | L21: - | M21: 0 | N21: - | O21: 0 | P21: 0 | Q21: 0 | R21: 0 | S21: 0 | T21: 0 | U21: 0 | V21: 0 | W21: 0 | X21: 0 | Y21: 0 | Z21: 0 | AA21: 0 | AB21: 1 | AC21: 0 | AD21: 1 | AE21: 1 | AF21: 0 | AG21: 4 | AH21: 5 | AI21: 44.44
A22: 7 | B22: Charlie Coyle | C22: CBJ | D22: C | E22: 1 | F22: 11.433333 | G22: 1 | H22: 1 | I22: 0 | J22: 1 | K22: 2 | L22: 100 | M22: 1 | N22: 100 | O22: 0.2 | P22: 2 | Q22: 2 | R22: 1 | S22: 1 | T22: 0 | U22: 0 | V22: 0 | W22: 0 | X22: 0 | Y22: 0 | Z22: 0 | AA22: 2 | AB22: 1 | AC22: 1 | AD22: 2 | AE22: 1 | AF22: 0 | AG22: 4 | AH22: 5 | AI22: 44.44
A23: 38 | B23: Christian Dvorak | C23: PHI | D23: C | E23: 1 | F23: 13.85 | G23: 0 | H23: 1 | I23: 1 | J23: 0 | K23: 1 | L23: 33.33 | M23: 2 | N23: 0 | O23: 0.22 | P23: 4 | Q23: 3 | R23: 4 | S23: 0 | T23: 0 | U23: 0 | V23: 2 | W23: 1 | X23: 1 | Y23: 0 | Z23: 0 | AA23: 0 | AB23: 0 | AC23: 0 | AD23: 0 | AE23: 0 | AF23: 2 | AG23: 7 | AH23: 7 | AI23: 50
A24: 2 | B24: Claude Giroux | C24: OTT | D24: R | E24: 1 | F24: 13.666667 | G24: 1 | H24: 0 | I24: 0 | J24: 0 | K24: 1 | L24: 50 | M24: 3 | N24: 33.33 | O24: 0.44 | P24: 4 | Q24: 4 | R24: 3 | S24: 2 | T24: 0 | U24: 0 | V24: 0 | W24: 0 | X24: 0 | Y24: 0 | Z24: 0 | AA24: 0 | AB24: 1 | AC24: 1 | AD24: 0 | AE24: 0 | AF24: 0 | AG24: 4 | AH24: 3 | AI24: 57.14
A25: 94 | B25: Cole Sillinger | C25: CBJ | D25: C | E25: 1 | F25: 11.7 | G25: 0 | H25: 1 | I25: 1 | J25: 0 | K25: 1 | L25: 50 | M25: 1 | N25: 0 | O25: 0.04 | P25: 1 | Q25: 1 | R25: 1 | S25: 0 | T25: 0 | U25: 0 | V25: 2 | W25: 1 | X25: 1 | Y25: 0 | Z25: 0 | AA25: 0 | AB25: 0 | AC25: 0 | AD25: 1 | AE25: 0 | AF25: 0 | AG25: 0 | AH25: 0 | AI25: -
A26: 23 | B26: Damon Severson | C26: CBJ | D26: D | E26: 1 | F26: 17.35 | G26: 0 | H26: 1 | I26: 1 | J26: 0 | K26: 1 | L26: 50 | M26: 2 | N26: 0 | O26: 0.07 | P26: 3 | Q26: 2 | R26: 1 | S26: 0 | T26: 0 | U26: 0 | V26: 0 | W26: 0 | X26: 0 | Y26: 0 | Z26: 0 | AA26: 0 | AB26: 0 | AC26: 0 | AD26: 1 | AE26: 0 | AF26: 0 | AG26: 0 | AH26: 0 | AI26: -
A27: 5 | B27: Dan Vladar | C27: PHI | D27: G | E27: 1 | F27: 45.116667
A28: 6 | B28: David Rittich | C28: NYI | D28: G | E28: 1 | F28: 49.9
A29: 98 | B29: Denton Mateychuk | C29: CBJ | D29: D | E29: 1 | F29: 14.75 | G29: 0 | H29: 0 | I29: 0 | J29: 0 | K29: 0 | L29: - | M29: 2 | N29: 0 | O29: 0.03 | P29: 3 | Q29: 2 | R29: 0 | S29: 0 | T29: 0 | U29: 0 | V29: 0 | W29: 0 | X29: 0 | Y29: 0 | Z29: 0 | AA29: 0 | AB29: 2 | AC29: 1 | AD29: 0 | AE29: 0 | AF29: 0 | AG29: 0 | AH29: 0 | AI29: -
A30: 102 | B30: Denver Barkey | C30: PHI | D30: C | E30: 1 | F30: 11.283333 | G30: 0 | H30: 0 | I30: 0 | J30: 0 | K30: 0 | L30: - | M30: 0 | N30: - | O30: 0 | P30: 0 | Q30: 0 | R30: 0 | S30: 0 | T30: 0 | U30: 0 | V30: 0 | W30: 0 | X30: 0 | Y30: 0 | Z30: 0 | AA30: 0 | AB30: 1 | AC30: 1 | AD30: 1 | AE30: 0 | AF30: 0 | AG30: 0 | AH30: 0 | AI30: -
A31: 79 | B31: Dmitri Voronkov | C31: CBJ | D31: L | E31: 1 | F31: 7.6833333 | G31: 0 | H31: 0 | I31: 0 | J31: 0 | K31: 0 | L31: - | M31: 0 | N31: - | O31: 0 | P31: 0 | Q31: 0 | R31: 0 | S31: 0 | T31: 0 | U31: 0 | V31: 2 | W31: 1 | X31: 1 | Y31: 0 | Z31: 0 | AA31: 0 | AB31: 0 | AC31: 0 | AD31: 1 | AE31: 1 | AF31: 0 | AG31: 0 | AH31: 0 | AI31: -
A32: 61 | B32: Drake Batherson | C32: OTT | D32: R | E32: 1 | F32: 13.516667 | G32: 0 | H32: 1 | I32: 1 | J32: 0 | K32: 1 | L32: 100 | M32: 0 | N32: - | O32: 0 | P32: 0 | Q32: 0 | R32: 0 | S32: 0 | T32: 0 | U32: 0 | V32: 0 | W32: 0 | X32: 0 | Y32: 0 | Z32: 0 | AA32: 1 | AB32: 1 | AC32: 0 | AD32: 1 | AE32: 0 | AF32: 0 | AG32: 0 | AH32: 0 | AI32: -
A33: 71 | B33: Dylan Cozens | C33: OTT | D33: C | E33: 1 | F33: 11.95 | G33: 0 | H33: 0 | I33: 0 | J33: 0 | K33: 0 | L33: - | M33: 0 | N33: - | O33: 0 | P33: 0 | Q33: 0 | R33: 0 | S33: 0 | T33: 0 | U33: 0 | V33: 0 | W33: 0 | X33: 0 | Y33: 0 | Z33: 0 | AA33: 0 | AB33: 0 | AC33: 0 | AD33: 1 | AE33: 0 | AF33: 0 | AG33: 2 | AH33: 5 | AI33: 28.57
A34: 68 | B34: Egor Zamula | C34: CBJ | D34: D | E34: 1 | F34: 13.633333 | G34: 0 | H34: 0 | I34: 0 | J34: 0 | K34: 0 | L34: 0 | M34: 2 | N34: 0 | O34: 0.02 | P34: 4 | Q34: 2 | R34: 0 | S34: 0 | T34: 0 | U34: 0 | V34: 0 | W34: 0 | X34: 0 | Y34: 0 | Z34: 0 | AA34: 0 | AB34: 2 | AC34: 0 | AD34: 1 | AE34: 3 | AF34: 3 | AG34: 0 | AH34: 0 | AI34: -
A35: 3 | B35: Elvis Merzlikins | C35: CBJ | D35: G | E35: 1 | F35: 45.116667
A36: 90 | B36: Emil Heineman | C36: NYI | D36: L | E36: 1 | F36: 13.15 | G36: 1 | H36: 0 | I36: 0 | J36: 0 | K36: 1 | L36: 100 | M36: 3 | N36: 33.33 | O36: 0.16 | P36: 4 | Q36: 3 | R36: 1 | S36: 1 | T36: 0 | U36: 0 | V36: 0 | W36: 0 | X36: 0 | Y36: 0 | Z36: 0 | AA36: 0 | AB36: 0 | AC36: 0 | AD36: 4 | AE36: 1 | AF36: 0 | AG36: 0 | AH36: 0 | AI36: -
A37: 9 | B37: Erik Gudbranson | C37: CBJ | D37: D | E37: 1 | F37: 13.45 | G37: 1 | H37: 0 | I37: 0 | J37: 0 | K37: 1 | L37: 100 | M37: 2 | N37: 50 | O37: 0.03 | P37: 3 | Q37: 3 | R37: 0 | S37: 0 | T37: 0 | U37: 0 | V37: 0 | W37: 0 | X37: 0 | Y37: 0 | Z37: 0 | AA37: 0 | AB37: 1 | AC37: 0 | AD37: 1 | AE37: 3 | AF37: 0 | AG37: 0 | AH37: 0 | AI37: -
A38: 60 | B38: Fabian Zetterlund | C38: OTT | D38: L | E38: 1 | F38: 8.9833333 | G38: 0 | H38: 0 | I38: 0 | J38: 0 | K38: 0 | L38: 0 | M38: 1 | N38: 0 | O38: 0.07 | P38: 1 | Q38: 1 | R38: 1 | S38: 0 | T38: 0 | U38: 0 | V38: 0 | W38: 0 | X38: 0 | Y38: 0 | Z38: 0 | AA38: 0 | AB38: 0 | AC38: 1 | AD38: 1 | AE38: 3 | AF38: 0 | AG38: 0 | AH38: 0 | AI38: -
A39: 105 | B39: Gabe Perreault | C39: NYR | D39: R | E39: 1 | F39: 15.466667 | G39: 0 | H39: 0 | I39: 0 | J39: 0 | K39: 0 | L39: - | M39: 1 | N39: 0 | O39: 0.45 | P39: 3 | Q39: 2 | R39: 3 | S39: 2 | T39: 0 | U39: 1 | V39: 0 | W39: 0 | X39: 0 | Y39: 0 | Z39: 0 | AA39: 0 | AB39: 1 | AC39: 1 | AD39: 0 | AE39: 1 | AF39: 1 | AG39: 0 | AH39: 0 | AI39: -
A40: 103 | B40: Gavin Brindley | C40: COL | D40: C | E40: 1 | F40: 8.7166667 | G40: 0 | H40: 0 | I40: 0 | J40: 0 | K40: 0 | L40: - | M40: 1 | N40: 0 | O40: 0.03 | P40: 2 | Q40: 1 | R40: 1 | S40: 0 | T40: 0 | U40: 0 | V40: 0 | W40: 0 | X40: 0 | Y40: 0 | Z40: 0 | AA40: 0 | AB40: 0 | AC40: 0 | AD40: 1 | AE40: 2 | AF40: 0 | AG40: 0 | AH40: 0 | AI40: -
...

Sheet FC
A1: Player | B1: Inj | C1: Likes | D1: Pos | E1: Salary | F1: Team | G1: Opp | H1: Time | I1: Fav. | J1: Win % | K1: Spread | L1: Total | M1: TeamGoal | N1: OppGoal | O1: Start/Line | P1: PP Unit | Q1: avg TOI | R1: Avg | S1: STDV | T1: Ceiling | U1: FC Proj | V1: My Proj | W1: Exp. | X1: Used | Y1: Con. | Z1: Value | AA1: Own% | AB1: TOI | AC1: Score | AD1: Val
A2: Nathan MacKinnon | C2: 0 | D2: C | E2: 10000 | F2: COL | G2: @ OTT | H2: 0.8125 | I2: Y | J2: 0.495 | K2: -98 | L2: 6.5 | M2: 3.25 | N2: 3.02 | O2: 1 | P2: 1 | Q2: 0.91875 | R2: 21 | S2: 11.37 | T2: 48.31 | U2: 25.57 | V2: 25.57 | W2: 100 | Y2: 73 | Z2: 2.6 | AA2: 0 | AB2: 0.98333333 | AC2: 2.8 | AD2: 0.3
A3: Zach Werenski | C3: 0 | D3: D | E3: 8500 | F3: CBJ | G3: vs PHI | H3: 0.8125 | I3: Y | J3: 0.44 | K3: -78.5 | L3: 6.5 | M3: 3.35 | N3: 3.25 | O3: 1 | P3: 1 | Q3: 1.1104167 | R3: 16.1 | S3: 8.71 | T3: 39.47 | U3: 22.05 | V3: 22.05 | W3: 100 | Y3: 73 | Z3: 2.6 | AA3: 0 | AB3: 0.95694444 | AC3: 14.3 | AD3: 1.7
A4: Brock Nelson | C4: 0 | D4: C | E4: 6900 | F4: COL | G4: @ OTT | H4: 0.8125 | I4: Y | J4: 0.495 | K4: -98 | L4: 6.5 | M4: 3.25 | N4: 3.02 | O4: 2 | P4: 1 | Q4: 0.79722222 | R4: 11.6 | S4: 9.08 | T4: 35.95 | U4: 17.79 | V4: 17.79 | W4: 100 | Y4: 61 | Z4: 2.6 | AA4: 0 | AB4: 0.93263889 | AC4: 6.3 | AD4: 0.9
A5: Cale Makar | C5: 0 | D5: D | E5: 8000 | F5: COL | G5: @ OTT | H5: 0.8125 | I5: Y | J5: 0.495 | K5: -98 | L5: 6.5 | M5: 3.25 | N5: 3.02 | O5: 1 | P5: 1 | Q5: 1.0458333 | R5: 14 | S5: 8.69 | T5: 33.1 | U5: 15.72 | V5: 15.72 | W5: 100 | Y5: 69 | Z5: 2 | AA5: 0 | AB5: 1.1402778 | AC5: 12.9 | AD5: 1.6
A6: Bo Horvat | C6: 0 | D6: C | E6: 7600 | F6: NYI | G6: vs NYR | H6: 0.79166667 | I6: Y | J6: 0.458 | K6: -84.5 | L6: 6.5 | M6: 3.5 | N6: 3.25 | O6: 1 | P6: 2 | Q6: 0.84722222 | R6: 12.2 | S6: 7.59 | T6: 31.4 | U6: 16.22 | V6: 16.22 | W6: 100 | Y6: 69 | Z6: 2.1 | AA6: 0 | AB6: 0.71319444 | AC6: 6.5 | AD6: 0.9
A7: Mika Zibanejad | C7: 0 | D7: C | E7: 6600 | F7: NYR | G7: @ NYI | H7: 0.79166667 | I7: N | J7: 0.542 | K7: 84.5 | L7: 6.5 | M7: 3.25 | N7: 3.5 | O7: 1 | P7: 1 | Q7: 0.86458333 | R7: 11.9 | S7: 9.39 | T7: 34.73 | U7: 15.95 | V7: 15.95 | W7: 100 | Y7: 61 | Z7: 2.4 | AA7: 0 | AB7: 0.90208333 | AC7: 11.5 | AD7: 1.7
A8: Brady Tkachuk | C8: 0 | D8: W | E8: 7500 | F8: OTT | G8: vs COL | H8: 0.8125 | I8: N | J8: 0.505 | K8: 98 | L8: 6.5 | M8: 3.02 | N8: 3.25 | O8: 2 | P8: 1 | Q8: 0.72083333 | R8: 13.3 | S8: 9.25 | T8: 33.22 | U8: 14.72 | V8: 14.72 | W8: 100 | Y8: 65 | Z8: 2 | AA8: 0 | AB8: 0.63333333 | AC8: 13 | AD8: 1.7
A9: Martin Necas | C9: 0 | D9: W | E9: 7000 | F9: COL | G9: @ OTT | H9: 0.8125 | I9: Y | J9: 0.495 | K9: -98 | L9: 6.5 | M9: 3.25 | N9: 3.02 | O9: 1 | P9: 1 | Q9: 0.87291667 | R9: 12.2 | S9: 8.41 | T9: 30.57 | U9: 13.75 | V9: 13.75 | W9: 100 | Y9: 66 | Z9: 2 | AA9: 0 | AB9: 0.94236111 | AC9: 0
A10: Kirill Marchenko | C10: 0 | D10: W | E10: 6700 | F10: CBJ | G10: vs PHI | H10: 0.8125 | I10: Y | J10: 0.44 | K10: -78.5 | L10: 6.5 | M10: 3.35 | N10: 3.25 | O10: 1 | P10: 1 | Q10: 0.78333333 | R10: 11.9 | S10: 7.99 | T10: 29.4 | U10: 13.42 | V10: 13.42 | W10: 100 | Y10: 66 | Z10: 2 | AA10: 0 | AB10: 0.74097222 | AC10: 13 | AD10: 1.9
A11: Jake Sanderson | C11: 0 | D11: D | E11: 6300 | F11: OTT | G11: vs COL | H11: 0.8125 | I11: N | J11: 0.505 | K11: 98 | L11: 6.5 | M11: 3.02 | N11: 3.25 | O11: 1 | P11: 1 | Q11: 1.0354167 | R11: 11.7 | S11: 7.83 | T11: 30 | U11: 14.34 | V11: 14.34 | W11: 100 | Y11: 67 | Z11: 2.3 | AA11: 0 | AB11: 1.0298611 | AC11: 9.1 | AD11: 1.4
A12: Tim Stuetzle | C12: 0 | D12: C | E12: 6800 | F12: OTT | G12: vs COL | H12: 0.8125 | I12: N | J12: 0.505 | K12: 98 | L12: 6.5 | M12: 3.02 | N12: 3.25 | O12: 1 | P12: 1 | Q12: 0.85208333 | R12: 11.6 | S12: 8.67 | T12: 30.53 | U12: 13.19 | V12: 13.19 | W12: 100 | Y12: 63 | Z12: 1.9 | AA12: 0 | AB12: 0.76944444 | AC12: 18 | AD12: 2.6
A13: MacKenzie Blackwood | C13: 0 | D13: G | E13: 8300 | F13: COL | G13: @ OTT | H13: 0.8125 | I13: Y | J13: 0.495 | K13: -98 | L13: 6.5 | M13: 3.25 | N13: 3.02 | O13: confirm | Q13: 2.4236111 | R13: 14.4 | S13: 10.58 | T13: 32.51 | U13: 11.35 | V13: 11.35 | W13: 100 | Y13: 63 | Z13: 1.4 | AA13: 0 | AB13: 2.4034722 | AC13: 2.1 | AD13: 0.3
A14: Mathew Barzal | C14: 0 | D14: C | E14: 6500 | F14: NYI | G14: vs NYR | H14: 0.79166667 | I14: Y | J14: 0.458 | K14: -84.5 | L14: 6.5 | M14: 3.5 | N14: 3.25 | O14: 2 | P14: 1 | Q14: 0.86111111 | R14: 9.4 | S14: 6.09 | T14: 24.2 | U14: 12.02 | V14: 12.02 | W14: 100 | Y14: 68 | Z14: 1.8 | AA14: 0 | AB14: 0.83958333 | AC14: 25.9 | AD14: 4
A15: Adam Fantilli | C15: 0 | D15: C | E15: 6100 | F15: CBJ | G15: vs PHI | H15: 0.8125 | I15: Y | J15: 0.44 | K15: -78.5 | L15: 6.5 | M15: 3.35 | N15: 3.25 | O15: 1 | P15: 1 | Q15: 0.78194444 | R15: 9.6 | S15: 7.06 | T15: 25.82 | U15: 11.7 | V15: 11.7 | W15: 100 | Y15: 63 | Z15: 1.9 | AA15: 0 | AB15: 0.71458333 | AC15: 11 | AD15: 1.8
A16: Matthew Schaefer | C16: 0 | D16: D | E16: 6000 | F16: NYI | G16: vs NYR | H16: 0.79166667 | I16: Y | J16: 0.458 | K16: -84.5 | L16: 6.5 | M16: 3.5 | N16: 3.25 | O16: 1 | P16: 2 | Q16: 0.99444444 | R16: 9.6 | S16: 6.36 | T16: 24.82 | U16: 12.1 | V16: 12.1 | W16: 100 | Y16: 67 | Z16: 2 | AA16: 0 | AB16: 1.025 | AC16: 16.4 | AD16: 2.7
A17: Travis Konecny | C17: 0 | D17: W | E17: 5500 | F17: PHI | G17: @ CBJ | H17: 0.8125 | I17: N | J17: 0.56 | K17: 78.5 | L17: 6.5 | M17: 3.25 | N17: 3.35 | O17: 1 | P17: 1 | Q17: 0.78194444 | R17: 10.4 | S17: 7.17 | T17: 26.97 | U17: 12.63 | V17: 12.63 | W17: 100 | Y17: 66 | Z17: 2.3 | AA17: 0 | AB17: 0.89583333 | AC17: 37.3 | AD17: 6.8
A18: Owen Tippett | C18: 0 | D18: W | E18: 4900 | F18: PHI | G18: @ CBJ | H18: 0.8125 | I18: N | J18: 0.56 | K18: 78.5 | L18: 6.5 | M18: 3.25 | N18: 3.35 | O18: 2 | P18: 2 | Q18: 0.68333333 | R18: 9.4 | S18: 9.48 | T18: 31.41 | U18: 12.45 | V18: 12.45 | W18: 100 | Y18: 50 | Z18: 2.5 | AA18: 0 | AB18: 0.75555556 | AC18: 4.3 | AD18: 0.9
A19: David Rittich | C19: 0 | D19: G | E19: 8100 | F19: NYI | G19: vs NYR | H19: 0.79166667 | I19: Y | J19: 0.458 | K19: -84.5 | L19: 6.5 | M19: 3.5 | N19: 3.25 | O19: confirm | Q19: 2.4826389 | R19: 10.5 | S19: 10.17 | T19: 30.45 | U19: 10.11 | V19: 10.11 | W19: 100 | Y19: 52 | Z19: 1.2 | AA19: 0 | AB19: 2.4736111 | AC19: 8.8 | AD19: 1.1
A20: Dan Vladar | C20: 0 | D20: G | E20: 7300 | F20: PHI | G20: @ CBJ | H20: 0.8125 | I20: N | J20: 0.56 | K20: 78.5 | L20: 6.5 | M20: 3.25 | N20: 3.35 | O20: confirm | Q20: 2.4388889 | R20: 11.3 | S20: 7.64 | T20: 25.56 | U20: 10.28 | V20: 10.28 | W20: 100 | Y20: 66 | Z20: 1.4 | AA20: 0 | AB20: 2.3847222 | AC20: 4.2 | AD20: 0.6
A21: J.T. Miller | C21: 0 | D21: W | E21: 5800 | F21: NYR | G21: @ NYI | H21: 0.79166667 | I21: N | J21: 0.542 | K21: 84.5 | L21: 6.5 | M21: 3.25 | N21: 3.5 | O21: 1 | P21: 1 | Q21: 0.85833333 | R21: 9.2 | S21: 7.18 | T21: 25.46 | U21: 11.1 | V21: 11.1 | W21: 100 | Y21: 61 | Z21: 1.9 | AA21: 0 | AB21: 0.82361111 | AC21: 6.5 | AD21: 1.1
A22: Vincent Trocheck | C22: 0 | D22: C | E22: 5600 | F22: NYR | G22: @ NYI | H22: 0.79166667 | I22: N | J22: 0.542 | K22: 84.5 | L22: 6.5 | M22: 3.25 | N22: 3.5 | O22: 2 | P22: 1 | Q22: 0.87569444 | R22: 9 | S22: 6.17 | T22: 23.95 | U22: 11.61 | V22: 11.61 | W22: 100 | Y22: 66 | Z22: 2.1 | AA22: 0 | AB22: 0.65972222 | AC22: 1.3 | AD22: 0.2
A23: Trevor Zegras | C23: 0 | D23: W | E23: 5300 | F23: PHI | G23: @ CBJ | H23: 0.8125 | I23: N | J23: 0.56 | K23: 78.5 | L23: 6.5 | M23: 3.25 | N23: 3.35 | O23: 1 | P23: 1 | Q23: 0.77777778 | R23: 9.7 | S23: 8.4 | T23: 28.08 | U23: 11.28 | V23: 11.28 | W23: 100 | Y23: 57 | Z23: 2.1 | AA23: 0 | AB23: 0.88888889 | AC23: 12 | AD23: 2.3
A24: Dylan Cozens | C24: 0 | D24: C | E24: 5200 | F24: OTT | G24: vs COL | H24: 0.8125 | I24: N | J24: 0.505 | K24: 98 | L24: 6.5 | M24: 3.02 | N24: 3.25 | O24: 2 | P24: 1 | Q24: 0.71458333 | R24: 9.3 | S24: 8.16 | T24: 27.31 | U24: 10.99 | V24: 10.99 | W24: 100 | Y24: 56 | Z24: 2.1 | AA24: 0 | AB24: 0.61388889 | AC24: 1.5 | AD24: 0.3
A25: Valeri Nichushkin | C25: 0 | D25: W | E25: 5100 | F25: COL | G25: @ OTT | H25: 0.8125 | I25: Y | J25: 0.495 | K25: -98 | L25: 6.5 | M25: 3.25 | N25: 3.02 | O25: 2 | P25: 2 | Q25: 0.74236111 | R25: 8.8 | S25: 8.73 | T25: 27.64 | U25: 10.18 | V25: 10.18 | W25: 100 | Y25: 50 | Z25: 2 | AA25: 0 | AB25: 0.66597222 | AC25: 12.8 | AD25: 2.5
A26: Drake Batherson | C26: 0 | D26: W | E26: 5000 | F26: OTT | G26: vs COL | H26: 0.8125 | I26: N | J26: 0.505 | K26: 98 | L26: 6.5 | M26: 3.02 | N26: 3.25 | O26: 1 | P26: 1 | Q26: 0.74305556 | R26: 9.5 | S26: 7.91 | T26: 26.06 | U26: 10.24 | V26: 10.24 | W26: 100 | Y26: 58 | Z26: 2 | AA26: 0 | AB26: 0.67222222 | AC26: 1.5 | AD26: 0.3
A27: Anders Lee | C27: 0 | D27: W | E27: 4800 | F27: NYI | G27: vs NYR | H27: 0.79166667 | I27: Y | J27: 0.458 | K27: -84.5 | L27: 6.5 | M27: 3.5 | N27: 3.25 | O27: 3 | P27: 1 | Q27: 0.64791667 | R27: 8.6 | S27: 7.68 | T27: 26.38 | U27: 11.02 | V27: 11.02 | W27: 100 | Y27: 55 | Z27: 2.3 | AA27: 0 | AB27: 0.65208333 | AC27: 13.1 | AD27: 2.7
A28: Thomas Chabot | C28: 0 | D28: D | E28: 4700 | F28: OTT | G28: vs COL | H28: 0.8125 | I28: N | J28: 0.505 | K28: 98 | L28: 6.5 | M28: 3.02 | N28: 3.25 | O28: 2 | P28: 2 | Q28: 0.91388889 | R28: 9.3 | S28: 5.06 | T28: 20.84 | U28: 10.72 | V28: 10.72 | W28: 100 | Y28: 73 | Z28: 2.3 | AA28: 0 | AB28: 0.89166667 | AC28: 15.6 | AD28: 3.3
A29: Anthony Deangelo | C29: 0 | D29: D | E29: 4500 | F29: NYI | G29: vs NYR | H29: 0.79166667 | I29: Y | J29: 0.458 | K29: -84.5 | L29: 6.5 | M29: 3.5 | N29: 3.25 | O29: 2 | P29: 1 | Q29: 0.76805556 | R29: 7 | S29: 5.94 | T29: 21.99 | U29: 10.11 | V29: 10.11 | W29: 100 | Y29: 58 | Z29: 2.2 | AA29: 0 | AB29: 0.81875 | AC29: 9.5 | AD29: 2.1
A30: Christian Dvorak | C30: 0 | D30: C | E30: 4500 | F30: PHI | G30: @ CBJ | H30: 0.8125 | I30: N | J30: 0.56 | K30: 78.5 | L30: 6.5 | M30: 3.25 | N30: 3.35 | O30: 1 | P30: 1 | Q30: 0.73680556 | R30: 8.3 | S30: 7.15 | T30: 24.67 | U30: 10.37 | V30: 10.37 | W30: 100 | Y30: 57 | Z30: 2.3 | AA30: 0 | AB30: 0.91597222 | AC30: 12.1 | AD30: 2.7
A31: Boone Jenner | C31: 0 | D31: W | E31: 4400 | F31: CBJ | G31: vs PHI | H31: 0.8125 | I31: Y | J31: 0.44 | K31: -78.5 | L31: 6.5 | M31: 3.35 | N31: 3.25 | O31: 2 | P31: 2 | Q31: 0.70347222 | R31: 8.9 | S31: 6.04 | T31: 23.26 | U31: 11.18 | V31: 11.18 | W31: 100 | Y31: 66 | Z31: 2.5 | AA31: 0 | AB31: 0.73958333 | AC31: 2.8 | AD31: 0.6
A32: Brent Burns | C32: 0 | D32: D | E32: 4300 | F32: COL | G32: @ OTT | H32: 0.8125 | I32: Y | J32: 0.495 | K32: -98 | L32: 6.5 | M32: 3.25 | N32: 3.02 | O32: 2 | P32: 2 | Q32: 0.80833333 | R32: 8.4 | S32: 5.22 | T32: 21.01 | U32: 10.57 | V32: 10.57 | W32: 100 | Y32: 69 | Z32: 2.5 | AA32: 0 | AB32: 0.90625 | AC32: 1.5 | AD32: 0.3
... A34: Ivan Provorov | C34: 0 | D34: D | E34: 3900 | F34: CBJ | G34: vs PHI | H34: 0.8125 | I34: Y | J34: 0.44 | K34: -78.5 | L34: 6.5 | M34: 3.35 | N34: 3.25 | O34: 2 | P34: 2 | Q34: 1.0680556 | R34: 8.1 | S34: 5.16 | T34: 21.09 | U34: 10.77 | V34: 10.77 | W34: 100 | Y34: 68 | Z34: 2.8 | AA34: 0 | AB34: 0.93194444 | AC34: 7.3 | AD34: 1.9
A35: Josh Manson | C35: 0 | D35: D | E35: 3800 | F35: COL | G35: @ OTT | H35: 0.8125 | I35: Y | J35: 0.495 | K35: -98 | L35: 6.5 | M35: 3.25 | N35: 3.02 | O35: 2 | Q35: 0.75208333 | R35: 7.3 | S35: 7.49 | T35: 25.99 | U35: 11.01 | V35: 11.01 | W35: 100 | Y35: 49 | Z35: 2.9 | AA35: 0 | AB35: 0.87152778 | AC35: 1.5 | AD35: 0.4
A36: Elvis Merzlikins | C36: 0 | D36: G | E36: 7900 | F36: CBJ | G36: vs PHI | H36: 0.8125 | I36: Y | J36: 0.44 | K36: -78.5 | L36: 6.5 | M36: 3.35 | N36: 3.25 | O36: confirm | Q36: 2.3333333 | R36: 9.1 | S36: 9.73 | T36: 28.66 | U36: 9.2 | V36: 9.2 | W36: 100 | Y36: 47 | Z36: 1.2 | AA36: 0 | AB36: 2.5 | AC36: 11.6 | AD36: 1.5
A37: James Reimer | C37: 0 | D37: G | E37: 7100 | F37: OTT | G37: vs COL | H37: 0.8125 | I37: N | J37: 0.505 | K37: 98 | L37: 6.5 | M37: 3.02 | N37: 3.25 | O37: confirm | Q37: 2.2395833 | R37: 5.5 | S37: 7.14 | T37: 23.66 | U37: 9.38 | V37: 9.38 | W37: 100 | Y37: 35 | Z37: 1.3 | AA37: 0 | AB37: 2.5 | AC37: 10.2 | AD37: 1.4
A38: Artturi Lehkonen | C38: 0 | D38: W | E38: 5400 | F38: COL | G38: @ OTT | H38: 0.8125 | I38: Y | J38: 0.495 | K38: -98 | L38: 6.5 | M38: 3.25 | N38: 3.02 | O38: 2 | P38: 2 | Q38: 0.80208333 | R38: 9.1 | S38: 6.27 | T38: 22.23 | U38: 9.69 | V38: 9.69 | W38: 100 | Y38: 66 | Z38: 1.8 | AA38: 0 | AB38: 0.70208333 | AC38: 0
A39: Mason Marchment | C39: 0 | D39: W | E39: 4600 | F39: CBJ | G39: vs PHI | H39: 0.8125 | I39: Y | J39: 0.44 | K39: -78.5 | L39: 6.5 | M39: 3.35 | N39: 3.25 | O39: 1 | P39: 2 | Q39: 0.71458333 | R39: 7.3 | S39: 8.25 | T39: 26.33 | U39: 9.83 | V39: 9.83 | W39: 100 | Y39: 43 | Z39: 2.1 | AA39: 0 | AB39: 0.69861111 | AC39: 1.5 | AD39: 0.3
A40: Emil Heineman | C40: 0 | D40: W | E40: 4200 | F40: NYI | G40: vs NYR | H40: 0.79166667 | I40: Y | J40: 0.458 | K40: -84.5 | L40: 6.5 | M40: 3.5 | N40: 3.25 | O40: 1 | P40: 2 | Q40: 0.69513889 | R40: 7.9 | S40: 7.03 | T40: 23.15 | U40: 9.09 | V40: 9.09 | W40: 100 | Y40: 56 | Z40: 2.2 | AA40: 0 | AB40: 0.71527778 | AC40: 14.5 | AD40: 3.5
A41: Charlie Coyle | C41: 0 | D41: C | E41: 4100 | F41: CBJ | G41: vs PHI | H41: 0.8125 | I41: Y | J41: 0.44 | K41: -78.5 | L41: 6.5 | M41: 3.35 | N41: 3.25 | O41: 3 | P41: 1 | Q41: 0.73541667 | R41: 7.6 | S41: 8.23 | T41: 26.39 | U41: 9.93 | V41: 9.93 | W41: 100 | Y41: 46 | Z41: 2.4 | AA41: 0 | AB41: 0.77430556 | AC41: 15 | AD41: 3.7
...
