Workbook

Sheet Actual
A1: Player | B1: Roster Position | C1: %Drafted | D1: FPTS
A2: Aaron Ekblad | B2: D | C2: 0.0101 | D2: 1.3
A3: Aatu Raty | B3: C | C3: 0.0017 | D3: 0
A4: Adam Gaudette | B4: W | C4: 0.0017 | D4: 10
A5: Adam Larsson | B5: D | C5: 0.0168 | D5: 6.5
A6: Adam Lowry | B6: C | C6: 0.0017 | D6: 5.8
A7: Adam Pelech | B7: D | C7: 0.0034 | D7: 9.5
A8: Adin Hill | B8: G | C8: 0.0017 | D8: 4.1
A9: Adrian Kempe | B9: UTIL | C9: 0.0067 | D9: 14.5
A10: Alex DeBrincat | B10: W | C10: 0.0859 | D10: 36.8
A11: Alex Iafallo | B11: UTIL | C11: 0.0017 | D11: 0
A12: Alex Killorn | B12: W | C12: 0.0623 | D12: 3
A13: Alex Laferriere | B13: C | C13: 0.0236 | D13: 7.3
... A457: Zack Bolduc | B457: W | C457: 0.0017 | D457: 17.1

Sheet Projection
A1: name | B1: team | C1: position | D1: salary | E1: projected_fpts | F1: dk_avg_fpts | G1: edge | H1: value | I1: floor | J1: ceiling | K1: predicted_ownership | L1: ownership_tier | M1: leverage_score | N1: dk_id | O1: actual | P1: own
A2: Juraj Slafkovsk√Ω | B2: MTL | C2: W | D2: 5200 | E2: 9.9480722 | F2: 9.86 | G2: 0.088072212 | H2: 1.9130908 | I2: 2.4870181 | J2: 29.870181 | K2: 0.8068629 | L2: Contrarian (<5%) | M2: 5.505715 | N2: 41766895 | O2: =IFERROR(VLOOKUP($A2,Actual!$A:$D,4,FALSE),IFERROR(VLOOKUP($A2,FC!$A:$AD,29,FALSE),"Not Found")) -> 22.1 | P2: =IFERROR(VLOOKUP($A2,Actual!$A:$D,3,FALSE),"0") -> 0.0152
A3: Mitch Marner | B3: VGK | C3: W | D3: 6300 | E3: 12.656876 | F3: 10.09 | G3: 2.5668763 | H3: 2.009028 | I3: 3.1642191 | J3: 36.642191 | K3: 3.9911772 | L3: Contrarian (<5%) | M3: 2.5358499 | N3: 41766469 | O3: =IFERROR(VLOOKUP($A3,Actual!$A:$D,4,FALSE),IFERROR(VLOOKUP($A3,FC!$A:$AD,29,FALSE),"Not Found")) -> 16.5 | P3: =IFERROR(VLOOKUP($A3,Actual!$A:$D,3,FALSE),"0") -> 0.0152
A4: Mike Matheson | B4: MTL | C4: D | D4: 4000 | E4: 8.1126446 | F4: 8.83 | G4: -0.71735536 | H4: 2.0281612 | I4: 2.0281612 | J4: 25.281612 | K4: 2.0759047 | L4: Contrarian (<5%) | M4: 2.6374824 | N4: 41767593 | O4: =IFERROR(VLOOKUP($A4,Actual!$A:$D,4,FALSE),IFERROR(VLOOKUP($A4,FC!$A:$AD,29,FALSE),"Not Found")) -> 11.3 | P4: =IFERROR(VLOOKUP($A4,Actual!$A:$D,3,FALSE),"0") -> 0.0101
A5: Alexander Wennberg | B5: SJS | C5: C | D5: 4300 | E5: 7.6295778 | F5: 8.1 | G5: -0.47042225 | H5: 1.7743204 | I5: 1.9073944 | J5: 24.073944 | K5: 3.0701363 | L5: Contrarian (<5%) | M5: 1.8745264 | N5: 41766535 | O5: =IFERROR(VLOOKUP($A5,Actual!$A:$D,4,FALSE),IFERROR(VLOOKUP($A5,FC!$A:$AD,29,FALSE),"Not Found")) -> 9.5 | P5: =IFERROR(VLOOKUP($A5,Actual!$A:$D,3,FALSE),"0") -> 0.0152
A6: Jake Middleton | B6: MIN | C6: D | D6: 2700 | E6: 5.2051574 | F6: 4.91 | G6: 0.2951574 | H6: 1.9278361 | I6: 1.3012893 | J6: 18.012893 | K6: 0.69196824 | L6: Contrarian (<5%) | M6: 3.0763919 | N6: 41767763 | O6: =IFERROR(VLOOKUP($A6,Actual!$A:$D,4,FALSE),IFERROR(VLOOKUP($A6,FC!$A:$AD,29,FALSE),"Not Found")) -> 7.8 | P6: =IFERROR(VLOOKUP($A6,Actual!$A:$D,3,FALSE),"0") -> 0.0084
A7: Joel Eriksson Ek | B7: MIN | C7: C | D7: 6000 | E7: 11.814814 | F7: 10.26 | G7: 1.5548137 | H7: 1.9691356 | I7: 2.9537034 | J7: 34.537034 | K7: 3.9911772 | L7: Contrarian (<5%) | M7: 2.3671397 | N7: 41766483 | O7: =IFERROR(VLOOKUP($A7,Actual!$A:$D,4,FALSE),IFERROR(VLOOKUP($A7,FC!$A:$AD,29,FALSE),"Not Found")) -> 5 | P7: =IFERROR(VLOOKUP($A7,Actual!$A:$D,3,FALSE),"0") -> 0.0606
A8: Matthew Knies | B8: TOR | C8: W | D8: 4700 | E8: 10.394466 | F8: 9.27 | G8: 1.1244661 | H8: 2.2115885 | I8: 2.5986165 | J8: 30.986165 | K8: 1.2102943 | L8: Contrarian (<5%) | M8: 4.702752 | N8: 41766927 | O8: =IFERROR(VLOOKUP($A8,Actual!$A:$D,4,FALSE),IFERROR(VLOOKUP($A8,FC!$A:$AD,29,FALSE),"Not Found")) -> 4.5 | P8: =IFERROR(VLOOKUP($A8,Actual!$A:$D,3,FALSE),"0") -> 0.0135
A9: Matt Coronato | B9: CGY | C9: W | D9: 4300 | E9: 10.384159 | F9: 8.05 | G9: 2.3341589 | H9: 2.4149207 | I9: 2.5960397 | J9: 30.960397 | K9: 1.9451159 | L9: Contrarian (<5%) | M9: 3.5258914 | N9: 41766949 | O9: =IFERROR(VLOOKUP($A9,Actual!$A:$D,4,FALSE),IFERROR(VLOOKUP($A9,FC!$A:$AD,29,FALSE),"Not Found")) -> 4.5 | P9: =IFERROR(VLOOKUP($A9,Actual!$A:$D,3,FALSE),"0") -> 0.0152
A10: Alexis Lafreni√®re | B10: NYR | C10: W | D10: 4000 | E10: 8.4315309 | F10: 7.24 | G10: 1.1915309 | H10: 2.1078827 | I10: 2.1078827 | J10: 26.078827 | K10: 0.79799627 | L10: Contrarian (<5%) | M10: 4.689404 | N10: 41766973 | O10: =IFERROR(VLOOKUP($A10,Actual!$A:$D,4,FALSE),IFERROR(VLOOKUP($A10,FC!$A:$AD,29,FALSE),"Not Found")) -> 2.8 | P10: =IFERROR(VLOOKUP($A10,Actual!$A:$D,3,FALSE),"0") -> 0.0101
A11: Charlie Lindgren | B11: WSH | C11: G | D11: 7500 | E11: 9.2877878 | F11: 10.27 | G11: -0.98221216 | H11: 1.2383717 | I11: 1.8575576 | J11: 28.575576 | K11: 4.9591414 | L11: Contrarian (<5%) | M11: 1.5585782 | N11: 41768112 | O11: =IFERROR(VLOOKUP($A11,Actual!$A:$D,4,FALSE),IFERROR(VLOOKUP($A11,FC!$A:$AD,29,FALSE),"Not Found")) -> 8.1 | P11: =IFERROR(VLOOKUP($A11,Actual!$A:$D,3,FALSE),"0") -> 0.0084
A12: Jake Oettinger | B12: DAL | C12: G | D12: 7400 | E12: 12.814866 | F12: 11.96 | G12: 0.85486631 | H12: 1.7317387 | I12: 2.5629733 | J12: 35.629733 | K12: 4.1961966 | L12: Contrarian (<5%) | M12: 2.4662012 | N12: 41768117 | O12: =IFERROR(VLOOKUP($A12,Actual!$A:$D,4,FALSE),IFERROR(VLOOKUP($A12,FC!$A:$AD,29,FALSE),"Not Found")) -> 3.9 | P12: =IFERROR(VLOOKUP($A12,Actual!$A:$D,3,FALSE),"0") -> 0.0286
A13: Adin Hill | B13: VGK | C13: G | D13: 8000 | E13: 4.9045827 | F13: 4.39 | G13: 0.51458269 | H13: 0.61307284 | I13: 0.98091654 | J13: 19.809165 | K13: 2.9754849 | L13: Contrarian (<5%) | M13: 1.2337068 | N13: 41768088 | O13: =IFERROR(VLOOKUP($A13,Actual!$A:$D,4,FALSE),IFERROR(VLOOKUP($A13,FC!$A:$AD,29,FALSE),"Not Found")) -> 4.1 | P13: =IFERROR(VLOOKUP($A13,Actual!$A:$D,3,FALSE),"0") -> 0.0017
... A645: Lane Pederson | B645: PHI | C645: C | D645: 2500 | E645: 0.86931543 | F645: 0.78 | G645: 0.089315435 | H645: 0.34772617 | I645: 0.21732886 | J645: 7.1732886 | K645: 0.40935151 | L645: Contrarian (<5%) | M645: 0.61681946 | N645: 41766691 | O645: =IFERROR(VLOOKUP($A645,Actual!$A:$D,4,FALSE),IFERROR(VLOOKUP($A645,FC!$A:$AD,29,FALSE),"Not Found")) -> 0 | P645: =IFERROR(VLOOKUP($A645,Actual!$A:$D,3,FALSE),"0") -> 0

Sheet NHT

Sheet FC
A1: Player | B1: Inj | C1: Likes | D1: Pos | E1: Salary | F1: Team | G1: Opp | H1: Time | I1: Fav. | J1: Win % | K1: Spread | L1: Total | M1: TeamGoal | N1: OppGoal | O1: Start/Line | P1: PP Unit | Q1: avg TOI | R1: Avg | S1: STDV | T1: Ceiling | U1: FC Proj | V1: My Proj | W1: Exp. | X1: Used | Y1: Con. | Z1: Value | AA1: Own% | AB1: TOI | AC1: Score | AD1: Val
A2: A.j. Greer | C2: 0 | D2: W | E2: 2500 | F2: FLA | G2: @ STL | H2: 0.83333333 | I2: Y | J2: 0.487 | K2: -95 | L2: 5.5 | M2: 2.75 | N2: 2.54 | O2: 4 | Q2: 0.47638889 | R2: 4.9 | S2: 5.84 | T2: 16.88 | U2: 5.2 | V2: 5.2 | W2: 100 | Y2: 40 | Z2: 2.1 | AA2: 0 | AB2: 0.31041667 | AC2: 11.5 | AD2: 4.6
A3: Aaron Ekblad | C3: 0 | D3: D | E3: 3900 | F3: FLA | G3: @ STL | H3: 0.83333333 | I3: Y | J3: 0.487 | K3: -95 | L3: 5.5 | M3: 2.75 | N3: 2.54 | O3: 1 | Q3: 0.92777778 | R3: 7.3 | S3: 5.29 | T3: 18.84 | U3: 8.26 | V3: 8.26 | W3: 100 | Y3: 64 | Z3: 2.1 | AA3: 0 | AB3: 0.96527778 | AC3: 1.3 | AD3: 0.3
A4: Aatu Raty | C4: 0 | D4: C | E4: 2600 | F4: VAN | G4: vs ANA | H4: 0.91666667 | I4: N | J4: 0.512 | K4: 95.5 | L4: 6.5 | M4: 3.01 | N4: 3.25 | O4: 3 | Q4: 0.50625 | R4: 3.8 | S4: 5.11 | T4: 14.45 | U4: 4.23 | V4: 4.23 | W4: 100 | Y4: 33 | Z4: 1.6 | AA4: 0 | AB4: 0.5375 | AC4: 0
A5: Adam Boqvist | C5: 0 | D5: D | E5: 2500 | F5: NYI | G5: @ NYR | H5: 0.79166667 | I5: Y | J5: 0.472 | K5: -89.5 | L5: 6 | M5: 3 | N5: 2.82 | Q5: 0.53472222 | R5: 2.3 | S5: 2.77 | T5: 0 | U5: 0 | V5: 0 | W5: 100 | Y5: 40 | Z5: 0 | AA5: 0
A6: Adam Edstrom | C6: 0 | D6: C | E6: 2500 | F6: NYR | G6: vs NYI | H6: 0.79166667 | I6: N | J6: 0.528 | K6: 89.5 | L6: 6 | M6: 2.82 | N6: 3 | Q6: 0.40347222 | R6: 3.6 | S6: 3.99 | T6: 0 | U6: 0 | V6: 0 | W6: 100 | Y6: 45 | Z6: 0 | AA6: 0
A7: Adam Engstrom | C7: 0 | D7: D | E7: 2500 | F7: MTL | G7: vs COL | H7: 0.79166667 | I7: N | J7: 0.551 | K7: 81.5 | L7: 6.5 | M7: 3.17 | N7: 3.25 | Q7: 0.54097222 | R7: 1.9 | S7: 1.96 | T7: 0 | U7: 0 | V7: 0 | W7: 100 | Y7: 48 | Z7: 0 | AA7: 0
A8: Adam Erne | C8: 0 | D8: W | E8: 2500 | F8: DAL | G8: @ VGK | H8: 0.91666667 | I8: N | J8: 0.535 | K8: 87 | L8: 6 | M8: 3 | N8: 3.14 | O8: 4 | Q8: 0.39305556 | R8: 3.8 | S8: 4.24 | T8: 12.98 | U8: 4.5 | V8: 4.5 | W8: 100 | Y8: 44 | Z8: 1.8 | AA8: 0 | AB8: 0.44652778 | AC8: 0
A9: Adam Fox | C9: 0 | D9: D | E9: 6400 | F9: NYR | G9: vs NYI | H9: 0.79166667 | I9: N | J9: 0.528 | K9: 89.5 | L9: 6 | M9: 2.82 | N9: 3 | Q9: 0.97708333 | R9: 11 | S9: 6.33 | T9: 0 | U9: 0 | V9: 0 | W9: 100 | Y9: 71 | Z9: 0 | AA9: 0
A10: Adam Gaudette | C10: 0 | D10: W | E10: 2900 | F10: SJ | G10: @ EDM | H10: 0.875 | I10: N | J10: 0.471 | K10: 112.5 | L10: 7 | M10: 3.5 | N10: 4.05 | O10: 3 | Q10: 0.49930556 | R10: 6.2 | S10: 5.9 | T10: 20.39 | U10: 8.59 | V10: 8.59 | W10: 100 | Y10: 52 | Z10: 3 | AA10: 0 | AB10: 0.51388889 | AC10: 10 | AD10: 3.4
A11: Adam Ginning | C11: 0 | D11: D | E11: 2500 | F11: PHI | G11: @ BOS | H11: 0.79166667 | I11: N | J11: 0.519 | K11: 92.5 | L11: 6.5 | M11: 3.25 | N11: 3.62 | Q11: 0.64097222 | R11: 2.6 | S11: 1.67 | T11: 0 | U11: 0 | V11: 0 | W11: 100 | Y11: 68 | Z11: 0 | AA11: 0
A12: Adam Henrique | C12: 0 | D12: C | E12: 2800 | F12: EDM | G12: vs SJ | H12: 0.875 | I12: Y | J12: 0.529 | K12: -112.5 | L12: 7 | M12: 4.05 | N12: 3.5 | Q12: 0.57708333 | R12: 5.8 | S12: 5.33 | T12: 0 | U12: 0 | V12: 0 | W12: 100 | Y12: 54 | Z12: 0 | AA12: 0
A13: Adam Klapka | C13: 0 | D13: W | E13: 2700 | F13: CGY | G13: @ MIN | H13: 0.83333333 | I13: N | J13: 0.487 | K13: 105.5 | L13: 6 | M13: 3 | N13: 3.46 | O13: 4 | Q13: 0.44166667 | R13: 4 | S13: 4.15 | T13: 12.45 | U13: 4.15 | V13: 4.15 | W13: 100 | Y13: 48 | Z13: 1.5 | AA13: 0 | AB13: 0.38680556 | AC13: 1.5 | AD13: 0.6
A14: Adam Larsson | C14: 0 | D14: D | E14: 3200 | F14: SEA | G14: vs TOR | H14: 0.91666667 | I14: Y | J14: 0.415 | K14: -71 | L14: 6 | M14: 3.02 | N14: 3 | O14: 1 | Q14: 0.90486111 | R14: 7 | S14: 4.9 | T14: 18.12 | U14: 8.32 | V14: 8.32 | W14: 100 | Y14: 65 | Z14: 2.6 | AA14: 0 | AB14: 0.77291667 | AC14: 6.5 | AD14: 2
A15: Adam Lowry | C15: 0 | D15: C | E15: 2500 | F15: WPG | G15: @ TB | H15: 0.79166667 | I15: N | J15: 0.482 | K15: 107.5 | L15: 5.5 | M15: 2.75 | N15: 3.2 | O15: 3 | Q15: 0.60069444 | R15: 4.4 | S15: 4.43 | T15: 12.86 | U15: 4 | V15: 4 | W15: 100 | Y15: 50 | Z15: 1.6 | AA15: 0 | AB15: 0.60069444 | AC15: 5.8 | AD15: 2.3
A16: Adam Pelech | C16: 0 | D16: D | E16: 3300 | F16: NYI | G16: @ NYR | H16: 0.79166667 | I16: Y | J16: 0.472 | K16: -89.5 | L16: 6 | M16: 3 | N16: 2.82 | O16: 2 | Q16: 0.86319444 | R16: 6.5 | S16: 3.92 | T16: 15.99 | U16: 8.15 | V16: 8.15 | W16: 100 | Y16: 70 | Z16: 2.5 | AA16: 0 | AB16: 0.88819444 | AC16: 9.5 | AD16: 2.9
A17: Adam Wilsby | C17: 0 | D17: D | E17: 2500 | F17: NSH | G17: @ NJ | H17: 0.79166667 | I17: N | J17: 0.536 | K17: 86.5 | L17: 6 | M17: 3 | N17: 3.19 | O17: 2 | Q17: 0.71041667 | R17: 3.8 | S17: 3.66 | T17: 11.9 | U17: 4.58 | V17: 4.58 | W17: 100 | Y17: 52 | Z17: 1.8 | AA17: 0 | AB17: 0.66875 | AC17: 9.3 | AD17: 3.7
A18: Adin Hill | C18: 0 | D18: G | E18: 8000 | F18: VGK | G18: vs DAL | H18: 0.91666667 | I18: Y | J18: 0.465 | K18: -87 | L18: 6 | M18: 3.14 | N18: 3 | O18: confirm | Q18: 2.1590278 | R18: 4.4 | S18: 7.27 | T18: 22.05 | U18: 7.51 | V18: 7.51 | W18: 100 | Y18: 17 | Z18: 0.9 | AA18: 0 | AB18: 2.6701389 | AC18: 4.1 | AD18: 0.5
A19: Adrian Kempe | C19: 0 | D19: W | E19: 6000 | F19: LA | G19: @ BUF | H19: 0.79166667 | I19: N | J19: 0.565 | K19: 77 | L19: 5.5 | M19: 2.75 | N19: 2.87 | O19: 1 | P19: 1 | Q19: 0.8 | R19: 10.3 | S19: 6.35 | T19: 22.18 | U19: 9.48 | V19: 9.48 | W19: 100 | Y19: 69 | Z19: 1.6 | AA19: 0 | AB19: 0.70069444 | AC19: 14.5 | AD19: 2.4
A20: Akira Schmid | C20: 0 | D20: G | E20: 8000 | F20: VGK | G20: vs DAL | H20: 0.91666667 | I20: Y | J20: 0.465 | K20: -87 | L20: 6 | M20: 3.14 | N20: 3 | O20: unlikely | Q20: 2.4208333 | R20: 10.7 | S20: 8.21 | T20: 0 | U20: 0 | V20: 0 | W20: 100 | Y20: 62 | Z20: 0 | AA20: 0 | AB20: 0 | AC20: 2 | AD20: 0.3
A21: Albert Johansson | C21: 0 | D21: D | E21: 2500 | F21: DET | G21: vs WSH | H21: 0.8125 | I21: Y | J21: 0.44 | K21: -78.5 | L21: 6.5 | M21: 3.43 | N21: 3.25 | O21: 3 | Q21: 0.66180556 | R21: 4.3 | S21: 4.02 | T21: 13.56 | U21: 5.52 | V21: 5.52 | W21: 100 | Y21: 53 | Z21: 2.2 | AA21: 0 | AB21: 0.80277778 | AC21: 2.6 | AD21: 1
A22: Alec Regula | C22: 0 | D22: D | E22: 2500 | F22: EDM | G22: vs SJ | H22: 0.875 | I22: Y | J22: 0.529 | K22: -112.5 | L22: 7 | M22: 4.05 | N22: 3.5 | Q22: 0.60902778 | R22: 4.2 | S22: 3.52 | T22: 0 | U22: 0 | V22: 0 | W22: 100 | Y22: 58 | Z22: 0 | AA22: 0
A23: Aleksander Barkov | B23: ! | C23: 0 | D23: C | E23: 2500 | F23: FLA | G23: @ STL | H23: 0.83333333 | I23: Y | J23: 0.487 | K23: -95 | L23: 5.5 | M23: 2.75 | N23: 2.54 | T23: 0 | U23: 0 | V23: 0 | W23: 100 | Y23: 0 | Z23: 0 | AA23: 0
A24: Aleksanteri Kaskimaki | C24: 0 | D24: C | E24: 2500 | F24: STL | G24: vs FLA | H24: 0.83333333 | I24: N | J24: 0.513 | K24: 95 | L24: 5.5 | M24: 2.54 | N24: 2.75 | Q24: 0.47083333 | R24: 3.8 | S24: 3.48 | T24: 0 | U24: 0 | V24: 0 | W24: 100 | Y24: 54 | Z24: 0 | AA24: 0
A25: Alex DeBrincat | C25: 0 | D25: W | E25: 6600 | F25: DET | G25: vs WSH | H25: 0.8125 | I25: Y | J25: 0.44 | K25: -78.5 | L25: 6.5 | M25: 3.43 | N25: 3.25 | O25: 2 | P25: 1 | Q25: 0.75555556 | R25: 14.2 | S25: 9.17 | T25: 35.82 | U25: 17.48 | V25: 17.48 | W25: 100 | Y25: 68 | Z25: 2.6 | AA25: 0 | AB25: 0.89444444 | AC25: 36.8 | AD25: 5.6
A26: Alex Iafallo | C26: 0 | D26: W | E26: 3000 | F26: WPG | G26: @ TB | H26: 0.79166667 | I26: N | J26: 0.482 | K26: 107.5 | L26: 5.5 | M26: 2.75 | N26: 3.2 | O26: 2 | P26: 2 | Q26: 0.6375 | R26: 5.7 | S26: 5.27 | T26: 15.93 | U26: 5.39 | V26: 5.39 | W26: 100 | Y26: 54 | Z26: 1.8 | AA26: 0 | AB26: 0.66319444 | AC26: 0
A27: Alex Killorn | C27: 0 | D27: W | E27: 3700 | F27: ANA | G27: @ VAN | H27: 0.91666667 | I27: Y | J27: 0.488 | K27: -95.5 | L27: 6.5 | M27: 3.25 | N27: 3.01 | O27: 1 | P27: 2 | Q27: 0.66527778 | R27: 5.5 | S27: 4.79 | T27: 16.73 | U27: 7.15 | V27: 7.15 | W27: 100 | Y27: 56 | Z27: 1.9 | AA27: 0 | AB27: 0.81736111 | AC27: 3 | AD27: 0.8
A28: Alex Laferriere | C28: 0 | D28: C | E28: 4700 | F28: LA | G28: @ BUF | H28: 0.79166667 | I28: N | J28: 0.565 | K28: 77 | L28: 5.5 | M28: 2.75 | N28: 2.87 | O28: 1 | P28: 2 | Q28: 0.72083333 | R28: 8.2 | S28: 7.31 | T28: 23.4 | U28: 8.78 | V28: 8.78 | W28: 100 | Y28: 55 | Z28: 1.9 | AA28: 0 | AB28: 0.73611111 | AC28: 7.3 | AD28: 1.6
A29: Alex Lyon | C29: 0 | D29: G | E29: 8000 | F29: BUF | G29: vs LA | H29: 0.79166667 | I29: Y | J29: 0.435 | K29: -77 | L29: 5.5 | M29: 2.87 | N29: 2.75 | O29: confirm | Q29: 2.26875 | R29: 12.5 | S29: 8.91 | T29: 29.32 | U29: 11.5 | V29: 11.5 | W29: 100 | Y29: 64 | Z29: 1.4 | AA29: 0 | AB29: 2.5 | AC29: 31.4 | AD29: 3.9
A30: Alex Nedeljkovic | C30: 0 | D30: G | E30: 7000 | F30: SJ | G30: @ EDM | H30: 0.875 | I30: N | J30: 0.471 | K30: 112.5 | L30: 7 | M30: 3.5 | N30: 4.05 | O30: unlikely | Q30: 2.3888889 | R30: 11 | S30: 9.84 | T30: 0 | U30: 0 | V30: 0 | W30: 100 | Y30: 55 | Z30: 0 | AA30: 0 | AB30: 0 | AC30: 2 | AD30: 0.3
A31: Alex Newhook | C31: 0 | D31: W | E31: 2500 | F31: MTL | G31: vs COL | H31: 0.79166667 | I31: N | J31: 0.551 | K31: 81.5 | L31: 6.5 | M31: 3.17 | N31: 3.25 | Q31: 0.60625 | R31: 7.4 | S31: 7.17 | T31: 0 | U31: 0 | V31: 0 | W31: 100 | Y31: 52 | Z31: 0 | AA31: 0
A32: Alex Ovechkin | C32: 0 | D32: W | E32: 6800 | F32: WSH | G32: @ DET | H32: 0.8125 | I32: N | J32: 0.56 | K32: 78.5 | L32: 6.5 | M32: 3.25 | N32: 3.43 | O32: 3 | P32: 2 | Q32: 0.74861111 | R32: 10.2 | S32: 7.44 | T32: 27.63 | U32: 12.75 | V32: 12.75 | W32: 100 | Y32: 64 | Z32: 1.9 | AA32: 0 | AB32: 0.66666667 | AC32: 11 | AD32: 1.6
A33: Alexander Petrovic | C33: 0 | D33: D | E33: 2500 | F33: DAL | G33: @ VGK | H33: 0.91666667 | I33: N | J33: 0.535 | K33: 87 | L33: 6 | M33: 3 | N33: 3.14 | O33: 3 | Q33: 0.65625 | R33: 5.2 | S33: 4.57 | T33: 14.72 | U33: 5.58 | V33: 5.58 | W33: 100 | Y33: 56 | Z33: 2.2 | AA33: 0 | AB33: 0.55902778 | AC33: 6.9 | AD33: 2.8
A34: Alex Pietrangelo | B34: ! | C34: 0 | D34: D | E34: 2700 | F34: VGK | G34: vs DAL | H34: 0.91666667 | I34: Y | J34: 0.465 | K34: -87 | L34: 6 | M34: 3.14 | N34: 3 | T34: 0 | U34: 0 | V34: 0 | W34: 100 | Y34: 0 | Z34: 0 | AA34: 0
A35: Alex Steeves | C35: 0 | D35: W | E35: 2700 | F35: BOS | G35: vs PHI | H35: 0.79166667 | I35: Y | J35: 0.481 | K35: -92.5 | L35: 6.5 | M35: 3.62 | N35: 3.25 | Q35: 0.51111111 | R35: 5.5 | S35: 5.87 | T35: 0 | U35: 0 | V35: 0 | W35: 100 | Y35: 47 | Z35: 0 | AA35: 0
A36: Alex Tuch | C36: 0 | D36: W | E36: 6100 | F36: BUF | G36: vs LA | H36: 0.79166667 | I36: Y | J36: 0.435 | K36: -77 | L36: 5.5 | M36: 2.87 | N36: 2.75 | O36: 1 | P36: 2 | Q36: 0.77638889 | R36: 11.1 | S36: 6.19 | T36: 24.34 | U36: 11.96 | V36: 11.96 | W36: 100 | Y36: 72 | Z36: 2 | AA36: 0 | AB36: 0.74791667 | AC36: 45 | AD36: 7.4
A37: Alex Turcotte | C37: 0 | D37: C | E37: 3100 | F37: LA | G37: @ BUF | H37: 0.79166667 | I37: N | J37: 0.565 | K37: 77 | L37: 5.5 | M37: 2.75 | N37: 2.87 | Q37: 0.45486111 | R37: 4 | S37: 4.65 | T37: 0 | U37: 0 | V37: 0 | W37: 100 | Y37: 42 | Z37: 0 | AA37: 0
A38: Alex Vlasic | C38: 0 | D38: D | E38: 2600 | F38: CHI | G38: @ PIT | H38: 0.79166667 | I38: N | J38: 0.493 | K38: 103 | L38: 6.5 | M38: 3.25 | N38: 3.71 | O38: 1 | Q38: 0.87291667 | R38: 5.4 | S38: 4.19 | T38: 14.56 | U38: 6.18 | V38: 6.18 | W38: 100 | Y38: 61 | Z38: 2.4 | AA38: 0 | AB38: 0.82777778 | AC38: 2.6 | AD38: 1
A39: Alex Wennberg | C39: 0 | D39: C | E39: 4300 | F39: SJ | G39: @ EDM | H39: 0.875 | I39: N | J39: 0.471 | K39: 112.5 | L39: 7 | M39: 3.5 | N39: 4.05 | O39: 2 | P39: 1 | Q39: 0.86180556 | R39: 8.1 | S39: 6.97 | T39: 25.65 | U39: 11.71 | V39: 11.71 | W39: 100 | Y39: 57 | Z39: 2.7 | AA39: 0 | AB39: 0.88194444 | AC39: 9.5 | AD39: 2.2
A40: Alexander Holtz | C40: 0 | D40: W | E40: 2500 | F40: VGK | G40: vs DAL | H40: 0.91666667 | I40: Y | J40: 0.465 | K40: -87 | L40: 6 | M40: 3.14 | N40: 3 | O40: 4 | Q40: 0.48055556 | R40: 4.3 | S40: 5.13 | T40: 15.29 | U40: 5.03 | V40: 5.03 | W40: 100 | Y40: 40 | Z40: 2 | AA40: 0 | AB40: 0.54930556 | AC40: 0
...
